Workbook

Sheet 1_Summary at PL
A2: Market | B2: DL | E2: HR | H2: RJ | K2: UP E + C | N2: CH | Q2: PB | T2: UK | W2: HP | Z2: J&K | AC2: Distri- Delear ladder
A3: <As on 9th Mar'26> | B3: Distr. level | C3: Dealer level | D3: Gap with TSL | E3: Distr. level | F3: Dealer level | G3: Gap with TSL | H3: Distr. level | I3: Dealer level | J3: Gap with TSL | K3: Distr. level | L3: Dealer level | M3: Gap with TSL | N3: Distr. level | O3: Dealer level | P3: Gap with TSL | Q3: Distr. level | R3: Dealer level | S3: Gap with TSL | T3: Distr. level | U3: Dealer level | V3: Gap with TSL | W3: Distr. level | X3: Dealer level | Y3: Gap with TSL | Z3: Distr. level | AA3: Dealer level | AB3: Gap with TSL | AC3: NCR | AD3: Rest
A4: TISCON | B4: 60000 | C4: =B4+AC4 -> 65650 | D4: =C4-C$4 -> 0 | E4: =B4 -> 60000 | F4: =E4+$AD4 -> 65650 | G4: =F4-F$4 -> 0 | H4: =B4+500 -> 60500 | I4: =H4+$AD4 -> 66150 | J4: =I4-I$4 -> 0 | K4: =B4-500 -> 59500 | L4: =K4+$AD4 -> 65150 | M4: =L4-L$4 -> 0 | N4: =B4+1000 -> 61000 | O4: =N4+$AD4 -> 66650 | P4: =O4-O$4 -> 0 | Q4: =B4+500 -> 60500 | R4: =Q4+AD4-500 -> 65650 | S4: =R4-R$4 -> 0 | T4: =B4+500 -> 60500 | U4: =T4+AD4 -> 66150 | V4: =U4-U$4 -> 0 | W4: =B4 -> 60000 | X4: =W4+AD4 -> 65650 | Y4: =X4-X$4 -> 0 | Z4: =B4+500 -> 60500 | AA4: =Z4+AD4 -> 66150 | AB4: =AA4-AA$4 -> 0 | AC4: 5650 | AD4: =AC4 -> 5650
A5: Neo | B5: 59150 | C5: =B5+AC5 -> 62850 | D5: =C5-C$4 -> -2800 | E5: =B5 -> 59150 | F5: =E5+$AD5 -> 62850 | G5: =F5-F$4 -> -2800 | H5: =B5 -> 59150 | I5: =H5+$AD5 -> 62850 | J5: =I5-I$4 -> -3300 | K5: =B5 -> 59150 | L5: =K5+$AD5 -> 62850 | M5: =L5-L$4 -> -2300 | N5: =B5 -> 59150 | O5: =N5+$AD5 -> 62850 | P5: =O5-O$4 -> -3800 | Q5: =B5+500 -> 59650 | R5: =Q5+AD5-500 -> 62850 | S5: =R5-R$4 -> -2800 | T5: =B5 -> 59150 | U5: =T5+AD5 -> 62850 | V5: =U5-U$4 -> -3300 | W5: =B5+500 -> 59650 | X5: =W5+AD5 -> 63350 | Y5: =X5-X$4 -> -2300 | Z5: =B5+1500 -> 60650 | AA5: =Z5+AD5 -> 64350 | AB5: =AA5-AA$4 -> -1800 | AC5: 3700 | AD5: =AC5 -> 3700
A6: JSPL | B6: 58500 | C6: =B6+AC6 -> 62100 | D6: =C6-C$4 -> -3550 | E6: NA | F6: 58650 | G6: =F6-F$4 -> -7000 | H6: =B6+250 -> 58750 | I6: =H6+$AD6 -> 62600 | J6: =I6-I$4 -> -3550 | K6: =B6-500 -> 58000 | L6: =K6+$AD6 -> 61850 | M6: =L6-L$4 -> -3300 | N6: =B6+500 -> 59000 | O6: =N6+$AD6 -> 62850 | P6: =O6-O$4 -> -3800 | Q6: =B6+250 -> 58750 | R6: =Q6+AD6-500 -> 62100 | S6: =R6-R$4 -> -3550 | T6: =B6+500 -> 59000 | U6: =T6+AD6 -> 62850 | V6: =U6-U$4 -> -3300 | W6: =B6+500 -> 59000 | X6: =W6+AD6 -> 62850 | Y6: =X6-X$4 -> -2800 | Z6: =B6+500 -> 59000 | AA6: =Z6+AD6 -> 62850 | AB6: =AA6-AA$4 -> -3300 | AC6: 3600 | AD6: 3850
A7: SAIL | B7: 59500 | C7: =B7+AC7 -> 61750 | D7: =C7-C$4 -> -3900 | E7: =B7 -> 59500 | F7: =E7+$AD7 -> 61750 | G7: =F7-F$4 -> -3900 | H7: =B7-250 -> 59250 | I7: =H7+$AD7 -> 61500 | J7: =I7-I$4 -> -4650 | K7: =B7-500 -> 59000 | L7: =K7+$AD7 -> 61250 | M7: =L7-L$4 -> -3900 | N7: =B7+500 -> 60000 | O7: =N7+$AD7 -> 62250 | P7: =O7-O$4 -> -4400 | Q7: =B7+500 -> 60000 | R7: =Q7+AD7-500 -> 61750 | S7: =R7-R$4 -> -3900 | T7: =B7+500 -> 60000 | U7: =T7+AD7 -> 62250 | V7: =U7-U$4 -> -3900 | W7: =B7+1000 -> 60500 | X7: =W7+AD7 -> 62750 | Y7: =X7-X$4 -> -2900 | Z7: =B7+2000 -> 61500 | AA7: =Z7+AD7 -> 63750 | AB7: =AA7-AA$4 -> -2400 | AC7: 2250 | AD7: =AC7 -> 2250
A8: JSW One Fe 550D | B8: 58400 | C8: =B8+AC8 -> 60700 | D8: =C8-C$4 -> -4950 | E8: =B8 -> 58400 | F8: =E8+$AD8 -> 60700 | G8: =F8-F$4 -> -4950 | H8: =B8 -> 58400 | I8: =H8+$AD8 -> 60700 | J8: =I8-I$4 -> -5450 | K8: =B8 -> 58400 | L8: =K8+$AD8 -> 60700 | M8: =L8-L$4 -> -4450 | N8: =B8+250 -> 58650 | O8: =N8+$AD8 -> 60950 | P8: =O8-O$4 -> -5700 | Q8: =B8+500 -> 58900 | R8: =Q8+AD8-500 -> 60700 | S8: =R8-R$4 -> -4950 | T8: =B8+500 -> 58900 | U8: =T8+AD8 -> 61200 | V8: =U8-U$4 -> -4950 | W8: =B8+1000 -> 59400 | X8: =W8+AD8 -> 61700 | Y8: =X8-X$4 -> -3950 | Z8: =B8+2000 -> 60400 | AA8: =Z8+AD8 -> 62700 | AB8: =AA8-AA$4 -> -3450 | AC8: 2300 | AD8: 2300
A9: <General SAIL position> | F9: =E9+$AD9 -> 0 | I9: =H9+$AD9 -> 0 | L9: =K9+$AD9 -> 0 | O9: =N9+$AD9 -> 0 | X9: =W9+AD9 -> 0 | AA9: =Z9+AD9 -> 0
A10: JSW One Fe 550 | B10: 57400 | C10: =B10+AC10 -> 59700 | D10: =C10-C$4 -> -5950 | E10: =B10 -> 57400 | F10: =E10+$AD10 -> 59700 | G10: =F10-F$4 -> -5950 | H10: =B10 -> 57400 | I10: =H10+$AD10 -> 59700 | J10: =I10-I$4 -> -6450 | K10: =B10 -> 57400 | L10: =K10+$AD10 -> 59700 | M10: =L10-L$4 -> -5450 | N10: =B10+250 -> 57650 | O10: =N10+$AD10 -> 59950 | P10: =O10-O$4 -> -6700 | Q10: =B10+500 -> 57900 | R10: =Q10+AD10-500 -> 59700 | S10: =R10-R$4 -> -5950 | T10: =B10 -> 57400 | U10: =T10+AD10 -> 59700 | V10: =U10-U$4 -> -6450 | W10: =B10+500 -> 57900 | X10: =W10+AD10 -> 60200 | Y10: =X10-X$4 -> -5450 | Z10: =B10+1500 -> 58900 | AA10: =Z10+AD10 -> 61200 | AB10: =AA10-AA$4 -> -4950 | AC10: 2300 | AD10: 2300
A11: Branded prem sec. | B11: =C11-250 -> 52400 | C11: =C12+1000 -> 52650 | D11: =C11-C$4 -> -13000 | E11: =B11 -> 52400 | F11: =C11 -> 52650 | G11: =F11-F$4 -> -13000 | H11: =I11-250 -> 49300 | I11: =I12+1000 -> 49550 | J11: =I11-I$4 -> -16600 | K11: =L11-250 -> 51900 | L11: =L12+1000 -> 52150 | M11: =L11-L$4 -> -13000 | N11: =O11-250 -> 50500 | O11: =O12+1000 -> 50750 | P11: =O11-O$4 -> -15900 | Q11: =R11-250 -> 51000 | R11: =R12+1500 -> 51250 | S11: =R11-R$4 -> -14400 | T11: =U11-250 -> 51900 | U11: =U12+500 -> 52150 | V11: =U11-U$4 -> -14000 | W11: =X11-250 -> 50500 | X11: =X12+1000 -> 50750 | Y11: =X11-X$4 -> -14900 | Z11: =Z12+250+1500+1000 -> 53500 | AA11: =AA12+1000 -> 51750 | AB11: =AA11-AA$4 -> -14400 | AC11: 1450 | AD11: 1450
A12: Steelmint | B12: =50400+250+1000 -> 51650 | C12: =B12 -> 51650 | D12: =C12-C$4 -> -14000 | E12: =B12 -> 51650 | F12: =C12 -> 51650 | G12: =F12-F$4 -> -14000 | H12: =47800+250+500 -> 48550 | I12: =H12 -> 48550 | J12: =I12-I$4 -> -17600 | K12: =49400+250+1500 -> 51150 | L12: =K12 -> 51150 | M12: =L12-L$4 -> -14000 | N12: =49000+250+500 -> 49750 | O12: =N12 -> 49750 | P12: =O12-O$4 -> -16900 | Q12: =49000+250+500 -> 49750 | R12: =Q12 -> 49750 | S12: =R12-R$4 -> -15900 | T12: =B12 -> 51650 | U12: =C12 -> 51650 | V12: =U12-U$4 -> -14500 | W12: =Q12 -> 49750 | X12: =R12 -> 49750 | Y12: =X12-X$4 -> -15900 | Z12: =49000+250+1500 -> 50750 | AA12: =Z12 -> 50750 | AB12: =AA12-AA$4 -> -15400

Sheet 2_Cost break up_Distr to dealer
T1: Fe 550 D (NCR, HR, UK, RJ, UP) | X1: Fe 550 (NCR, HR, UK, RJ, UP)
A2: Particulars | B2: Neo (RJ) | C2: Neo (NCR) | D2: TSL | E2: JSPL (NCR) | F2: JSPL (UP) | G2: SAIL (Stock) | H2: JSW One bend (B2S2) | T2: JSW One (B2S2) | U2: JSW One (Stock) | V2: JSW One bend (B2S2) | W2: JSW One bend (Stock) | X2: JSW One (B2S2) | Y2: JSW One (Stock) | Z2: JSW One bend (B2S2) | AA2: JSW One bend (Stock)
A3: Form | B3: Straight | C3: Straight | D3: Straight | E3: Straight | F3: Straight | G3: Straight | H3: Bend | T3: Straight | U3: Straight | V3: Bend | W3: Bend | X3: Straight | Y3: Straight | Z3: Bend | AA3: Bend
A4: Handling/Bending | B4: 500 | C4: 800 | D4: 1000 | E4: 600 | F4: 600 | G4: 500 | H4: 600 | T4: 0 | U4: 500 | V4: 0 | W4: 0 | X4: 0 | Y4: 500 | Z4: 0 | AA4: 0
A5: ECP Provision | B5: =30%*1500 -> 450 | C5: =30%*1500 -> 450 | H5: 450 | T5: 450 | U5: =T5 -> 450 | V5: =U5 -> 450 | W5: =V5 -> 450 | X5: 450 | Y5: =X5 -> 450 | Z5: =Y5 -> 450 | AA5: =Z5 -> 450
A6: freight to dealer | B6: 750 | C6: =B6 -> 750 | D6: 750 | E6: =C6 -> 750 | F6: 1000 | G6: =E6 -> 750 | T6: 0 | U6: =B6 -> 750 | V6: 0 | W6: =B6 -> 750 | X6: 0 | Y6: =B6 -> 750 | Z6: 0 | AA6: =B6 -> 750
A7: Dist to dealer (incl generic cost to serve) | B7: =SUM(B4:B6) -> 1700 | C7: =SUM(C4:C6) -> 2000 | D7: =SUM(D4:D6) -> 1750 | E7: =SUM(E4:E6) -> 1350 | F7: =SUM(F4:F6) -> 1600 | G7: =SUM(G4:G6) -> 1250 | H7: =SUM(H4:H6) -> 1050 | T7: =SUM(T4:T6) -> 450 | U7: =SUM(U4:U6) -> 1700 | V7: =SUM(V4:V6) -> 450 | W7: =SUM(W4:W6) -> 1200 | X7: =SUM(X4:X6) -> 450 | Y7: =SUM(Y4:Y6) -> 1700 | Z7: =SUM(Z4:Z6) -> 450 | AA7: =SUM(AA4:AA6) -> 1200
A8: Distributor margin + admin + inventory | B8: 1000 | C8: =B8 -> 1000 | D8: 1000 | E8: =C8 -> 1000 | F8: =D8 -> 1000 | G8: 1000 | H8: 1000 | T8: 1000 | U8: =T8 -> 1000 | V8: =U8 -> 1000 | W8: =V8 -> 1000 | X8: =W8 -> 1000 | Y8: =X8 -> 1000 | Z8: =Y8 -> 1000 | AA8: =Z8 -> 1000
A9: Dealer landed costing (incl generic cost + bend) | B9: =B7+B8 -> 2700 | C9: =C7+C8 -> 3000 | D9: =D7+D8 -> 2750 | E9: =E7+E8 -> 2350 | F9: =F7+F8 -> 2600 | G9: =G7+G8 -> 2250 | H9: =H7+H8 -> 2050 | T9: =T7+T8 -> 1450 | U9: =U7+U8 -> 2700 | V9: =V7+V8 -> 1450 | W9: =W7+W8 -> 2200 | X9: =X7+X8 -> 1450 | Y9: =Y7+Y8 -> 2700 | Z9: =Z7+Z8 -> 1450 | AA9: =AA7+AA8 -> 2200
A10: Additional channel schemes | B10: 2500 | C10: 500 | D10: 1750 | E10: 250 | F10: 250 | G10: 0 | H10: 250 | T10: 150 | U10: 150 | V10: 150 | W10: 150 | X10: 150 | Y10: 150 | Z10: 150 | AA10: 150
A11: Additional channel provision | B11: 1300 | C11: =650-450 -> 200 | D11: 1150 | E11: 500 | F11: 500 | G11: 0 | T11: =150+100 -> 250 | U11: =150+100 -> 250 | V11: =150+100 -> 250 | W11: =150+100 -> 250 | X11: =150+100 -> 250 | Y11: =150+100 -> 250 | Z11: =150+100 -> 250 | AA11: =150+100 -> 250
A12: Dealer landed billing | B12: =B9+B10+B11 -> 6500 | C12: =C9+C10+C11 -> 3700 | D12: =D9+D10+D11 -> 5650 | E12: =E9+E10+E11 -> 3100 | F12: =F9+F10+F11 -> 3350 | G12: =G9+G10+G11 -> 2250 | H12: =H9+H10+H11 -> 2300 | T12: =T9+T10+T11 -> 1850 | U12: =U9+U10+U11 -> 3100 | V12: =V9+V10+V11 -> 1850 | W12: =W9+W10+W11 -> 2600 | X12: =X9+X10+X11 -> 1850 | Y12: =Y9+Y10+Y11 -> 3100 | Z12: =Z9+Z10+Z11 -> 1850 | AA12: =AA9+AA10+AA11 -> 2600
S13: Sales split | T13: 0.42 | U13: 0.26 | V13: 0.27 | W13: 0.05 | X13: 0.32 | Y13: 0.29 | Z13: 0.28 | AA13: 0.11
S14: Effective dealer landed | W14: =SUMPRODUCT(T9:W9,T13:W13) -> 1812.5 | AA14: =SUMPRODUCT(X9:AA9,X13:AA13) -> 1895
C17: Neo | D17: TSL - NCR | E17: NCR | F17: UP | H17: NCR | I17: Neo
A18: Handling/Bending | C18: =C19+C20 -> 800 | D18: =D19+D20 -> 1000 | E18: =E19+E20 -> 600 | F18: =F19+F20 -> 600 | H18: Distributor margin | I18: 700
A19: Bending, bundling | C19: 400 | D19: 500 | E19: 300 | F19: 300 | H19: Admin cost | I19: 250
A20: Handling | C20: 400 | D20: 500 | E20: 300 | F20: 300 | H20: Dealer Loyalty
A21: Dist margin | C21: =SUM(C22:C23) -> 1000 | D21: =SUM(D22:D23) -> 1000 | E21: =SUM(E22:E23) -> 1000 | F21: =SUM(F22:F23) -> 1000 | H21: CD
A22: Inventory CC | C22: 500 | D22: 500 | E22: 500 | F22: 500 | H22: QD | I22: 500
A23: Dist margin | C23: 500 | D23: 500 | E23: 500 | F23: 500 | H23: Shortage | I23: 150
A24: Frt to dealer | C24: 750 | D24: 750 | E24: 750 | F24: 1000 | H24: BTL Provision | I24: 400
H25: Handling/Bending | I25: 800
A26: Channel scheme | C26: 500 | D26: 1750 | E26: 250 | F26: 250 | H26: ECP Provision | I26: 375
H27: Dealer meet provision | I27: 200
H28: Contractor loyalty
A29: Channel prov | C29: =SUM(C30:C38) -> 650 | D29: =SUM(D30:D38) -> 1150 | E29: =SUM(E30:E38) -> 1000 | F29: =SUM(F30:F38) -> 1000 | H29: Contractor Meet provision
A30: Est cost | E30: 50 | F30: 50 | H30: freight to dealer | I30: 750
A31: ASO cost | E31: 200 | F31: 200 | H31: Bend cost | I31: =ROUND(SUM(I18:I30)-I22,-2) -> 3600
A32: Dealer loyalty | D32: 150
A33: Dealer meet | C33: 200 | D33: 800
A34: Cons activity | E34: 100 | F34: 100
A35: Influencer meet an | D35: 100 | E35: 150 | F35: 150
A36: Contractor loyalty | D36: 100
A37: ECP Provision | C37: 450
A38: Addl premium | E38: 500 | F38: 500
A39: Total cost | C39: =C18+C21+C24+C26+C29 -> 3700 | D39: =D18+D21+D24+D26+D29 -> 5650 | E39: =E18+E21+E24+E26+E29 -> 3600 | F39: =F18+F21+F24+F26+F29 -> 3850
A41: Co funded | E41: =E42+E43+E44 -> 830 | F41: =F42+F43+F44 -> 830
A42: Samaan | E42: 50 | F42: 50
A43: Provision for ILP | E43: 320 | F43: 320
...

Sheet 3_Summary less QD
A2: Market | B2: DL | G2: Haryana | J2: Jaipur | N2: Kanpur | R2: Chandigarh | V2: Ludhiana | Z2: Dehradun | AD2: Shimla | AH2: Jammu | AL2: Distri- Delear ladder
A3: <As on 9th Mar'26> | B3: Distr. level | C3: Gap with TSL | D3: Dealer level | E3: Gap with TSL | F3: Distr. level | G3: Gap with TSL | H3: Dealer level | I3: Gap with TSL | J3: Distr. level | K3: Gap with TSL | L3: Dealer level | M3: Gap with TSL | N3: Distr. level | O3: Gap with TSL | P3: Dealer level | Q3: Gap with TSL | R3: Distr. level | S3: Gap with TSL | T3: Dealer level | U3: Gap with TSL | V3: Distr. level | W3: Gap with TSL | X3: Dealer level | Y3: Gap with TSL | Z3: Distr. level | AA3: Gap with TSL | AB3: Dealer level | AC3: Gap with TSL | AD3: Distr. level | AE3: Gap with TSL | AF3: Dealer level | AG3: Gap with TSL | AH3: Distr. level | AI3: Gap with TSL | AJ3: Dealer level | AK3: Gap with TSL | AL3: NCR | AM3: Rest
A4: TISCON | B4: 60000 | C4: =B4-B$4 -> 0 | D4: =B4+AL4 -> 63900 | E4: =D4-D$4 -> 0 | F4: =B4 -> 60000 | G4: =F4-F$4 -> 0 | H4: =F4+$AM4 -> 63900 | I4: =H4-H$4 -> 0 | J4: =B4+500 -> 60500 | K4: =J4-J$4 -> 0 | L4: =J4+$AM4 -> 64400 | M4: =L4-L$4 -> 0 | N4: =B4-500 -> 59500 | O4: =N4-N$4 -> 0 | P4: =N4+$AM4 -> 63400 | Q4: =P4-P$4 -> 0 | R4: =B4+1000 -> 61000 | S4: =R4-R$4 -> 0 | T4: =R4+$AM4 -> 64900 | U4: =T4-T$4 -> 0 | V4: =B4+500 -> 60500 | W4: =V4-V$4 -> 0 | X4: =V4+AM4-500 -> 63900 | Y4: =X4-X$4 -> 0 | Z4: =B4+500 -> 60500 | AA4: =Z4-Z$4 -> 0 | AB4: =Z4+AM4 -> 64400 | AC4: =AB4-AB$4 -> 0 | AD4: =B4 -> 60000 | AE4: =AD4-AD$4 -> 0 | AF4: =AD4+AM4 -> 63900 | AG4: =AF4-AF$4 -> 0 | AH4: =B4+500 -> 60500 | AI4: =AH4-AH$4 -> 0 | AJ4: =AH4+AM4 -> 64400 | AK4: =AJ4-AJ$4 -> 0 | AL4: =5650-1750 -> 3900 | AM4: =AL4 -> 3900
A5: Neo | B5: 59150 | C5: =B5-B$4 -> -850 | D5: =B5+AL5 -> 62350 | E5: =D5-D$4 -> -1550 | F5: =B5 -> 59150 | G5: =F5-F$4 -> -850 | H5: =F5+$AM5 -> 62350 | I5: =H5-H$4 -> -1550 | J5: =B5 -> 59150 | K5: =J5-J$4 -> -1350 | L5: =J5+$AM5 -> 62350 | M5: =L5-L$4 -> -2050 | N5: =B5 -> 59150 | O5: =N5-N$4 -> -350 | P5: =N5+$AM5 -> 62350 | Q5: =P5-P$4 -> -1050 | R5: =B5 -> 59150 | S5: =R5-R$4 -> -1850 | T5: =R5+$AM5 -> 62350 | U5: =T5-T$4 -> -2550 | V5: =B5+500 -> 59650 | W5: =V5-V$4 -> -850 | X5: =V5+AM5-500 -> 62350 | Y5: =X5-X$4 -> -1550 | Z5: =B5 -> 59150 | AA5: =Z5-Z$4 -> -1350 | AB5: =Z5+AM5 -> 62350 | AC5: =AB5-AB$4 -> -2050 | AD5: =B5+500 -> 59650 | AE5: =AD5-AD$4 -> -350 | AF5: =AD5+AM5 -> 62850 | AG5: =AF5-AF$4 -> -1050 | AH5: =B5+1500 -> 60650 | AI5: =AH5-AH$4 -> 150 | AJ5: =AH5+AM5 -> 63850 | AK5: =AJ5-AJ$4 -> -550 | AL5: =3700-500 -> 3200 | AM5: =AL5 -> 3200
A6: JSPL | B6: 58500 | C6: =B6-B$4 -> -1500 | D6: =B6+AL6 -> 61350 | E6: =D6-D$4 -> -2550 | F6: NA | G6: NA | H6: 58650 | I6: =H6-H$4 -> -5250 | J6: =B6+250 -> 58750 | K6: =J6-J$4 -> -1750 | L6: =J6+$AM6 -> 61600 | M6: =L6-L$4 -> -2800 | N6: =B6-500 -> 58000 | O6: =N6-N$4 -> -1500 | P6: =N6+$AM6 -> 60850 | Q6: =P6-P$4 -> -2550 | R6: =B6+500 -> 59000 | S6: =R6-R$4 -> -2000 | T6: =R6+$AM6 -> 61850 | U6: =T6-T$4 -> -3050 | V6: =B6+250 -> 58750 | W6: =V6-V$4 -> -1750 | X6: =V6+AM6-500 -> 61100 | Y6: =X6-X$4 -> -2800 | Z6: =B6+500 -> 59000 | AA6: =Z6-Z$4 -> -1500 | AB6: =Z6+AM6 -> 61850 | AC6: =AB6-AB$4 -> -2550 | AD6: =B6+500 -> 59000 | AE6: =AD6-AD$4 -> -1000 | AF6: =AD6+AM6 -> 61850 | AG6: =AF6-AF$4 -> -2050 | AH6: =B6+500 -> 59000 | AI6: =AH6-AH$4 -> -1500 | AJ6: =AH6+AM6 -> 61850 | AK6: =AJ6-AJ$4 -> -2550 | AL6: =3600-750 -> 2850 | AM6: =AL6 -> 2850
A7: SAIL | B7: 59500 | C7: =B7-B$4 -> -500 | D7: =B7+AL7 -> 61750 | E7: =D7-D$4 -> -2150 | F7: =B7 -> 59500 | G7: =F7-F$4 -> -500 | H7: =F7+$AM7 -> 61750 | I7: =H7-H$4 -> -2150 | J7: =B7-250 -> 59250 | K7: =J7-J$4 -> -1250 | L7: =J7+$AM7 -> 61500 | M7: =L7-L$4 -> -2900 | N7: =B7-500 -> 59000 | O7: =N7-N$4 -> -500 | P7: =N7+$AM7 -> 61250 | Q7: =P7-P$4 -> -2150 | R7: =B7+500 -> 60000 | S7: =R7-R$4 -> -1000 | T7: =R7+$AM7 -> 62250 | U7: =T7-T$4 -> -2650 | V7: =B7+500 -> 60000 | W7: =V7-V$4 -> -500 | X7: =V7+AM7-500 -> 61750 | Y7: =X7-X$4 -> -2150 | Z7: =B7+500 -> 60000 | AA7: =Z7-Z$4 -> -500 | AB7: =Z7+AM7 -> 62250 | AC7: =AB7-AB$4 -> -2150 | AD7: =B7+1000 -> 60500 | AE7: =AD7-AD$4 -> 500 | AF7: =AD7+AM7 -> 62750 | AG7: =AF7-AF$4 -> -1150 | AH7: =B7+2000 -> 61500 | AI7: =AH7-AH$4 -> 1000 | AJ7: =AH7+AM7 -> 63750 | AK7: =AJ7-AJ$4 -> -650 | AL7: 2250 | AM7: =AL7 -> 2250
A8: JSW One Fe 550D | B8: 58400 | C8: =B8-B$4 -> -1600 | D8: =B8+AL8 -> 60700 | E8: =D8-D$4 -> -3200 | F8: =B8 -> 58400 | G8: =F8-F$4 -> -1600 | H8: =F8+$AM8 -> 60700 | I8: =H8-H$4 -> -3200 | J8: =B8 -> 58400 | K8: =J8-J$4 -> -2100 | L8: =J8+$AM8 -> 60700 | M8: =L8-L$4 -> -3700 | N8: =B8 -> 58400 | O8: =N8-N$4 -> -1100 | P8: =N8+$AM8 -> 60700 | Q8: =P8-P$4 -> -2700 | R8: =B8+250 -> 58650 | S8: =R8-R$4 -> -2350 | T8: =R8+$AM8 -> 60950 | U8: =T8-T$4 -> -3950 | V8: =B8+500 -> 58900 | W8: =V8-V$4 -> -1600 | X8: =V8+AM8-500 -> 60700 | Y8: =X8-X$4 -> -3200 | Z8: =B8+500 -> 58900 | AA8: =Z8-Z$4 -> -1600 | AB8: =Z8+AM8 -> 61200 | AC8: =AB8-AB$4 -> -3200 | AD8: =B8+1000 -> 59400 | AE8: =AD8-AD$4 -> -600 | AF8: =AD8+AM8 -> 61700 | AG8: =AF8-AF$4 -> -2200 | AH8: =B8+2000 -> 60400 | AI8: =AH8-AH$4 -> -100 | AJ8: =AH8+AM8 -> 62700 | AK8: =AJ8-AJ$4 -> -1700 | AL8: 2300 | AM8: 2300
A9: <General SAIL position> | H9: =F9+$AM9 -> 0 | L9: =J9+$AM9 -> 0 | P9: =N9+$AM9 -> 0 | T9: =R9+$AM9 -> 0 | AF9: =AD9+AM9 -> 0 | AJ9: =AH9+AM9 -> 0
A10: JSW One Fe 550 | B10: 57400 | C10: =B10-B$4 -> -2600 | D10: =B10+AL10 -> 59700 | E10: =D10-D$4 -> -4200 | F10: =B10 -> 57400 | G10: =F10-F$4 -> -2600 | H10: =F10+$AM10 -> 59700 | I10: =H10-H$4 -> -4200 | J10: =B10 -> 57400 | K10: =J10-J$4 -> -3100 | L10: =J10+$AM10 -> 59700 | M10: =L10-L$4 -> -4700 | N10: =B10 -> 57400 | O10: =N10-N$4 -> -2100 | P10: =N10+$AM10 -> 59700 | Q10: =P10-P$4 -> -3700 | R10: =B10+250 -> 57650 | S10: =R10-R$4 -> -3350 | T10: =R10+$AM10 -> 59950 | U10: =T10-T$4 -> -4950 | V10: =B10+500 -> 57900 | W10: =V10-V$4 -> -2600 | X10: =V10+AM10-500 -> 59700 | Y10: =X10-X$4 -> -4200 | Z10: =B10 -> 57400 | AA10: =Z10-Z$4 -> -3100 | AB10: =Z10+AM10 -> 59700 | AC10: =AB10-AB$4 -> -4700 | AD10: =B10+500 -> 57900 | AE10: =AD10-AD$4 -> -2100 | AF10: =AD10+AM10 -> 60200 | AG10: =AF10-AF$4 -> -3700 | AH10: =B10+1500 -> 58900 | AI10: =AH10-AH$4 -> -1600 | AJ10: =AH10+AM10 -> 61200 | AK10: =AJ10-AJ$4 -> -3200 | AL10: 2300 | AM10: 2300
A11: Branded prem sec. | B11: =D11-250 -> 52400 | C11: =B11-B$4 -> -7600 | D11: =D12+1000 -> 52650 | E11: =D11-D$4 -> -11250 | F11: =B11 -> 52400 | G11: =F11-F$4 -> -7600 | H11: =D11 -> 52650 | I11: =H11-H$4 -> -11250 | J11: =L11-250 -> 49300 | K11: =J11-J$4 -> -11200 | L11: =L12+1000 -> 49550 | M11: =L11-L$4 -> -14850 | N11: =P11-250 -> 51900 | O11: =N11-N$4 -> -7600 | P11: =P12+1000 -> 52150 | Q11: =P11-P$4 -> -11250 | R11: =T11-250 -> 50500 | S11: =R11-R$4 -> -10500 | T11: =T12+1000 -> 50750 | U11: =T11-T$4 -> -14150 | V11: =X11-250 -> 51000 | W11: =V11-V$4 -> -9500 | X11: =X12+1500 -> 51250 | Y11: =X11-X$4 -> -12650 | Z11: =AB11-250 -> 51900 | AA11: =Z11-Z$4 -> -8600 | AB11: =AB12+500 -> 52150 | AC11: =AB11-AB$4 -> -12250 | AD11: =AF11-250 -> 50500 | AE11: =AD11-AD$4 -> -9500 | AF11: =AF12+1000 -> 50750 | AG11: =AF11-AF$4 -> -13150 | AH11: =AH12+250+1500+1000 -> 53500 | AI11: =AH11-AH$4 -> -7000 | AJ11: =AJ12+1000 -> 51750 | AK11: =AJ11-AJ$4 -> -12650 | AL11: 1450 | AM11: 1450
A12: Steelmint | B12: =50400+250+1000 -> 51650 | C12: =B12-B$4 -> -8350 | D12: =B12 -> 51650 | E12: =D12-D$4 -> -12250 | F12: =B12 -> 51650 | G12: =F12-F$4 -> -8350 | H12: =D12 -> 51650 | I12: =H12-H$4 -> -12250 | J12: =47800+250+500 -> 48550 | K12: =J12-J$4 -> -11950 | L12: =J12 -> 48550 | M12: =L12-L$4 -> -15850 | N12: =49400+250+1500 -> 51150 | O12: =N12-N$4 -> -8350 | P12: =N12 -> 51150 | Q12: =P12-P$4 -> -12250 | R12: =49000+250+500 -> 49750 | S12: =R12-R$4 -> -11250 | T12: =R12 -> 49750 | U12: =T12-T$4 -> -15150 | V12: =49000+250+500 -> 49750 | W12: =V12-V$4 -> -10750 | X12: =V12 -> 49750 | Y12: =X12-X$4 -> -14150 | Z12: =B12 -> 51650 | AA12: =Z12-Z$4 -> -8850 | AB12: =D12 -> 51650 | AC12: =AB12-AB$4 -> -12750 | AD12: =V12 -> 49750 | AE12: =AD12-AD$4 -> -10250 | AF12: =X12 -> 49750 | AG12: =AF12-AF$4 -> -14150 | AH12: =49000+250+1500 -> 50750 | AI12: =AH12-AH$4 -> -9750 | AJ12: =AH12 -> 50750 | AK12: =AJ12-AJ$4 -> -13650

Sheet 4_Summary prevailing dlr level
A2: Market | B2: DL | D2: HR | F2: RJ | H2: UP E + C | J2: CH | L2: PB | N2: UK | P2: HP | R2: Jammu | T2: Distri- Delear ladder
A3: <As on 9th Mar'26> | B3: Dealer level | C3: Gap with TSL | D3: Dealer level | E3: Gap with TSL | F3: Dealer level | G3: Gap with TSL | H3: Dealer level | I3: Gap with TSL | J3: Dealer level | K3: Gap with TSL | L3: Dealer level | M3: Gap with TSL | N3: Dealer level | O3: Gap with TSL | P3: Dealer level | Q3: Gap with TSL | R3: Dealer level | S3: Gap with TSL | T3: NCR | U3: Rest
A4: TISCON | B4: ='3_Summary less QD'!D4-2000 -> 61900 | C4: =B4-B$4 -> 0 | D4: ='3_Summary less QD'!H4-2000 -> 61900 | E4: =D4-D$4 -> 0 | F4: ='3_Summary less QD'!L4-2000 -> 62400 | G4: =F4-F$4 -> 0 | H4: ='3_Summary less QD'!P4-2000 -> 61400 | I4: =H4-H$4 -> 0 | J4: ='3_Summary less QD'!T4-2000 -> 62900 | K4: =J4-J$4 -> 0 | L4: =#REF!+U4-500 -> #REF! | M4: =L4-L$4 -> #REF! | N4: =#REF!+U4 -> #REF! | O4: =N4-N$4 -> #REF! | P4: =#REF!+U4 -> #REF! | Q4: =P4-P$4 -> #REF! | R4: =#REF!+U4 -> #REF! | S4: =R4-R$4 -> #REF! | T4: =5650-1750 -> 3900 | U4: =T4 -> 3900
A5: Neo | B5: ='3_Summary less QD'!D5-1000 -> 61350 | C5: =B5-B$4 -> -550 | D5: ='3_Summary less QD'!H5-1000 -> 61350 | E5: =D5-D$4 -> -550 | F5: ='3_Summary less QD'!L5-1000 -> 61350 | G5: =F5-F$4 -> -1050 | H5: ='3_Summary less QD'!P5-1000 -> 61350 | I5: =H5-H$4 -> -50 | J5: ='3_Summary less QD'!T5-1000 -> 61350 | K5: =J5-J$4 -> -1550 | L5: =#REF!+U5-500 -> #REF! | M5: =L5-L$4 -> #REF! | N5: =#REF!+U5 -> #REF! | O5: =N5-N$4 -> #REF! | P5: =#REF!+U5 -> #REF! | Q5: =P5-P$4 -> #REF! | R5: =#REF!+U5 -> #REF! | S5: =R5-R$4 -> #REF! | T5: =3700-500 -> 3200 | U5: =T5 -> 3200
A6: JSPL | B6: ='3_Summary less QD'!D6-500 -> 60850 | C6: =B6-B$4 -> -1050 | D6: ='3_Summary less QD'!H6-500 -> 58150 | E6: =D6-D$4 -> -3750 | F6: ='3_Summary less QD'!L6-500 -> 61100 | G6: =F6-F$4 -> -1300 | H6: ='3_Summary less QD'!P6-500 -> 60350 | I6: =H6-H$4 -> -1050 | J6: ='3_Summary less QD'!T6-500 -> 61350 | K6: =J6-J$4 -> -1550 | L6: =#REF!+U6-500 -> #REF! | M6: =L6-L$4 -> #REF! | N6: =#REF!+U6 -> #REF! | O6: =N6-N$4 -> #REF! | P6: =#REF!+U6 -> #REF! | Q6: =P6-P$4 -> #REF! | R6: =#REF!+U6 -> #REF! | S6: =R6-R$4 -> #REF! | T6: =3600-750 -> 2850 | U6: =T6 -> 2850
A7: SAIL | B7: ='3_Summary less QD'!D7-1500 -> 60250 | C7: =B7-B$4 -> -1650 | D7: ='3_Summary less QD'!H7-1500 -> 60250 | E7: =D7-D$4 -> -1650 | F7: ='3_Summary less QD'!L7-1500 -> 60000 | G7: =F7-F$4 -> -2400 | H7: ='3_Summary less QD'!P7-1500 -> 59750 | I7: =H7-H$4 -> -1650 | J7: ='3_Summary less QD'!T7-1500 -> 60750 | K7: =J7-J$4 -> -2150 | L7: =#REF!+U7-500 -> #REF! | M7: =L7-L$4 -> #REF! | N7: =#REF!+U7 -> #REF! | O7: =N7-N$4 -> #REF! | P7: =#REF!+U7 -> #REF! | Q7: =P7-P$4 -> #REF! | R7: =#REF!+U7 -> #REF! | S7: =R7-R$4 -> #REF! | T7: 2250 | U7: =T7 -> 2250
A8: JSW One Fe 550D | B8: ='3_Summary less QD'!D8 -> 60700 | C8: =B8-B$4 -> -1200 | D8: ='3_Summary less QD'!H8 -> 60700 | E8: =D8-D$4 -> -1200 | F8: ='3_Summary less QD'!L8 -> 60700 | G8: =F8-F$4 -> -1700 | H8: ='3_Summary less QD'!P8 -> 60700 | I8: =H8-H$4 -> -700 | J8: ='3_Summary less QD'!T8 -> 60950 | K8: =J8-J$4 -> -1950 | L8: =#REF!+U8-500 -> #REF! | M8: =L8-L$4 -> #REF! | N8: =#REF!+U8 -> #REF! | O8: =N8-N$4 -> #REF! | P8: =#REF!+U8 -> #REF! | Q8: =P8-P$4 -> #REF! | R8: =#REF!+U8 -> #REF! | S8: =R8-R$4 -> #REF! | T8: 2300 | U8: 2300
A9: <General SAIL position> | H9: ='3_Summary less QD'!P9 -> 0 | J9: ='3_Summary less QD'!T9 -> 0 | P9: =#REF!+U9 -> #REF! | R9: =#REF!+U9 -> #REF!
A10: JSW One Fe 550 | B10: ='3_Summary less QD'!D10 -> 59700 | C10: =B10-B$4 -> -2200 | D10: ='3_Summary less QD'!H10 -> 59700 | E10: =D10-D$4 -> -2200 | F10: ='3_Summary less QD'!L10 -> 59700 | G10: =F10-F$4 -> -2700 | H10: ='3_Summary less QD'!P10 -> 59700 | I10: =H10-H$4 -> -1700 | J10: ='3_Summary less QD'!T10 -> 59950 | K10: =J10-J$4 -> -2950 | L10: =#REF!+U10-500 -> #REF! | M10: =L10-L$4 -> #REF! | N10: =#REF!+U10 -> #REF! | O10: =N10-N$4 -> #REF! | P10: =#REF!+U10 -> #REF! | Q10: =P10-P$4 -> #REF! | R10: =#REF!+U10 -> #REF! | S10: =R10-R$4 -> #REF! | T10: 2300 | U10: 2300
A11: Branded prem sec. | B11: ='3_Summary less QD'!D11 -> 52650 | C11: =B11-B$4 -> -9250 | D11: ='3_Summary less QD'!H11 -> 52650 | E11: =D11-D$4 -> -9250 | F11: ='3_Summary less QD'!L11 -> 49550 | G11: =F11-F$4 -> -12850 | H11: ='3_Summary less QD'!P11 -> 52150 | I11: =H11-H$4 -> -9250 | J11: ='3_Summary less QD'!T11 -> 50750 | K11: =J11-J$4 -> -12150 | L11: =L12+1500 -> #REF! | M11: =L11-L$4 -> #REF! | N11: =N12+500 -> 52150 | O11: =N11-N$4 -> #REF! | P11: =P12+1000 -> #REF! | Q11: =P11-P$4 -> #REF! | R11: =R12+1000 -> #REF! | S11: =R11-R$4 -> #REF! | T11: 1450 | U11: 1450
A12: Steelmint | B12: ='3_Summary less QD'!D12 -> 51650 | C12: =B12-B$4 -> -10250 | D12: ='3_Summary less QD'!H12 -> 51650 | E12: =D12-D$4 -> -10250 | F12: ='3_Summary less QD'!L12 -> 48550 | G12: =F12-F$4 -> -13850 | H12: ='3_Summary less QD'!P12 -> 51150 | I12: =H12-H$4 -> -10250 | J12: ='3_Summary less QD'!T12 -> 49750 | K12: =J12-J$4 -> -13150 | L12: =#REF! -> #REF! | M12: =L12-L$4 -> #REF! | N12: =B12 -> 51650 | O12: =N12-N$4 -> #REF! | P12: =L12 -> #REF! | Q12: =P12-P$4 -> #REF! | R12: =#REF! -> #REF! | S12: =R12-R$4 -> #REF!

Sheet back up->1_Summary at PL (2)
A2: Market | B2: DL | G2: Haryana | J2: Jaipur | N2: Kanpur | R2: Chandigarh | V2: Ludhiana | Z2: Dehradun | AD2: Shimla | AH2: Jammu | AL2: Distri- Delear ladder
A3: <As on 9th Mar'26> | B3: Distr. level | C3: Gap with TSL | D3: Dealer level | E3: Gap with TSL | F3: Distr. level | G3: Gap with TSL | H3: Dealer level | I3: Gap with TSL | J3: Distr. level | K3: Gap with TSL | L3: Dealer level | M3: Gap with TSL | N3: Distr. level | O3: Gap with TSL | P3: Dealer level | Q3: Gap with TSL | R3: Distr. level | S3: Gap with TSL | T3: Dealer level | U3: Gap with TSL | V3: Distr. level | W3: Gap with TSL | X3: Dealer level | Y3: Gap with TSL | Z3: Distr. level | AA3: Gap with TSL | AB3: Dealer level | AC3: Gap with TSL | AD3: Distr. level | AE3: Gap with TSL | AF3: Dealer level | AG3: Gap with TSL | AH3: Distr. level | AI3: Gap with TSL | AJ3: Dealer level | AK3: Gap with TSL | AL3: NCR | AM3: Rest
A4: TISCON | B4: 60000 | C4: =B4-B$4 -> 0 | D4: =B4+AL4 -> 65650 | E4: =D4-D$4 -> 0 | F4: =B4 -> 60000 | G4: =F4-F$4 -> 0 | H4: =F4+$AM4 -> 65650 | I4: =H4-H$4 -> 0 | J4: =B4+500 -> 60500 | K4: =J4-J$4 -> 0 | L4: =J4+$AM4 -> 66150 | M4: =L4-L$4 -> 0 | N4: =B4-500 -> 59500 | O4: =N4-N$4 -> 0 | P4: =N4+$AM4 -> 65150 | Q4: =P4-P$4 -> 0 | R4: =B4+1000 -> 61000 | S4: =R4-R$4 -> 0 | T4: =R4+$AM4 -> 66650 | U4: =T4-T$4 -> 0 | V4: =B4+500 -> 60500 | W4: =V4-V$4 -> 0 | X4: =V4+AM4-500 -> 65650 | Y4: =X4-X$4 -> 0 | Z4: =B4+500 -> 60500 | AA4: =Z4-Z$4 -> 0 | AB4: =Z4+AM4 -> 66150 | AC4: =AB4-AB$4 -> 0 | AD4: =B4 -> 60000 | AE4: =AD4-AD$4 -> 0 | AF4: =AD4+AM4 -> 65650 | AG4: =AF4-AF$4 -> 0 | AH4: =B4+500 -> 60500 | AI4: =AH4-AH$4 -> 0 | AJ4: =AH4+AM4 -> 66150 | AK4: =AJ4-AJ$4 -> 0 | AL4: 5650 | AM4: =AL4 -> 5650
A5: Neo | B5: 59150 | C5: =B5-B$4 -> -850 | D5: =B5+AL5 -> 62850 | E5: =D5-D$4 -> -2800 | F5: =B5 -> 59150 | G5: =F5-F$4 -> -850 | H5: =F5+$AM5 -> 62850 | I5: =H5-H$4 -> -2800 | J5: =B5 -> 59150 | K5: =J5-J$4 -> -1350 | L5: =J5+$AM5 -> 62850 | M5: =L5-L$4 -> -3300 | N5: =B5 -> 59150 | O5: =N5-N$4 -> -350 | P5: =N5+$AM5 -> 62850 | Q5: =P5-P$4 -> -2300 | R5: =B5 -> 59150 | S5: =R5-R$4 -> -1850 | T5: =R5+$AM5 -> 62850 | U5: =T5-T$4 -> -3800 | V5: =B5+500 -> 59650 | W5: =V5-V$4 -> -850 | X5: =V5+AM5-500 -> 62850 | Y5: =X5-X$4 -> -2800 | Z5: =B5 -> 59150 | AA5: =Z5-Z$4 -> -1350 | AB5: =Z5+AM5 -> 62850 | AC5: =AB5-AB$4 -> -3300 | AD5: =B5+500 -> 59650 | AE5: =AD5-AD$4 -> -350 | AF5: =AD5+AM5 -> 63350 | AG5: =AF5-AF$4 -> -2300 | AH5: =B5+1500 -> 60650 | AI5: =AH5-AH$4 -> 150 | AJ5: =AH5+AM5 -> 64350 | AK5: =AJ5-AJ$4 -> -1800 | AL5: 3700 | AM5: =AL5 -> 3700
A6: JSPL | B6: 58500 | C6: =B6-B$4 -> -1500 | D6: =B6+AL6 -> 62100 | E6: =D6-D$4 -> -3550 | F6: NA | G6: NA | H6: 58650 | I6: =H6-H$4 -> -7000 | J6: =B6+250 -> 58750 | K6: =J6-J$4 -> -1750 | L6: =J6+$AM6 -> 62600 | M6: =L6-L$4 -> -3550 | N6: =B6-500 -> 58000 | O6: =N6-N$4 -> -1500 | P6: =N6+$AM6 -> 61850 | Q6: =P6-P$4 -> -3300 | R6: =B6+500 -> 59000 | S6: =R6-R$4 -> -2000 | T6: =R6+$AM6 -> 62850 | U6: =T6-T$4 -> -3800 | V6: =B6+250 -> 58750 | W6: =V6-V$4 -> -1750 | X6: =V6+AM6-500 -> 62100 | Y6: =X6-X$4 -> -3550 | Z6: =B6+500 -> 59000 | AA6: =Z6-Z$4 -> -1500 | AB6: =Z6+AM6 -> 62850 | AC6: =AB6-AB$4 -> -3300 | AD6: =B6+500 -> 59000 | AE6: =AD6-AD$4 -> -1000 | AF6: =AD6+AM6 -> 62850 | AG6: =AF6-AF$4 -> -2800 | AH6: =B6+500 -> 59000 | AI6: =AH6-AH$4 -> -1500 | AJ6: =AH6+AM6 -> 62850 | AK6: =AJ6-AJ$4 -> -3300 | AL6: 3600 | AM6: 3850
A7: SAIL | B7: 59500 | C7: =B7-B$4 -> -500 | D7: =B7+AL7 -> 61750 | E7: =D7-D$4 -> -3900 | F7: =B7 -> 59500 | G7: =F7-F$4 -> -500 | H7: =F7+$AM7 -> 61750 | I7: =H7-H$4 -> -3900 | J7: =B7-250 -> 59250 | K7: =J7-J$4 -> -1250 | L7: =J7+$AM7 -> 61500 | M7: =L7-L$4 -> -4650 | N7: =B7-500 -> 59000 | O7: =N7-N$4 -> -500 | P7: =N7+$AM7 -> 61250 | Q7: =P7-P$4 -> -3900 | R7: =B7+500 -> 60000 | S7: =R7-R$4 -> -1000 | T7: =R7+$AM7 -> 62250 | U7: =T7-T$4 -> -4400 | V7: =B7+500 -> 60000 | W7: =V7-V$4 -> -500 | X7: =V7+AM7-500 -> 61750 | Y7: =X7-X$4 -> -3900 | Z7: =B7+500 -> 60000 | AA7: =Z7-Z$4 -> -500 | AB7: =Z7+AM7 -> 62250 | AC7: =AB7-AB$4 -> -3900 | AD7: =B7+1000 -> 60500 | AE7: =AD7-AD$4 -> 500 | AF7: =AD7+AM7 -> 62750 | AG7: =AF7-AF$4 -> -2900 | AH7: =B7+2000 -> 61500 | AI7: =AH7-AH$4 -> 1000 | AJ7: =AH7+AM7 -> 63750 | AK7: =AJ7-AJ$4 -> -2400 | AL7: 2250 | AM7: =AL7 -> 2250
A8: JSW One Fe 550D | B8: 58400 | C8: =B8-B$4 -> -1600 | D8: =B8+AL8 -> 60700 | E8: =D8-D$4 -> -4950 | F8: =B8 -> 58400 | G8: =F8-F$4 -> -1600 | H8: =F8+$AM8 -> 60700 | I8: =H8-H$4 -> -4950 | J8: =B8 -> 58400 | K8: =J8-J$4 -> -2100 | L8: =J8+$AM8 -> 60700 | M8: =L8-L$4 -> -5450 | N8: =B8 -> 58400 | O8: =N8-N$4 -> -1100 | P8: =N8+$AM8 -> 60700 | Q8: =P8-P$4 -> -4450 | R8: =B8+250 -> 58650 | S8: =R8-R$4 -> -2350 | T8: =R8+$AM8 -> 60950 | U8: =T8-T$4 -> -5700 | V8: =B8+500 -> 58900 | W8: =V8-V$4 -> -1600 | X8: =V8+AM8-500 -> 60700 | Y8: =X8-X$4 -> -4950 | Z8: =B8+500 -> 58900 | AA8: =Z8-Z$4 -> -1600 | AB8: =Z8+AM8 -> 61200 | AC8: =AB8-AB$4 -> -4950 | AD8: =B8+1000 -> 59400 | AE8: =AD8-AD$4 -> -600 | AF8: =AD8+AM8 -> 61700 | AG8: =AF8-AF$4 -> -3950 | AH8: =B8+2000 -> 60400 | AI8: =AH8-AH$4 -> -100 | AJ8: =AH8+AM8 -> 62700 | AK8: =AJ8-AJ$4 -> -3450 | AL8: 2300 | AM8: 2300
A9: <General SAIL position> | H9: =F9+$AM9 -> 0 | L9: =J9+$AM9 -> 0 | P9: =N9+$AM9 -> 0 | T9: =R9+$AM9 -> 0 | AF9: =AD9+AM9 -> 0 | AJ9: =AH9+AM9 -> 0
A10: JSW One Fe 550 | B10: 57400 | C10: =B10-B$4 -> -2600 | D10: =B10+AL10 -> 59700 | E10: =D10-D$4 -> -5950 | F10: =B10 -> 57400 | G10: =F10-F$4 -> -2600 | H10: =F10+$AM10 -> 59700 | I10: =H10-H$4 -> -5950 | J10: =B10 -> 57400 | K10: =J10-J$4 -> -3100 | L10: =J10+$AM10 -> 59700 | M10: =L10-L$4 -> -6450 | N10: =B10 -> 57400 | O10: =N10-N$4 -> -2100 | P10: =N10+$AM10 -> 59700 | Q10: =P10-P$4 -> -5450 | R10: =B10+250 -> 57650 | S10: =R10-R$4 -> -3350 | T10: =R10+$AM10 -> 59950 | U10: =T10-T$4 -> -6700 | V10: =B10+500 -> 57900 | W10: =V10-V$4 -> -2600 | X10: =V10+AM10-500 -> 59700 | Y10: =X10-X$4 -> -5950 | Z10: =B10 -> 57400 | AA10: =Z10-Z$4 -> -3100 | AB10: =Z10+AM10 -> 59700 | AC10: =AB10-AB$4 -> -6450 | AD10: =B10+500 -> 57900 | AE10: =AD10-AD$4 -> -2100 | AF10: =AD10+AM10 -> 60200 | AG10: =AF10-AF$4 -> -5450 | AH10: =B10+1500 -> 58900 | AI10: =AH10-AH$4 -> -1600 | AJ10: =AH10+AM10 -> 61200 | AK10: =AJ10-AJ$4 -> -4950 | AL10: 2300 | AM10: 2300
A11: Branded prem sec. | B11: =D11-250 -> 52400 | C11: =B11-B$4 -> -7600 | D11: =D12+1000 -> 52650 | E11: =D11-D$4 -> -13000 | F11: =B11 -> 52400 | G11: =F11-F$4 -> -7600 | H11: =D11 -> 52650 | I11: =H11-H$4 -> -13000 | J11: =L11-250 -> 49300 | K11: =J11-J$4 -> -11200 | L11: =L12+1000 -> 49550 | M11: =L11-L$4 -> -16600 | N11: =P11-250 -> 51900 | O11: =N11-N$4 -> -7600 | P11: =P12+1000 -> 52150 | Q11: =P11-P$4 -> -13000 | R11: =T11-250 -> 50500 | S11: =R11-R$4 -> -10500 | T11: =T12+1000 -> 50750 | U11: =T11-T$4 -> -15900 | V11: =X11-250 -> 51000 | W11: =V11-V$4 -> -9500 | X11: =X12+1500 -> 51250 | Y11: =X11-X$4 -> -14400 | Z11: =AB11-250 -> 51900 | AA11: =Z11-Z$4 -> -8600 | AB11: =AB12+500 -> 52150 | AC11: =AB11-AB$4 -> -14000 | AD11: =AF11-250 -> 50500 | AE11: =AD11-AD$4 -> -9500 | AF11: =AF12+1000 -> 50750 | AG11: =AF11-AF$4 -> -14900 | AH11: =AH12+250+1500+1000 -> 53500 | AI11: =AH11-AH$4 -> -7000 | AJ11: =AJ12+1000 -> 51750 | AK11: =AJ11-AJ$4 -> -14400 | AL11: 1450 | AM11: 1450
A12: Steelmint | B12: =50400+250+1000 -> 51650 | C12: =B12-B$4 -> -8350 | D12: =B12 -> 51650 | E12: =D12-D$4 -> -14000 | F12: =B12 -> 51650 | G12: =F12-F$4 -> -8350 | H12: =D12 -> 51650 | I12: =H12-H$4 -> -14000 | J12: =47800+250+500 -> 48550 | K12: =J12-J$4 -> -11950 | L12: =J12 -> 48550 | M12: =L12-L$4 -> -17600 | N12: =49400+250+1500 -> 51150 | O12: =N12-N$4 -> -8350 | P12: =N12 -> 51150 | Q12: =P12-P$4 -> -14000 | R12: =49000+250+500 -> 49750 | S12: =R12-R$4 -> -11250 | T12: =R12 -> 49750 | U12: =T12-T$4 -> -16900 | V12: =49000+250+500 -> 49750 | W12: =V12-V$4 -> -10750 | X12: =V12 -> 49750 | Y12: =X12-X$4 -> -15900 | Z12: =B12 -> 51650 | AA12: =Z12-Z$4 -> -8850 | AB12: =D12 -> 51650 | AC12: =AB12-AB$4 -> -14500 | AD12: =V12 -> 49750 | AE12: =AD12-AD$4 -> -10250 | AF12: =X12 -> 49750 | AG12: =AF12-AF$4 -> -15900 | AH12: =49000+250+1500 -> 50750 | AI12: =AH12-AH$4 -> -9750 | AJ12: =AH12 -> 50750 | AK12: =AJ12-AJ$4 -> -15400

Sheet Price Map
A1: Brand / Market | B1: DL | C1: HR | D1: RJ | E1: UP E+C | F1: CH | G1: PB | H1: UK | I1: HP | J1: J&K
A2: TISCON | B2: ='1_Summary at PL'!C4 -> 65650 | C2: ='1_Summary at PL'!F4 -> 65650 | D2: ='1_Summary at PL'!I4 -> 66150 | E2: ='1_Summary at PL'!L4 -> 65150 | F2: ='1_Summary at PL'!O4 -> 66650 | G2: ='1_Summary at PL'!R4 -> 65650 | H2: ='1_Summary at PL'!U4 -> 66150 | I2: ='1_Summary at PL'!X4 -> 65650 | J2: ='1_Summary at PL'!AA4 -> 66150
A3: Neo | B3: ='1_Summary at PL'!C5 -> 62850 | C3: ='1_Summary at PL'!F5 -> 62850 | D3: ='1_Summary at PL'!I5 -> 62850 | E3: ='1_Summary at PL'!L5 -> 62850 | F3: ='1_Summary at PL'!O5 -> 62850 | G3: ='1_Summary at PL'!R5 -> 62850 | H3: ='1_Summary at PL'!U5 -> 62850 | I3: ='1_Summary at PL'!X5 -> 63350 | J3: ='1_Summary at PL'!AA5 -> 64350
A4: JSPL | B4: ='1_Summary at PL'!C6 -> 62100 | C4: ='1_Summary at PL'!F6 -> 58650 | D4: ='1_Summary at PL'!I6 -> 62600 | E4: ='1_Summary at PL'!L6 -> 61850 | F4: ='1_Summary at PL'!O6 -> 62850 | G4: ='1_Summary at PL'!R6 -> 62100 | H4: ='1_Summary at PL'!U6 -> 62850 | I4: ='1_Summary at PL'!X6 -> 62850 | J4: ='1_Summary at PL'!AA6 -> 62850
A5: SAIL | B5: ='1_Summary at PL'!C7 -> 61750 | C5: ='1_Summary at PL'!F7 -> 61750 | D5: ='1_Summary at PL'!I7 -> 61500 | E5: ='1_Summary at PL'!L7 -> 61250 | F5: ='1_Summary at PL'!O7 -> 62250 | G5: ='1_Summary at PL'!R7 -> 61750 | H5: ='1_Summary at PL'!U7 -> 62250 | I5: ='1_Summary at PL'!X7 -> 62750 | J5: ='1_Summary at PL'!AA7 -> 63750
A6: JSW One Fe 550D | B6: ='1_Summary at PL'!C8 -> 60700 | C6: ='1_Summary at PL'!F8 -> 60700 | D6: ='1_Summary at PL'!I8 -> 60700 | E6: ='1_Summary at PL'!L8 -> 60700 | F6: ='1_Summary at PL'!O8 -> 60950 | G6: ='1_Summary at PL'!R8 -> 60700 | H6: ='1_Summary at PL'!U8 -> 61200 | I6: ='1_Summary at PL'!X8 -> 61700 | J6: ='1_Summary at PL'!AA8 -> 62700
A7: JSW One Fe 550 | B7: ='1_Summary at PL'!C10 -> 59700 | C7: ='1_Summary at PL'!F10 -> 59700 | D7: ='1_Summary at PL'!I10 -> 59700 | E7: ='1_Summary at PL'!L10 -> 59700 | F7: ='1_Summary at PL'!O10 -> 59950 | G7: ='1_Summary at PL'!R10 -> 59700 | H7: ='1_Summary at PL'!U10 -> 59700 | I7: ='1_Summary at PL'!X10 -> 60200 | J7: ='1_Summary at PL'!AA10 -> 61200
A8: Branded Prem Sec. | B8: ='1_Summary at PL'!C11 -> 52650 | C8: ='1_Summary at PL'!F11 -> 52650 | D8: ='1_Summary at PL'!I11 -> 49550 | E8: ='1_Summary at PL'!L11 -> 52150 | F8: ='1_Summary at PL'!O11 -> 50750 | G8: ='1_Summary at PL'!R11 -> 51250 | H8: ='1_Summary at PL'!U11 -> 52150 | I8: ='1_Summary at PL'!X11 -> 50750 | J8: ='1_Summary at PL'!AA11 -> 51750
A9: Steelmint | B9: ='1_Summary at PL'!C12 -> 51650 | C9: ='1_Summary at PL'!F12 -> 51650 | D9: ='1_Summary at PL'!I12 -> 48550 | E9: ='1_Summary at PL'!L12 -> 51150 | F9: ='1_Summary at PL'!O12 -> 49750 | G9: ='1_Summary at PL'!R12 -> 49750 | H9: ='1_Summary at PL'!U12 -> 51650 | I9: ='1_Summary at PL'!X12 -> 49750 | J9: ='1_Summary at PL'!AA12 -> 50750
