Workbook

Sheet #Dealers
D1: Quarter 1 | J1: Quarter 2 | P1: Quarter 3 | V1: Quarter 4
D2: One Helix | E2: JSW One | F2: One Helix | G2: JSW One | H2: One Helix | I2: JSW One | J2: One Helix | K2: JSW One | L2: One Helix | M2: JSW One | N2: One Helix | O2: JSW One | P2: One Helix | Q2: JSW One | R2: One Helix | S2: JSW One | T2: One Helix | U2: JSW One | V2: One Helix | W2: JSW One | X2: One Helix | Y2: JSW One | Z2: One Helix | AA2: JSW One
A3: # of Active Dealers | D3: 155 | E3: 742 | F3: 207 | G3: 995 | H3: 188 | I3: 789 | J3: 163 | K3: 735 | L3: 160 | M3: 641 | N3: 189 | O3: 643 | P3: 285 | Q3: 690 | R3: 404 | S3: 898 | T3: 490 | U3: 847 | V3: 646 | W3: 1067 | X3: 775 | Y3: 1173 | Z3: 972 | AA3: 1411
A4: Sr. No. | B4: State | C4: Zone | D4: 46138 | F4: 46168 | H4: 46199 | J4: 46229 | L4: 46260 | N4: 46291 | P4: 46321 | R4: 46352 | T4: 46382 | V4: 46049 | X4: 46080 | Z4: 46108
A5: 1 | B5: UTTAR PRADESH | C5: North | D5: 0 | E5: 152 | F5: 0 | G5: 184 | H5: 0 | I5: 168 | J5: 0 | K5: 152 | L5: 6 | M5: 101 | N5: 6 | O5: 108 | P5: 19 | Q5: 152 | R5: 38 | S5: 155 | T5: 60 | U5: 139 | V5: 89 | W5: 171 | X5: 114 | Y5: 171 | Z5: 165 | AA5: 184
A6: a# | B6: RAJASTHAN | C6: North | D6: 0 | E6: 59 | F6: 0 | G6: 71 | H6: 0 | I6: 67 | J6: 0 | K6: 59 | L6: 0 | M6: 54 | N6: 0 | O6: 57 | P6: 7 | Q6: 57 | R6: 10 | S6: 67 | T6: 22 | U6: 57 | V6: 27 | W6: 64 | X6: 44 | Y6: 54 | Z6: 71 | AA6: 67
A7: 3 | B7: DELHI | C7: North | D7: 0 | E7: 20 | F7: 0 | G7: 24 | H7: 0 | I7: 24 | J7: 0 | K7: 20 | L7: 0 | M7: 16 | N7: 0 | O7: 16 | P7: 4 | Q7: 20 | R7: 4 | S7: 20 | T7: 12 | U7: 16 | V7: 16 | W7: 16 | X7: 20 | Y7: 20 | Z7: 28 | AA7: 20
A8: 4 | B8: HARYANA | C8: North | D8: 0 | E8: 81 | F8: 0 | G8: 104 | H8: 0 | I8: 92 | J8: 0 | K8: 81 | L8: 0 | M8: 72 | N8: 0 | O8: 77 | P8: 7 | Q8: 86 | R8: 18 | S8: 90 | T8: 36 | U8: 77 | V8: 54 | W8: 99 | X8: 63 | Y8: 108 | Z8: 88 | AA8: 104
A9: 5 | B9: PUNJAB | C9: North | D9: 23 | E9: 0 | F9: 28 | G9: 0 | H9: 25 | I9: 0 | J9: 23 | K9: 0 | L9: 17 | M9: 0 | N9: 20 | O9: 0 | P9: 25 | Q9: 0 | R9: 31 | S9: 0 | T9: 34 | U9: 0 | V9: 42 | W9: 0 | X9: 48 | Y9: 0 | Z9: 57 | AA9: 28
A10: 6 | B10: UTTARAKHAND | C10: North | D10: 0 | E10: 26 | F10: 0 | G10: 39 | H10: 0 | I10: 32 | J10: 0 | K10: 26 | L10: 6 | M10: 19 | N10: 13 | O10: 13 | P10: 19 | Q10: 6 | R10: 39 | S10: 0 | T10: 39 | U10: 0 | V10: 52 | W10: 0 | X10: 58 | Y10: 0 | Z10: 64 | AA10: 0
A11: 7 | B11: JAMMU AND KASHMIR | C11: North | D11: 20 | E11: 0 | F11: 27 | G11: 0 | H11: 20 | I11: 0 | J11: 20 | K11: 0 | L11: 14 | M11: 0 | N11: 20 | O11: 0 | P11: 20 | Q11: 0 | R11: 27 | S11: 0 | T11: 27 | U11: 0 | V11: 41 | W11: 0 | X11: 41 | Y11: 0 | Z11: 54 | AA11: 0
A12: 8 | B12: HIMACHAL PRADESH | C12: North | D12: 5 | E12: 0 | F12: 5 | G12: 0 | H12: 5 | I12: 0 | J12: 5 | K12: 0 | L12: 5 | M12: 0 | N12: 5 | O12: 0 | P12: 5 | Q12: 0 | R12: 5 | S12: 0 | T12: 5 | U12: 0 | V12: 5 | W12: 0 | X12: 11 | Y12: 0 | Z12: 11 | AA12: 0
A13: 9 | B13: CHHATTISGARH | C13: Central | D13: 4 | E13: 0 | F13: 8 | G13: 0 | H13: 8 | I13: 0 | J13: 4 | K13: 0 | L13: 4 | M13: 0 | N13: 4 | O13: 0 | P13: 8 | Q13: 0 | R13: 8 | S13: 0 | T13: 8 | U13: 0 | V13: 12 | W13: 0 | X13: 16 | Y13: 0 | Z13: 16 | AA13: 0
A14: 10 | B14: ODISHA | C14: Central | D14: 38 | E14: 58 | F14: 53 | G14: 62 | H14: 48 | I14: 58 | J14: 38 | K14: 58 | L14: 34 | M14: 53 | N14: 38 | O14: 53 | P14: 53 | Q14: 53 | R14: 72 | S14: 48 | T14: 77 | U14: 48 | V14: 91 | W14: 48 | X14: 106 | Y14: 48 | Z14: 125 | AA14: 96
A15: 11 | B15: MADHYA PRADESH | C15: Central | D15: 12 | E15: 32 | F15: 16 | G15: 39 | H15: 20 | I15: 32 | J15: 20 | K15: 24 | L15: 20 | M15: 20 | N15: 20 | O15: 20 | P15: 36 | Q15: 20 | R15: 47 | S15: 16 | T15: 55 | U15: 8 | V15: 75 | W15: 47 | X15: 95 | Y15: 39 | Z15: 107 | AA15: 39
A16: 12 | B16: MADHYA PRADESH | C16: North | D16: 0 | E16: 0 | F16: 0 | G16: 0 | H16: 0 | I16: 0 | J16: 0 | K16: 0 | L16: 0 | M16: 0 | N16: 0 | O16: 0 | P16: 0 | Q16: 0 | R16: 0 | S16: 0 | T16: 4 | U16: 0 | V16: 4 | W16: 0 | X16: 4 | Y16: 0 | Z16: 4 | AA16: 0
A17: 12 | B17: MAHARASHTRA | C17: Central | D17: 0 | E17: 4 | F17: 0 | G17: 6 | H17: 0 | I17: 6 | J17: 0 | K17: 4 | L17: 2 | M17: 2 | N17: 2 | O17: 2 | P17: 4 | Q17: 2 | R17: 6 | S17: 0 | T17: 8 | U17: 0 | V17: 10 | W17: 0 | X17: 10 | Y17: 0 | Z17: 13 | AA17: 0
A18: 13 | B18: JHARKHAND | C18: East | D18: 0 | E18: 61 | F18: 0 | G18: 61 | H18: 0 | I18: 61 | J18: 0 | K18: 61 | L18: 0 | M18: 61 | N18: 0 | O18: 61 | P18: 0 | Q18: 61 | R18: 0 | S18: 122 | T18: 0 | U18: 122 | V18: 0 | W18: 122 | X18: 0 | Y18: 122 | Z18: 0 | AA18: 183
... A24: 19 | B24: ASSAM | C24: East | D24: 0 | E24: 0 | F24: 0 | G24: 0 | H24: 0 | I24: 0 | J24: 0 | K24: 0 | L24: 0 | M24: 0 | N24: 0 | O24: 0 | P24: 0 | Q24: 0 | R24: 0 | S24: 0 | T24: 0 | U24: 0 | V24: 0 | W24: 0 | X24: 0 | Y24: 40 | Z24: 0 | AA24: 40
A26: 3.8876712e+08

Sheet One Helix Budget
A1: #Distributors | B1: 42
A2: Volume projection (Mar'27 Exit) | B2: 27000
A3: Avg. volume/retailer/month | B3: 20
A4: Total retailers (Mar'27) | B4: 6230.7692
A5: Total Active retailers (Mar'27) | B5: 2015 | D5: In specific areas for longer
A6: Total transacting retailers (Mar'27) | B6: 1310 | D6: 15% discreationary cost
A7: #Priority districts | B7: 250
C8: Month | D8: 46048 | E8: 46168 | F8: 46199 | G8: 46229 | H8: 46260 | I8: 46291 | J8: 46321 | K8: 46352 | L8: 46382 | M8: 46413 | N8: 46444 | O8: 46472 | Q8: Left to Allocate | S8: Quarter | T8: Q1 | U8: Q2 | V8: Q3 | W8: Q4
S9: Marketing Cost | T9: =SUM(D54:F54) -> 66877908 | U9: =SUM(G54:I54) -> 31564253 | V9: =SUM(J54:L54) -> 76659596 | W9: =SUM(M54:O54) -> 52307088 | Z9: =121/(100/Z10) -> 30.25 | AA9: =121/(100/AA10) -> 18.15 | AB9: =121/(100/AB10) -> 42.35 | AC9: =121/(100/AC10) -> 30.25
A10: ATL Activities | B10: Remarks | C10: =SUM(C12:C20) -> 125600000 | D10: =SUM(D12:D20) -> 9342148.8 | E10: =SUM(E12:E20) -> 12456198 | F10: =SUM(F12:F20) -> 9342148.8 | G10: =SUM(G12:G20) -> 6228099.2 | H10: =SUM(H12:H20) -> 6228099.2 | I10: =SUM(I12:I20) -> 6228099.2 | J10: =SUM(J12:J20) -> 15570248 | ... O10: =SUM(O12:O20) -> 9342148.8 | S10: % Allocation | T10: =T9/$C$54 -> 0.28532795 | U10: =U9/$C$54 -> 0.13466575 | V10: =V9/$C$54 -> 0.32706055 | W10: =W9/$C$54 -> 0.22316299 | Z10: 25 | AA10: 15 | AB10: 35 | AC10: 25
A11: ATL Spends breakup | D11: 9 | E11: 12 | F11: 9 | G11: 6 | H11: 6 | I11: 6 | J11: 15 | K11: 13 | L11: 15 | M11: 12 | N11: 9 | O11: 9 | Q11: =121-SUM(D11:O11) -> 0 | S11: Cost / MT | T11: =W16 -> 5144.4545 | U11: =W21 -> 2630.3544 | V11: =W26 -> 2555.3199 | W11: =W31 -> 792.53164
A12: Impact Wall Painting | B12: 20,000 sq ft in high potential district @ Rs 15 | C12: ='One Helix'!C12 -> 16800000 | D12: =(D$11/121)*$C12 -> 1249586.8 | E12: =(E$11/121)*$C12 -> 1666115.7 | F12: =(F$11/121)*$C12 -> 1249586.8 | G12: =(G$11/121)*$C12 -> 833057.85 | H12: =(H$11/121)*$C12 -> 833057.85 | I12: =(I$11/121)*$C12 -> 833057.85 | J12: =(J$11/121)*$C12 -> 2082644.6 | K12: =(K$11/121)*$C12 -> 1804958.7 | ... O12: =(O$11/121)*$C12 -> 1249586.8 | S12: Q1 | T12: 46113 | U12: 46143 | V12: 46174 | W12: Total
A13: Integrated FM Radio Campaigns (Ad + Promotional Activity) | B13: To be done in Top 3 high potential districts for all operational states @Rs 2.5 Lac/campaign (No. of states: 15) for 3 months | C13: ='One Helix'!C13 -> 6000000 | D13: =(D$11/121)*$C13 -> 446280.99 | E13: =(E$11/121)*$C13 -> 595041.32 | F13: =(F$11/121)*$C13 -> 446280.99 | G13: =(G$11/121)*$C13 -> 297520.66 | H13: =(H$11/121)*$C13 -> 297520.66 | I13: =(I$11/121)*$C13 -> 297520.66 | J13: =(J$11/121)*$C13 -> 743801.65 | K13: =(K$11/121)*$C13 -> 644628.1 | ... O13: =(O$11/121)*$C13 -> 446280.99 | S13: % allocation | T13: =T14/$W14 -> 0.3390453 | U13: =U14/$W14 -> 0.36924732 | V13: =V14/$W14 -> 0.29170738 | Z13: 30.25 | AA13: =Z13*0.3 -> 9.075 | AB13: =0.4*Z13 -> 12.1 | AC13: =0.3*Z13 -> 9.075
A14: Hoardings (steel markets, cement shops cluster, construction zones) | B14: 5 hoardings in every high potential district @ Rs 50K | C14: ='One Helix'!C14 -> 15000000 | D14: =(D$11/121)*$C14 -> 1115702.5 | E14: =(E$11/121)*$C14 -> 1487603.3 | F14: =(F$11/121)*$C14 -> 1115702.5 | G14: =(G$11/121)*$C14 -> 743801.65 | H14: =(H$11/121)*$C14 -> 743801.65 | I14: =(I$11/121)*$C14 -> 743801.65 | J14: =(J$11/121)*$C14 -> 1859504.1 | K14: =(K$11/121)*$C14 -> 1611570.2 | ... O14: =(O$11/121)*$C14 -> 1115702.5 | S14: Marketing costs | T14: =D54 -> 22674641 | U14: =E54 -> 24694488 | V14: =F54 -> 19508779 | W14: =T9 -> 66877908 | Z14: 18.15 | AA14: =Z14*0.3 -> 5.445 | AB14: =Z14*0.35 -> 6.3525 | AC14: =Z14*0.35 -> 6.3525
A15: Digital Marketing Campaigns | B15: To be done in Top 3 high potential districts for all operational states @Rs 5 Lac/campaign (No. of states: 15) for 3 months | C15: ='One Helix'!C15 -> 14400000 | D15: =(D$11/121)*$C15 -> 1071074.4 | E15: =(E$11/121)*$C15 -> 1428099.2 | F15: =(F$11/121)*$C15 -> 1071074.4 | G15: =(G$11/121)*$C15 -> 714049.59 | H15: =(H$11/121)*$C15 -> 714049.59 | I15: =(I$11/121)*$C15 -> 714049.59 | J15: =(J$11/121)*$C15 -> 1785124 | K15: =(K$11/121)*$C15 -> 1547107.4 | ... O15: =(O$11/121)*$C15 -> 1071074.4 | S15: Vol. (in 000s MT) | T15: 4 | U15: 5 | V15: 4 | W15: =SUM(T15:V15) -> 13 | Z15: 42.35 | AA15: =Z15*0.35 -> 14.8225 | AB15: =Z15*0.3 -> 12.705 | AC15: =Z15*0.35 -> 14.8225
A16: Local Events/Fairs/Exhibitions | B16: For different Plant Launches, promotional exhibitions and mass events like Mahakumbh, etc - Total 10 events | C16: ='One Helix'!C16 -> 5000000 | D16: =(D$11/121)*$C16 -> 371900.83 | E16: =(E$11/121)*$C16 -> 495867.77 | F16: =(F$11/121)*$C16 -> 371900.83 | G16: =(G$11/121)*$C16 -> 247933.88 | H16: =(H$11/121)*$C16 -> 247933.88 | I16: =(I$11/121)*$C16 -> 247933.88 | J16: =(J$11/121)*$C16 -> 619834.71 | K16: =(K$11/121)*$C16 -> 537190.08 | ... O16: =(O$11/121)*$C16 -> 371900.83 | S16: Cost (in Rs./MT) | T16: =T14/(T15*1000) -> 5668.6602 | U16: =U14/(U15*1000) -> 4938.8976 | V16: =V14/(V15*1000) -> 4877.1949 | W16: =W14/(W15*1000) -> 5144.4545 | Z16: 30.25 | AA16: =Z16*0.4 -> 12.1 | AB16: =Z16*0.3 -> 9.075 | AC16: =Z16*0.3 -> 9.075
A17: Paper Advertisement | B17: 1 newspaper insert for onboarding 50% of new distributors @1 Lac | C17: ='One Helix'!C17 -> 0 | D17: =(D$11/121)*$C17 -> 0 | E17: =(E$11/121)*$C17 -> 0 | F17: =(F$11/121)*$C17 -> 0 | G17: =(G$11/121)*$C17 -> 0 | H17: =(H$11/121)*$C17 -> 0 | I17: =(I$11/121)*$C17 -> 0 | J17: =(J$11/121)*$C17 -> 0 | K17: =(K$11/121)*$C17 -> 0 | ... O17: =(O$11/121)*$C17 -> 0 | S17: Q2 | T17: 46204 | U17: 46235 | V17: 46266 | W17: Total
A18: Van Campaign | B18: To be done in Top 3 high potential districts for all operational states @ Rs 7000 /day (No. of states: 15) for 2 month | C18: ='One Helix'!C18 -> 18900000 | D18: =(D$11/121)*$C18 -> 1405785.1 | E18: =(E$11/121)*$C18 -> 1874380.2 | F18: =(F$11/121)*$C18 -> 1405785.1 | G18: =(G$11/121)*$C18 -> 937190.08 | H18: =(H$11/121)*$C18 -> 937190.08 | I18: =(I$11/121)*$C18 -> 937190.08 | J18: =(J$11/121)*$C18 -> 2342975.2 | K18: =(K$11/121)*$C18 -> 2030578.5 | ... O18: =(O$11/121)*$C18 -> 1405785.1 | S18: % allocation | T18: =T19/$W19 -> 0.33333333 | U18: =U19/$W19 -> 0.33333333 | V18: =V19/$W19 -> 0.33333333
A19: Syndicate Launch events | B19: Syndicate Launch events @15 states -Distributor base locations @Rs 5 Lac/event | C19: ='One Helix'!C19 -> 7500000 | D19: =(D$11/121)*$C19 -> 557851.24 | E19: =(E$11/121)*$C19 -> 743801.65 | F19: =(F$11/121)*$C19 -> 557851.24 | G19: =(G$11/121)*$C19 -> 371900.83 | H19: =(H$11/121)*$C19 -> 371900.83 | I19: =(I$11/121)*$C19 -> 371900.83 | J19: =(J$11/121)*$C19 -> 929752.07 | K19: =(K$11/121)*$C19 -> 805785.12 | ... O19: =(O$11/121)*$C19 -> 557851.24 | S19: Marketing costs | T19: =G54 -> 10521418 | U19: =H54 -> 10521418 | V19: =I54 -> 10521418 | W19: =U9 -> 31564253
A20: Transit Branding | B20: To be done in Top 3 high potential districts for all operational states @2000 autos @Rs. 700/auto (No. of states: 15) | C20: ='One Helix'!C20 -> 42000000 | D20: =(D$11/121)*$C20 -> 3123966.9 | E20: =(E$11/121)*$C20 -> 4165289.3 | F20: =(F$11/121)*$C20 -> 3123966.9 | G20: =(G$11/121)*$C20 -> 2082644.6 | H20: =(H$11/121)*$C20 -> 2082644.6 | I20: =(I$11/121)*$C20 -> 2082644.6 | J20: =(J$11/121)*$C20 -> 5206611.6 | K20: =(K$11/121)*$C20 -> 4512396.7 | ... O20: =(O$11/121)*$C20 -> 3123966.9 | S20: Vol. (in 000s MT) | T20: 4 | U20: 4 | V20: 4 | W20: =SUM(T20:V20) -> 12
A21: BTL Activities | B21: Remarks | C21: =SUM(C23:C39) -> 87364615 | D21: =SUM(D23:D39) -> 9157285.4 | E21: =SUM(E23:E39) -> 8286637 | F21: =SUM(F23:F39) -> 6214977.7 | G21: =SUM(G23:G39) -> 4143318.5 | H21: =SUM(H23:H39) -> 4143318.5 | I21: =SUM(I23:I39) -> 4143318.5 | J21: =SUM(J23:J39) -> 11742912 | ... O21: =SUM(O23:O39) -> 6214977.7 | S21: Cost (in Rs./MT) | T21: =T19/(T20*1000) -> 2630.3544 | U21: =U19/(U20*1000) -> 2630.3544 | V21: =V19/(V20*1000) -> 2630.3544 | W21: =W19/(W20*1000) -> 2630.3544
A22: BTL Spends breakup | D22: 9 | E22: 12 | F22: 9 | G22: 6 | H22: 6 | I22: 6 | J22: 15 | K22: 13 | L22: 15 | M22: 12 | N22: 9 | O22: 9 | Q22: =121-SUM(D22:O22) -> 0 | S22: Q3 | T22: 46296 | U22: 46327 | V22: 46357 | W22: Total
A23: NLBs | B23: To be given to 50% of active dealers (Cost is taken to be Rs.40/sqft. Avg size is taken to be 10*3=30 sqft) | C23: ='One Helix'!C23 -> 830769.23 | D23: =(D$22/121)*$C23 -> 61792.753 | E23: =(E$22/121)*$C23 -> 82390.337 | F23: =(F$22/121)*$C23 -> 61792.753 | G23: =(G$22/121)*$C23 -> 41195.168 | H23: =(H$22/121)*$C23 -> 41195.168 | I23: =(I$22/121)*$C23 -> 41195.168 | J23: =(J$22/121)*$C23 -> 102987.92 | K23: =(K$22/121)*$C23 -> 89256.198 | ... O23: =(O$22/121)*$C23 -> 61792.753 | S23: % allocation | T23: =T24/$W24 -> 0.36105654 | U23: =U24/$W24 -> 0.29724516 | V23: =V24/$W24 -> 0.34169829
A24: GSBs | B24: To be given to 25% of active dealers. Cost: (180 *size of flex + 65*length of iron angle), Avg size of flex taken to be 10*3. Avg iron angle length: 18 ft | C24: ='One Helix'!C24 -> 2274230.8 | D24: =(D$22/121)*$C24 -> 169157.66 | E24: =(E$22/121)*$C24 -> 225543.55 | F24: =(F$22/121)*$C24 -> 169157.66 | G24: =(G$22/121)*$C24 -> 112771.77 | H24: =(H$22/121)*$C24 -> 112771.77 | I24: =(I$22/121)*$C24 -> 112771.77 | J24: =(J$22/121)*$C24 -> 281929.43 | K24: =(K$22/121)*$C24 -> 244338.84 | ... O24: =(O$22/121)*$C24 -> 169157.66 | S24: Marketing costs | T24: =J54 -> 27678449 | U24: =K54 -> 22786694 | V24: =L54 -> 26194453 | W24: =V9 -> 76659596
A25: Counter Wall Painting | B25: To be given to exclusive 20% active counters @Rs 10000/counter | C25: ='One Helix'!C25 -> 2769230.8 | D25: =(D$22/121)*$C25 -> 205975.84 | E25: =(E$22/121)*$C25 -> 274634.46 | F25: =(F$22/121)*$C25 -> 205975.84 | G25: =(G$22/121)*$C25 -> 137317.23 | H25: =(H$22/121)*$C25 -> 137317.23 | I25: =(I$22/121)*$C25 -> 137317.23 | J25: =(J$22/121)*$C25 -> 343293.07 | K25: =(K$22/121)*$C25 -> 297520.66 | ... O25: =(O$22/121)*$C25 -> 205975.84 | S25: Vol. (in 000s MT) | T25: 7 | U25: 10 | V25: 13 | W25: =SUM(T25:V25) -> 30
A26: Inshop Branding | B26: To be given to exclusive 10% active counters @Rs 40000/counter | C26: ='One Helix'!C26 -> 5538461.5 | D26: =(D$22/121)*$C26 -> 411951.68 | E26: =(E$22/121)*$C26 -> 549268.91 | F26: =(F$22/121)*$C26 -> 411951.68 | G26: =(G$22/121)*$C26 -> 274634.46 | H26: =(H$22/121)*$C26 -> 274634.46 | I26: =(I$22/121)*$C26 -> 274634.46 | J26: =(J$22/121)*$C26 -> 686586.14 | K26: =(K$22/121)*$C26 -> 595041.32 | ... O26: =(O$22/121)*$C26 -> 411951.68 | S26: Cost (in Rs./MT) | T26: =T24/(T25*1000) -> 3954.0641 | U26: =U24/(U25*1000) -> 2278.6694 | V26: =V24/(V25*1000) -> 2014.9579 | W26: =W24/(W25*1000) -> 2555.3199
A27: Architect/Engineer Meets | B27: Considering every distributor does 1 meets with 50 architects @Rs 3500/pax every quarter | C27: ='One Helix'!C27 -> 29400000 | D27: =(D$22/121)*$C27 -> 2186776.9 | E27: =(E$22/121)*$C27 -> 2915702.5 | F27: =(F$22/121)*$C27 -> 2186776.9 | G27: =(G$22/121)*$C27 -> 1457851.2 | H27: =(H$22/121)*$C27 -> 1457851.2 | I27: =(I$22/121)*$C27 -> 1457851.2 | J27: =(J$22/121)*$C27 -> 3644628.1 | K27: =(K$22/121)*$C27 -> 3158677.7 | ... O27: =(O$22/121)*$C27 -> 2186776.9 | S27: Q4 | T27: 46388 | U27: 46419 | V27: 46447 | W27: Total
A28: Contractor Meets | B28: Considering every distributor does 2 meets with 50 contractors @Rs 1000/pax per quarter | C28: ='One Helix'!C28 -> 16800000 | D28: =(D$22/121)*$C28 -> 1249586.8 | E28: =(E$22/121)*$C28 -> 1666115.7 | F28: =(F$22/121)*$C28 -> 1249586.8 | G28: =(G$22/121)*$C28 -> 833057.85 | H28: =(H$22/121)*$C28 -> 833057.85 | I28: =(I$22/121)*$C28 -> 833057.85 | J28: =(J$22/121)*$C28 -> 2082644.6 | K28: =(K$22/121)*$C28 -> 1804958.7 | ... O28: =(O$22/121)*$C28 -> 1249586.8 | S28: % allocation | T28: =T29/$W29 -> 0.39942646 | U28: =U29/$W29 -> 0.30028677 | V28: =V29/$W29 -> 0.30028677
A29: Mason Meets | B29: 1 Mason meet for every transacting dealer, of 30 pax/meet Cost @ Rs 300/pax/meet | C29: ='One Helix'!C29 -> 8100000 | D29: =(D$22/121)*$C29 -> 602479.34 | E29: =(E$22/121)*$C29 -> 803305.79 | F29: =(F$22/121)*$C29 -> 602479.34 | G29: =(G$22/121)*$C29 -> 401652.89 | H29: =(H$22/121)*$C29 -> 401652.89 | I29: =(I$22/121)*$C29 -> 401652.89 | J29: =(J$22/121)*$C29 -> 1004132.2 | K29: =(K$22/121)*$C29 -> 870247.93 | ... O29: =(O$22/121)*$C29 -> 602479.34 | S29: Marketing costs | T29: =M54 -> 20892835 | U29: =N54 -> 15707127 | V29: =O54 -> 15707127 | W29: =W9 -> 52307088
A30: Dealer Certificates | B30: To be given to all active retailers @Rs 400 | C30: ='One Helix'!C30 -> 553846.15 | D30: =(D$22/121)*$C30 -> 41195.168 | E30: =(E$22/121)*$C30 -> 54926.891 | F30: =(F$22/121)*$C30 -> 41195.168 | G30: =(G$22/121)*$C30 -> 27463.446 | H30: =(H$22/121)*$C30 -> 27463.446 | I30: =(I$22/121)*$C30 -> 27463.446 | J30: =(J$22/121)*$C30 -> 68658.614 | K30: =(K$22/121)*$C30 -> 59504.132 | ... O30: =(O$22/121)*$C30 -> 41195.168 | S30: Vol. (in 000s MT) | T30: 18 | U30: 21 | V30: 27 | W30: =SUM(T30:V30) -> 66
A31: Architect one-to-one visit Gifts | B31: Considering 75 architects for every distributor with gift cost @ Rs 500 | C31: ='One Helix'!C31 -> 1575000 | D31: =(D$22/121)*$C31 -> 117148.76 | E31: =(E$22/121)*$C31 -> 156198.35 | F31: =(F$22/121)*$C31 -> 117148.76 | G31: =(G$22/121)*$C31 -> 78099.174 | H31: =(H$22/121)*$C31 -> 78099.174 | I31: =(I$22/121)*$C31 -> 78099.174 | J31: =(J$22/121)*$C31 -> 195247.93 | K31: =(K$22/121)*$C31 -> 169214.88 | ... O31: =(O$22/121)*$C31 -> 117148.76 | S31: Cost (in Rs./MT) | T31: =T29/(T30*1000) -> 1160.7131 | U31: =U29/(U30*1000) -> 747.95841 | V31: =V29/(V30*1000) -> 581.74543 | W31: =W29/(W30*1000) -> 792.53164
A32: Digital Factory visits to dealers via VR headset | B32: Digital headset for factory visit to 25% of active dealers @ Rs 5000 | C32: ='One Helix'!C33 -> 1730769.2 | D32: =(D$22/121)*$C32 -> 128734.9 | E32: =(E$22/121)*$C32 -> 171646.54 | F32: =(F$22/121)*$C32 -> 128734.9 | G32: =(G$22/121)*$C32 -> 85823.268 | H32: =(H$22/121)*$C32 -> 85823.268 | I32: =(I$22/121)*$C32 -> 85823.268 | J32: =(J$22/121)*$C32 -> 214558.17 | K32: =(K$22/121)*$C32 -> 185950.41 | ... O32: =(O$22/121)*$C32 -> 128734.9
A33: POP | B33: POP materials @Rs 3K to be given to every active dealer | C33: ='One Helix'!C34 -> 4153846.2 | D33: =(D$22/121)*$C33 -> 308963.76 | E33: =(E$22/121)*$C33 -> 411951.68 | F33: =(F$22/121)*$C33 -> 308963.76 | G33: =(G$22/121)*$C33 -> 205975.84 | H33: =(H$22/121)*$C33 -> 205975.84 | I33: =(I$22/121)*$C33 -> 205975.84 | J33: =(J$22/121)*$C33 -> 514939.61 | K33: =(K$22/121)*$C33 -> 446280.99 | ... O33: =(O$22/121)*$C33 -> 308963.76
A34: Vehicle Branding | B34: To be done at 10% of active dealers @Rs 5k/vehicle | C34: ='One Helix'!C35 -> 692307.69 | D34: =(D$22/121)*$C34 -> 51493.961 | E34: =(E$22/121)*$C34 -> 68658.614 | F34: =(F$22/121)*$C34 -> 51493.961 | G34: =(G$22/121)*$C34 -> 34329.307 | H34: =(H$22/121)*$C34 -> 34329.307 | I34: =(I$22/121)*$C34 -> 34329.307 | J34: =(J$22/121)*$C34 -> 85823.268 | K34: =(K$22/121)*$C34 -> 74380.165 | ... O34: =(O$22/121)*$C34 -> 51493.961
A35: Leaflets/Brochures | B35: 2000 units to be sent to all active retailers at Rs 4/pc | C35: ='One Helix'!C36 -> 5538461.5 | D35: =(D$22/121)*$C35 -> 411951.68 | E35: =(E$22/121)*$C35 -> 549268.91 | F35: =(F$22/121)*$C35 -> 411951.68 | G35: =(G$22/121)*$C35 -> 274634.46 | H35: =(H$22/121)*$C35 -> 274634.46 | I35: =(I$22/121)*$C35 -> 274634.46 | J35: =(J$22/121)*$C35 -> 686586.14 | K35: =(K$22/121)*$C35 -> 595041.32 | ... O35: =(O$22/121)*$C35 -> 411951.68
A36: Annual Diaries | B36: 3 annual diaries per active retailer@Rs250/diary | C36: ='One Helix'!C37 -> 1038461.5 | D36: 1557692.3 | E36: 0 | F36: 0 | G36: 0 | H36: 0 | I36: 0 | J36: 0 | K36: 0 | L36: 0 | M36: 0 | N36: 0 | O36: 0
A37: Festival Branding gifts (Diwali, Holi) | B37: To all active dealers and active influencers (3/retailer) | C37: ='One Helix'!C38 -> 2769230.8 | D37: =C37*0.5 -> 1384615.4 | E37: 0 | F37: 0 | G37: 0 | H37: 0 | I37: 0 | J37: =C37-D37 -> 1384615.4 | K37: 0 | L37: 0 | M37: 0 | N37: 0 | O37: 0
A38: Branded Tarpaulins | B38: 1 Branded Tarpaulins @ 1500/pc | C38: ='One Helix'!C39 -> 2076923.1 | D38: =(D$22/121)*$C38 -> 154481.88 | E38: =(E$22/121)*$C38 -> 205975.84 | F38: =(F$22/121)*$C38 -> 154481.88 | G38: =(G$22/121)*$C38 -> 102987.92 | H38: =(H$22/121)*$C38 -> 102987.92 | I38: =(I$22/121)*$C38 -> 102987.92 | J38: =(J$22/121)*$C38 -> 257469.8 | K38: =(K$22/121)*$C38 -> 223140.5 | ... O38: =(O$22/121)*$C38 -> 154481.88
A39: Cutout Standees from Ads | B39: For 50% of active retailer in size 5ft X 3ft; 5mm board with stand @ 2200/pc | C39: ='One Helix'!C40 -> 1523076.9 | D39: =(D$22/121)*$C39 -> 113286.71 | E39: =(E$22/121)*$C39 -> 151048.95 | F39: =(F$22/121)*$C39 -> 113286.71 | G39: =(G$22/121)*$C39 -> 75524.476 | H39: =(H$22/121)*$C39 -> 75524.476 | I39: =(I$22/121)*$C39 -> 75524.476 | J39: =(J$22/121)*$C39 -> 188811.19 | K39: =(K$22/121)*$C39 -> 163636.36 | ... O39: =(O$22/121)*$C39 -> 113286.71
A40: Project BTL Activities | B40: Remarks | C40: =SUM(C42:C45) -> 3625000 | D40: =SUM(D42:D45) -> 297933.88 | E40: =SUM(E42:E45) -> 165289.26 | F40: =SUM(F42:F45) -> 165289.26 | G40: =SUM(G42:G45) -> 0 | H40: =SUM(H42:H45) -> 0 | I40: =SUM(I42:I45) -> 0 | J40: =SUM(J42:J45) -> 215289.26 | ... O40: =SUM(O42:O45) -> 0
...

Sheet JSW ONE TMT Budget
A1: #Distributors | B1: 42
A2: Volume projection (Mar'27 Exit) | B2: 27000
A3: Avg. volume/retailer/month | B3: 20
A4: Total retailers (Mar'27) | B4: 6230.7692
A5: Total Active retailers (Mar'27) | B5: 2015
A6: Total transacting retailers (Mar'27) | B6: 1310
A7: #Priority districts | B7: 250
C8: Month | D8: 46048 | E8: 46168 | F8: 46199 | G8: 46229 | H8: 46260 | I8: 46291 | J8: 46321 | K8: 46352 | L8: 46382 | M8: 46413 | N8: 46444 | O8: 46472 | Q8: Left to Allocate | S8: Quarter | T8: Q1 | U8: Q2 | V8: Q3 | W8: Q4
S9: Marketing Cost | T9: =SUM(D50:F50) -> 70846502 | U9: =SUM(G50:I50) -> 42490141 | V9: =SUM(J50:L50) -> 55613732 | W9: =SUM(M50:O50) -> 47522204
A10: ATL Activities | B10: Remarks | C10: =SUM(C12:C20) -> 95050000 | D10: =SUM(D12:D20) -> 11783058 | E10: =SUM(E12:E20) -> 10997521 | F10: =SUM(F12:F20) -> 6284297.5 | G10: =SUM(G12:G20) -> 6284297.5 | H10: =SUM(H12:H20) -> 6284297.5 | I10: =SUM(I12:I20) -> 6284297.5 | J10: =SUM(J12:J20) -> 11783058 | ... O10: =SUM(O12:O20) -> 6284297.5 | S10: % Allocation | T10: =T9/$C$50 -> 0.32734725 | U10: =U9/$C$50 -> 0.19632629 | V10: =V9/$C$50 -> 0.25696403 | W10: =W9/$C$50 -> 0.21957701
A11: ATL Spends breakup | D11: 15 | E11: 14 | F11: 8 | G11: 8 | H11: 8 | I11: 8 | J11: 15 | K11: 10 | L11: 8 | M11: 11 | N11: 8 | O11: 8 | Q11: =121-SUM(D11:O11) -> 0 | S11: Cost / MT | T11: =W16 -> 874.64817 | U11: =W21 -> 674.44668 | V11: =W26 -> 585.40771 | W11: =W31 -> 314.71659
A12: Impact Wall Painting | B12: 20,000 sq ft in high potential district @ Rs 15 | C12: 75000000 | D12: =(D$11/121)*$C12 -> 9297520.7 | E12: =(E$11/121)*$C12 -> 8677686 | F12: =(F$11/121)*$C12 -> 4958677.7 | G12: =(G$11/121)*$C12 -> 4958677.7 | H12: =(H$11/121)*$C12 -> 4958677.7 | I12: =(I$11/121)*$C12 -> 4958677.7 | J12: =(J$11/121)*$C12 -> 9297520.7 | K12: =(K$11/121)*$C12 -> 6198347.1 | ... O12: =(O$11/121)*$C12 -> 4958677.7 | S12: Q1 | T12: 46113 | U12: 46143 | V12: 46174 | W12: Total
A13: Integrated FM Radio Campaigns (Ad + Promotional Activity) | B13: To be done in Top 3 high potential districts for all operational states @Rs 2.5 Lac/campaign (No. of states: 5) for 3 months | C13: =11250000/3 -> 3750000 | D13: =(D$11/121)*$C13 -> 464876.03 | E13: =(E$11/121)*$C13 -> 433884.3 | F13: =(F$11/121)*$C13 -> 247933.88 | G13: =(G$11/121)*$C13 -> 247933.88 | H13: =(H$11/121)*$C13 -> 247933.88 | I13: =(I$11/121)*$C13 -> 247933.88 | J13: =(J$11/121)*$C13 -> 464876.03 | K13: =(K$11/121)*$C13 -> 309917.36 | ... O13: =(O$11/121)*$C13 -> 247933.88 | S13: % allocation | T13: =T14/$W14 -> 0.42356841 | U13: =U14/$W14 -> 0.33406744 | V13: =V14/$W14 -> 0.24236415
D14: =(D$11/121)*$C14 -> 0 | E14: =(E$11/121)*$C14 -> 0 | F14: =(F$11/121)*$C14 -> 0 | G14: =(G$11/121)*$C14 -> 0 | H14: =(H$11/121)*$C14 -> 0 | I14: =(I$11/121)*$C14 -> 0 | J14: =(J$11/121)*$C14 -> 0 | K14: =(K$11/121)*$C14 -> 0 | ... O14: =(O$11/121)*$C14 -> 0 | S14: Marketing costs | T14: =D50 -> 30008340 | U14: =E50 -> 23667510 | V14: =F50 -> 17170652 | W14: =T9 -> 70846502
A15: Digital Marketing Campaigns | B15: To be done in Top 3 high potential districts for all operational states @Rs 5 Lac/campaign (No. of states: 5) for 3 months | C15: =22500000/3 -> 7500000 | D15: =(D$11/121)*$C15 -> 929752.07 | E15: =(E$11/121)*$C15 -> 867768.6 | F15: =(F$11/121)*$C15 -> 495867.77 | G15: =(G$11/121)*$C15 -> 495867.77 | H15: =(H$11/121)*$C15 -> 495867.77 | I15: =(I$11/121)*$C15 -> 495867.77 | J15: =(J$11/121)*$C15 -> 929752.07 | K15: =(K$11/121)*$C15 -> 619834.71 | ... O15: =(O$11/121)*$C15 -> 495867.77 | S15: Vol. (in 000s MT) | T15: 23 | U15: 31 | V15: 27 | W15: =SUM(T15:V15) -> 81
A16: Local Events/Fairs/Exhibitions | B16: For different Plant Launches, promotional exhibitions and mass events like Mahakumbh, etc - Total 5 events | C16: =5000000/2 -> 2500000 | D16: =(D$11/121)*$C16 -> 309917.36 | E16: =(E$11/121)*$C16 -> 289256.2 | F16: =(F$11/121)*$C16 -> 165289.26 | G16: =(G$11/121)*$C16 -> 165289.26 | H16: =(H$11/121)*$C16 -> 165289.26 | I16: =(I$11/121)*$C16 -> 165289.26 | J16: =(J$11/121)*$C16 -> 309917.36 | K16: =(K$11/121)*$C16 -> 206611.57 | ... O16: =(O$11/121)*$C16 -> 165289.26 | S16: Cost (in Rs./MT) | T16: =T14/(T15*1000) -> 1304.7105 | U16: =U14/(U15*1000) -> 763.46805 | V16: =V14/(V15*1000) -> 635.95007 | W16: =W14/(W15*1000) -> 874.64817
D17: =(D$11/121)*$C17 -> 0 | E17: =(E$11/121)*$C17 -> 0 | F17: =(F$11/121)*$C17 -> 0 | G17: =(G$11/121)*$C17 -> 0 | H17: =(H$11/121)*$C17 -> 0 | I17: =(I$11/121)*$C17 -> 0 | J17: =(J$11/121)*$C17 -> 0 | K17: =(K$11/121)*$C17 -> 0 | ... O17: =(O$11/121)*$C17 -> 0 | S17: Q2 | T17: 46204 | U17: 46235 | V17: 46266 | W17: Total
A18: Van Campaign | B18: To be done in Top 3 high potential districts for all operational states @ Rs 7000 /day (No. of states: 5) for 2 month | C18: =18900000/3 -> 6300000 | D18: =(D$11/121)*$C18 -> 780991.74 | E18: =(E$11/121)*$C18 -> 728925.62 | F18: =(F$11/121)*$C18 -> 416528.93 | G18: =(G$11/121)*$C18 -> 416528.93 | H18: =(H$11/121)*$C18 -> 416528.93 | I18: =(I$11/121)*$C18 -> 416528.93 | J18: =(J$11/121)*$C18 -> 780991.74 | K18: =(K$11/121)*$C18 -> 520661.16 | ... O18: =(O$11/121)*$C18 -> 416528.93 | S18: % allocation | T18: =T19/$W19 -> 0.36131841 | U18: =U19/$W19 -> 0.3193408 | V18: =V19/$W19 -> 0.3193408
D19: =(D$11/121)*$C19 -> 0 | E19: =(E$11/121)*$C19 -> 0 | F19: =(F$11/121)*$C19 -> 0 | G19: =(G$11/121)*$C19 -> 0 | H19: =(H$11/121)*$C19 -> 0 | I19: =(I$11/121)*$C19 -> 0 | J19: =(J$11/121)*$C19 -> 0 | K19: =(K$11/121)*$C19 -> 0 | ... O19: =(O$11/121)*$C19 -> 0 | S19: Marketing costs | T19: =G50 -> 15352470 | U19: =H50 -> 13568836 | V19: =I50 -> 13568836 | W19: =U9 -> 42490141
D20: =(D$11/121)*$C20 -> 0 | E20: =(E$11/121)*$C20 -> 0 | F20: =(F$11/121)*$C20 -> 0 | G20: =(G$11/121)*$C20 -> 0 | H20: =(H$11/121)*$C20 -> 0 | I20: =(I$11/121)*$C20 -> 0 | J20: =(J$11/121)*$C20 -> 0 | K20: =(K$11/121)*$C20 -> 0 | ... O20: =(O$11/121)*$C20 -> 0 | S20: Vol. (in 000s MT) | T20: 23 | U20: 19 | V20: 21 | W20: =SUM(T20:V20) -> 63
A21: BTL Activities | B21: Remarks | C21: =SUM(C23:C39) -> 1.1345114e+08 | D21: =SUM(D23:D39) -> 16058134 | E21: =SUM(E23:E39) -> 10701807 | F21: =SUM(F23:F39) -> 8918172.5 | G21: =SUM(G23:G39) -> 8918172.5 | H21: =SUM(H23:H39) -> 7134538 | I21: =SUM(I23:I39) -> 7134538 | J21: =SUM(J23:J39) -> 12716807 | ... O21: =SUM(O23:O39) -> 8026355.3 | S21: Cost (in Rs./MT) | T21: =T19/(T20*1000) -> 667.4987 | U21: =U19/(U20*1000) -> 714.14924 | V21: =V19/(V20*1000) -> 646.13503 | W21: =W19/(W20*1000) -> 674.44668
A22: BTL Spends breakup | D22: 14 | E22: 12 | F22: 10 | G22: 10 | H22: 8 | I22: 8 | J22: 12 | K22: 10 | L22: 8 | M22: 10 | N22: 10 | O22: 9 | Q22: =121-SUM(D22:O22) -> 0 | S22: Q3 | T22: 46296 | U22: 46327 | V22: 46357 | W22: Total
A23: NLBs | B23: To be given to 50% of active dealers (Cost is taken to be Rs.40/sqft. Avg size is taken to be 10*3=30 sqft) | C23: 1209000 | D23: =(D$22/121)*$C23 -> 139884.3 | E23: =(E$22/121)*$C23 -> 119900.83 | F23: =(F$22/121)*$C23 -> 99917.355 | G23: =(G$22/121)*$C23 -> 99917.355 | H23: =(H$22/121)*$C23 -> 79933.884 | I23: =(I$22/121)*$C23 -> 79933.884 | J23: =(J$22/121)*$C23 -> 119900.83 | K23: =(K$22/121)*$C23 -> 99917.355 | ... O23: =(O$22/121)*$C23 -> 89925.62 | S23: % allocation | T23: =T24/$W24 -> 0.44710457 | U23: =U24/$W24 -> 0.30727723 | V23: =V24/$W24 -> 0.2456182
A24: GSBs | B24: To be given to 25% of active dealers. Cost: (180 *size of flex + 65*length of iron angle), Avg size of flex taken to be 10*3. Avg iron angle length: 18 ft | C24: 3309637.5 | D24: =(D$22/121)*$C24 -> 382933.26 | E24: =(E$22/121)*$C24 -> 328228.51 | F24: =(F$22/121)*$C24 -> 273523.76 | G24: =(G$22/121)*$C24 -> 273523.76 | H24: =(H$22/121)*$C24 -> 218819.01 | I24: =(I$22/121)*$C24 -> 218819.01 | J24: =(J$22/121)*$C24 -> 328228.51 | K24: =(K$22/121)*$C24 -> 273523.76 | ... O24: =(O$22/121)*$C24 -> 246171.38 | S24: Marketing costs | T24: =J50 -> 24865154 | U24: =K50 -> 17088834 | V24: =L50 -> 13659745 | W24: =V9 -> 55613732
A25: Counter Wall Painting | B25: To be given to exclusive 20% active counters @Rs 10000/counter | C25: 4030000 | D25: =(D$22/121)*$C25 -> 466280.99 | E25: =(E$22/121)*$C25 -> 399669.42 | F25: =(F$22/121)*$C25 -> 333057.85 | G25: =(G$22/121)*$C25 -> 333057.85 | H25: =(H$22/121)*$C25 -> 266446.28 | I25: =(I$22/121)*$C25 -> 266446.28 | J25: =(J$22/121)*$C25 -> 399669.42 | K25: =(K$22/121)*$C25 -> 333057.85 | ... O25: =(O$22/121)*$C25 -> 299752.07 | S25: Vol. (in 000s MT) | T25: 27 | U25: 33 | V25: 35 | W25: =SUM(T25:V25) -> 95
A26: Inshop Branding | B26: To be given to exclusive 10% active counters @Rs 40000/counter | C26: 8060000 | D26: =(D$22/121)*$C26 -> 932561.98 | E26: =(E$22/121)*$C26 -> 799338.84 | F26: =(F$22/121)*$C26 -> 666115.7 | G26: =(G$22/121)*$C26 -> 666115.7 | H26: =(H$22/121)*$C26 -> 532892.56 | I26: =(I$22/121)*$C26 -> 532892.56 | J26: =(J$22/121)*$C26 -> 799338.84 | K26: =(K$22/121)*$C26 -> 666115.7 | ... O26: =(O$22/121)*$C26 -> 599504.13 | S26: Cost (in Rs./MT) | T26: =T24/(T25*1000) -> 920.93163 | U26: =U24/(U25*1000) -> 517.84344 | V26: =V24/(V25*1000) -> 390.27842 | W26: =W24/(W25*1000) -> 585.40771
A27: Architect/Engineer Meets | B27: Considering every distributor does 1 meets with 50 architects @Rs 3500/pax every quarter | C27: 29400000 | D27: =(D$22/121)*$C27 -> 3401652.9 | E27: =(E$22/121)*$C27 -> 2915702.5 | F27: =(F$22/121)*$C27 -> 2429752.1 | G27: =(G$22/121)*$C27 -> 2429752.1 | H27: =(H$22/121)*$C27 -> 1943801.7 | I27: =(I$22/121)*$C27 -> 1943801.7 | J27: =(J$22/121)*$C27 -> 2915702.5 | K27: =(K$22/121)*$C27 -> 2429752.1 | ... O27: =(O$22/121)*$C27 -> 2186776.9 | S27: Q4 | T27: 46388 | U27: 46419 | V27: 46447 | W27: Total
A28: Contractor Meets | B28: Considering every distributor does 2 meets with 50 contractors @Rs 1000/pax per quarter | C28: 16800000 | D28: =(D$22/121)*$C28 -> 1943801.7 | E28: =(E$22/121)*$C28 -> 1666115.7 | F28: =(F$22/121)*$C28 -> 1388429.8 | G28: =(G$22/121)*$C28 -> 1388429.8 | H28: =(H$22/121)*$C28 -> 1110743.8 | I28: =(I$22/121)*$C28 -> 1110743.8 | J28: =(J$22/121)*$C28 -> 1666115.7 | K28: =(K$22/121)*$C28 -> 1388429.8 | ... O28: =(O$22/121)*$C28 -> 1249586.8 | S28: % allocation | T28: =T29/$W29 -> 0.37264857 | U28: =U29/$W29 -> 0.32305888 | V28: =V29/$W29 -> 0.30429255
A29: Mason Meets | B29: 1 Mason meet for every transacting dealer, of 30 pax/meet Cost @ Rs 300/pax/meet | C29: 11790000 | D29: =(D$22/121)*$C29 -> 1364132.2 | E29: =(E$22/121)*$C29 -> 1169256.2 | F29: =(F$22/121)*$C29 -> 974380.17 | G29: =(G$22/121)*$C29 -> 974380.17 | H29: =(H$22/121)*$C29 -> 779504.13 | I29: =(I$22/121)*$C29 -> 779504.13 | J29: =(J$22/121)*$C29 -> 1169256.2 | K29: =(K$22/121)*$C29 -> 974380.17 | ... O29: =(O$22/121)*$C29 -> 876942.15 | S29: Marketing costs | T29: =M50 -> 17709082 | U29: =N50 -> 15352470 | V29: =O50 -> 14460653 | W29: =W9 -> 47522204
A30: Dealer Certificates | B30: To be given to all active retailers @Rs 400 | C30: 806000 | D30: =(D$22/121)*$C30 -> 93256.198 | E30: =(E$22/121)*$C30 -> 79933.884 | F30: =(F$22/121)*$C30 -> 66611.57 | G30: =(G$22/121)*$C30 -> 66611.57 | H30: =(H$22/121)*$C30 -> 53289.256 | I30: =(I$22/121)*$C30 -> 53289.256 | J30: =(J$22/121)*$C30 -> 79933.884 | K30: =(K$22/121)*$C30 -> 66611.57 | ... O30: =(O$22/121)*$C30 -> 59950.413 | S30: Vol. (in 000s MT) | T30: 44 | U30: 49 | V30: 58 | W30: =SUM(T30:V30) -> 151
A31: Architect one-to-one visit Gifts | B31: Considering 75 architects for every distributor with gift cost @ Rs 500 | C31: 1575000 | D31: =(D$22/121)*$C31 -> 182231.4 | E31: =(E$22/121)*$C31 -> 156198.35 | F31: =(F$22/121)*$C31 -> 130165.29 | G31: =(G$22/121)*$C31 -> 130165.29 | H31: =(H$22/121)*$C31 -> 104132.23 | I31: =(I$22/121)*$C31 -> 104132.23 | J31: =(J$22/121)*$C31 -> 156198.35 | K31: =(K$22/121)*$C31 -> 130165.29 | ... O31: =(O$22/121)*$C31 -> 117148.76 | S31: Cost (in Rs./MT) | T31: =T29/(T30*1000) -> 402.47913 | U31: =U29/(U30*1000) -> 313.31572 | V31: =V29/(V30*1000) -> 249.3216 | W31: =W29/(W30*1000) -> 314.71659
A32: Digital Factory visits to dealers via VR headset | B32: Digital headset for factory visit to 25% of active dealers @ Rs 5000 | C32: 2518750 | D32: =(D$22/121)*$C32 -> 291425.62 | E32: =(E$22/121)*$C32 -> 249793.39 | F32: =(F$22/121)*$C32 -> 208161.16 | G32: =(G$22/121)*$C32 -> 208161.16 | H32: =(H$22/121)*$C32 -> 166528.93 | I32: =(I$22/121)*$C32 -> 166528.93 | J32: =(J$22/121)*$C32 -> 249793.39 | K32: =(K$22/121)*$C32 -> 208161.16 | ... O32: =(O$22/121)*$C32 -> 187345.04
A33: POP | B33: POP materials @Rs 3K to be given to every active dealer | C33: 6045000 | D33: =(D$22/121)*$C33 -> 699421.49 | E33: =(E$22/121)*$C33 -> 599504.13 | F33: =(F$22/121)*$C33 -> 499586.78 | G33: =(G$22/121)*$C33 -> 499586.78 | H33: =(H$22/121)*$C33 -> 399669.42 | I33: =(I$22/121)*$C33 -> 399669.42 | J33: =(J$22/121)*$C33 -> 599504.13 | K33: =(K$22/121)*$C33 -> 499586.78 | ... O33: =(O$22/121)*$C33 -> 449628.1
A34: Vehicle Branding | B34: To be done at 10% of active dealers @Rs 5k/vehicle | C34: 1007500 | D34: =(D$22/121)*$C34 -> 116570.25 | E34: =(E$22/121)*$C34 -> 99917.355 | F34: =(F$22/121)*$C34 -> 83264.463 | G34: =(G$22/121)*$C34 -> 83264.463 | H34: =(H$22/121)*$C34 -> 66611.57 | I34: =(I$22/121)*$C34 -> 66611.57 | J34: =(J$22/121)*$C34 -> 99917.355 | K34: =(K$22/121)*$C34 -> 83264.463 | ... O34: =(O$22/121)*$C34 -> 74938.017
A35: Leaflets/Brochures | B35: 2000 units to be sent to all active retailers at Rs 4/pc | C35: 16120000 | D35: =(D$22/121)*$C35 -> 1865124 | E35: =(E$22/121)*$C35 -> 1598677.7 | F35: =(F$22/121)*$C35 -> 1332231.4 | G35: =(G$22/121)*$C35 -> 1332231.4 | H35: =(H$22/121)*$C35 -> 1065785.1 | I35: =(I$22/121)*$C35 -> 1065785.1 | J35: =(J$22/121)*$C35 -> 1598677.7 | K35: =(K$22/121)*$C35 -> 1332231.4 | ... O35: =(O$22/121)*$C35 -> 1199008.3
A36: Annual Diaries | B36: 3 annual diaries per active retailer@Rs250/diary | C36: 1511250 | D36: 1557692.3 | E36: 0 | F36: 0 | G36: 0 | H36: 0 | I36: 0 | J36: 0 | K36: 0 | L36: 0 | M36: 0 | N36: 0 | O36: 0
A37: Festival Branding gifts (Diwali, Holi) | B37: To all active dealers and active influencers (3/retailer) | C37: 4030000 | D37: =C37*0.5 -> 2015000 | E37: 0 | F37: 0 | G37: 0 | H37: 0 | I37: 0 | J37: =C37-D37 -> 2015000 | K37: 0 | L37: 0 | M37: 0 | N37: 0 | O37: 0
A38: Branded Tarpaulins | B38: 1 Branded Tarpaulins @ 1500/pc | C38: 3022500 | D38: =(D$22/121)*$C38 -> 349710.74 | E38: =(E$22/121)*$C38 -> 299752.07 | F38: =(F$22/121)*$C38 -> 249793.39 | G38: =(G$22/121)*$C38 -> 249793.39 | H38: =(H$22/121)*$C38 -> 199834.71 | I38: =(I$22/121)*$C38 -> 199834.71 | J38: =(J$22/121)*$C38 -> 299752.07 | K38: =(K$22/121)*$C38 -> 249793.39 | ... O38: =(O$22/121)*$C38 -> 224814.05
A39: Cutout Standees from Ads | B39: For 50% of active retailer in size 5ft X 3ft; 5mm board with stand @ 2200/pc | C39: 2216500 | D39: =(D$22/121)*$C39 -> 256454.55 | E39: =(E$22/121)*$C39 -> 219818.18 | F39: =(F$22/121)*$C39 -> 183181.82 | G39: =(G$22/121)*$C39 -> 183181.82 | H39: =(H$22/121)*$C39 -> 146545.45 | I39: =(I$22/121)*$C39 -> 146545.45 | J39: =(J$22/121)*$C39 -> 219818.18 | K39: =(K$22/121)*$C39 -> 183181.82 | ... O39: =(O$22/121)*$C39 -> 164863.64
A40: Project BTL Activities | B40: Remarks | C40: =SUM(C42:C44) -> 1125000 | D40: =SUM(D42:D44) -> 322933.88 | E40: =SUM(E42:E44) -> 165289.26 | F40: =SUM(F42:F44) -> 165289.26 | G40: =SUM(G42:G44) -> 0 | H40: =SUM(H42:H44) -> 0 | I40: =SUM(I42:I44) -> 0 | J40: =SUM(J42:J44) -> 215289.26 | ... O40: =SUM(O42:O44) -> 0
...

Sheet One Helix
A1: Category | B1: Remarks | C1: YEAR TOTALS | D1: %age of totals - Bucketwise | E1: Q1 | I1: Q2 | M1: Q3 | Q1: Q4
E2: Apr | F2: May | G2: Jun | H2: Q1 Totals | I2: Jul | J2: Aug | K2: Sep | L2: Q2 Totals | M2: Oct | N2: Nov | O2: Dec | P2: Q3 Totals | Q2: Jan | R2: Feb | S2: Mar | T2: Q4 Totals
A3: Particulars
A4: #Distributors | B4: 42
A5: Volume projection (Mar'27 Exit) | B5: 27000
A6: Avg. volume/retailer/month | B6: 30
A7: Total retailers (Mar'27) | B7: =B8*3 -> 4153.8462
A8: Total Active retailers (Mar'27) | B8: =B9/65% -> 1384.6154
A9: Total transacting retailers (Mar'27) | B9: =B5/B6 -> 900
A10: #Priority districts | B10: 150
A11: ATL Activities | C11: =SUM(C12:C21) -> 140600000 | E11: =SUM(E12:E21) -> 10970250 | F11: =SUM(F12:F21) -> 14926250 | G11: =SUM(G12:G21) -> 10986000 | H11: =SUM(H12:H21) -> 36882500 | I11: =SUM(I12:I21) -> 4720500 | J11: =SUM(J12:J21) -> 5507250 | K11: =SUM(K12:K21) -> 7381500 | L11: =SUM(L12:L21) -> 17609250 | ... T11: =SUM(T12:T21) -> 35150000
A12: Impact Wall Painting | B12: 20,000 sq ft in 60 Very High and High priority district @ Rs 14 | C12: =60*20000*14 -> 16800000 | D12: =C12/$C$11 -> 0.11948791 | E12: =($D12*QuarterBreakup!C$10*'One Helix'!$C$56) -> 1260000 | F12: =$D12*QuarterBreakup!D$10*'One Helix'!$C$56+882000/2 -> 2121000 | G12: =$D12*QuarterBreakup!E$10*'One Helix'!$C$56+882000/2 -> 1701000 | H12: =E12+F12+G12 -> 5082000 | K12: =$D12*QuarterBreakup!E$16*'One Helix'!$C$56 -> 882000 | L12: =I12+J12+K12 -> 882000 | M12: =$D12*QuarterBreakup!C$22*'One Helix'!$C$56+756000/2 -> 2436000 | N12: =$D12*QuarterBreakup!D$22*'One Helix'!$C$56+756000/2 -> 2142000 | O12: =$D12*QuarterBreakup!E$22*'One Helix'!$C$56 -> 2058000 | P12: =M12+N12+O12 -> 6636000 | Q12: =$D12*QuarterBreakup!C$28*'One Helix'!$C$56 -> 1680000 | R12: =$D12*QuarterBreakup!D$28*'One Helix'!$C$56 -> 1260000 | S12: =$D12*QuarterBreakup!E$28*'One Helix'!$C$56 -> 1260000 | T12: =Q12+R12+S12 -> 4200000
A13: Integrated FM Radio Campaigns (Ad + Promotional Activity) | B13: To be done in Top 3 high priority districts for all 4 states @Rs 2.5 Lac/campaign/district/quarter (No. of states: 4) for 2 quarters | C13: =4*3*250000*2 -> 6000000 | D13: =C13/$C$11 -> 0.042674253 | E13: =$D13*QuarterBreakup!C$10*'One Helix'!$C$56 -> 450000 | F13: =$D13*QuarterBreakup!D$10*'One Helix'!$C$56 -> 600000 | G13: =$D13*QuarterBreakup!E$10*'One Helix'!$C$56 -> 450000 | H13: =E13+F13+G13 -> 1500000 | I13: =$D13*QuarterBreakup!C$16*'One Helix'!$C$56 -> 270000 | J13: =$D13*QuarterBreakup!D$16*'One Helix'!$C$56 -> 315000 | K13: =$D13*QuarterBreakup!E$16*'One Helix'!$C$56 -> 315000 | L13: =I13+J13+K13 -> 900000 | M13: =$D13*QuarterBreakup!C$22*'One Helix'!$C$56 -> 735000 | N13: =$D13*QuarterBreakup!D$22*'One Helix'!$C$56 -> 630000 | O13: =$D13*QuarterBreakup!E$22*'One Helix'!$C$56 -> 735000 | P13: =M13+N13+O13 -> 2100000 | Q13: =$D13*QuarterBreakup!C$28*'One Helix'!$C$56 -> 600000 | R13: =$D13*QuarterBreakup!D$28*'One Helix'!$C$56 -> 450000 | S13: =$D13*QuarterBreakup!E$28*'One Helix'!$C$56 -> 450000 | T13: =Q13+R13+S13 -> 1500000
A14: Hoardings (steel markets, cement shops cluster, construction zones) | B14: 5 hoardings in 60 Very High and High potential districts @ Rs 50K | C14: =60*5*50000 -> 15000000 | D14: =C14/$C$11 -> 0.10668563 | E14: =$D14*QuarterBreakup!C$10*'One Helix'!$C$56 -> 1125000 | F14: =$D14*QuarterBreakup!D$10*'One Helix'!$C$56 -> 1500000 | G14: =$D14*QuarterBreakup!E$10*'One Helix'!$C$56 -> 1125000 | H14: =E14+F14+G14 -> 3750000 | I14: =$D14*QuarterBreakup!C$16*'One Helix'!$C$56 -> 675000 | J14: =$D14*QuarterBreakup!D$16*'One Helix'!$C$56 -> 787500 | K14: =$D14*QuarterBreakup!E$16*'One Helix'!$C$56 -> 787500 | L14: =I14+J14+K14 -> 2250000 | M14: =$D14*QuarterBreakup!C$22*'One Helix'!$C$56 -> 1837500 | N14: =$D14*QuarterBreakup!D$22*'One Helix'!$C$56 -> 1575000 | O14: =$D14*QuarterBreakup!E$22*'One Helix'!$C$56 -> 1837500 | P14: =M14+N14+O14 -> 5250000 | Q14: =$D14*QuarterBreakup!C$28*'One Helix'!$C$56 -> 1500000 | R14: =$D14*QuarterBreakup!D$28*'One Helix'!$C$56 -> 1125000 | S14: =$D14*QuarterBreakup!E$28*'One Helix'!$C$56 -> 1125000 | T14: =Q14+R14+S14 -> 3750000
A15: Digital Marketing Campaigns | B15: To be done in Top 3 high potential districts for all 4 states @Rs 6 Lac/campaign/district/quarter (No. of states: 4) for 2 quarters | C15: =4*3*600000*2 -> 14400000 | D15: =C15/$C$11 -> 0.10241821 | E15: =$D15*QuarterBreakup!C$10*'One Helix'!$C$56 -> 1080000 | F15: =$D15*QuarterBreakup!D$10*'One Helix'!$C$56 -> 1440000 | G15: =$D15*QuarterBreakup!E$10*'One Helix'!$C$56 -> 1080000 | H15: =E15+F15+G15 -> 3600000 | I15: =$D15*QuarterBreakup!C$16*'One Helix'!$C$56 -> 648000 | J15: =$D15*QuarterBreakup!D$16*'One Helix'!$C$56 -> 756000 | K15: =$D15*QuarterBreakup!E$16*'One Helix'!$C$56 -> 756000 | L15: =I15+J15+K15 -> 2160000 | M15: =$D15*QuarterBreakup!C$22*'One Helix'!$C$56 -> 1764000 | N15: =$D15*QuarterBreakup!D$22*'One Helix'!$C$56 -> 1512000 | O15: =$D15*QuarterBreakup!E$22*'One Helix'!$C$56 -> 1764000 | P15: =M15+N15+O15 -> 5040000 | Q15: =$D15*QuarterBreakup!C$28*'One Helix'!$C$56 -> 1440000 | R15: =$D15*QuarterBreakup!D$28*'One Helix'!$C$56 -> 1080000 | S15: =$D15*QuarterBreakup!E$28*'One Helix'!$C$56 -> 1080000 | T15: =Q15+R15+S15 -> 3600000
A16: Local Events/Fairs/Exhibitions | B16: For different Plant Launches, promotional exhibitions and mass events like Mahakumbh, etc - Total 10 events | C16: 5000000 | D16: =C16/$C$11 -> 0.035561878 | E16: =$D16*QuarterBreakup!C$10*'One Helix'!$C$56 -> 375000 | F16: =$D16*QuarterBreakup!D$10*'One Helix'!$C$56 -> 500000 | G16: =$D16*QuarterBreakup!E$10*'One Helix'!$C$56 -> 375000 | H16: =E16+F16+G16 -> 1250000 | I16: =$D16*QuarterBreakup!C$16*'One Helix'!$C$56 -> 225000 | J16: =$D16*QuarterBreakup!D$16*'One Helix'!$C$56 -> 262500 | K16: =$D16*QuarterBreakup!E$16*'One Helix'!$C$56 -> 262500 | L16: =I16+J16+K16 -> 750000 | M16: =$D16*QuarterBreakup!C$22*'One Helix'!$C$56 -> 612500 | N16: =$D16*QuarterBreakup!D$22*'One Helix'!$C$56 -> 525000 | O16: =$D16*QuarterBreakup!E$22*'One Helix'!$C$56 -> 612500 | P16: =M16+N16+O16 -> 1750000 | Q16: =$D16*QuarterBreakup!C$28*'One Helix'!$C$56 -> 500000 | R16: =$D16*QuarterBreakup!D$28*'One Helix'!$C$56 -> 375000 | S16: =$D16*QuarterBreakup!E$28*'One Helix'!$C$56 -> 375000 | T16: =Q16+R16+S16 -> 1250000
A17: Paper Advertisement | B17: 1 newspaper insert for onboarding 50% of new distributors @1 Lac | C17: 0 | D17: =C17/$C$11 -> 0 | E17: =$D17*QuarterBreakup!C$10*'One Helix'!$C$56 -> 0 | F17: =$D17*QuarterBreakup!D$10*'One Helix'!$C$56 -> 0 | G17: =$D17*QuarterBreakup!E$10*'One Helix'!$C$56 -> 0 | H17: =E17+F17+G17 -> 0 | I17: =$D17*QuarterBreakup!C$16*'One Helix'!$C$56 -> 0 | J17: =$D17*QuarterBreakup!D$16*'One Helix'!$C$56 -> 0 | K17: =$D17*QuarterBreakup!E$16*'One Helix'!$C$56 -> 0 | L17: =I17+J17+K17 -> 0 | M17: =$D17*QuarterBreakup!C$22*'One Helix'!$C$56 -> 0 | N17: =$D17*QuarterBreakup!D$22*'One Helix'!$C$56 -> 0 | O17: =$D17*QuarterBreakup!E$22*'One Helix'!$C$56 -> 0 | P17: =M17+N17+O17 -> 0 | Q17: =$D17*QuarterBreakup!C$28*'One Helix'!$C$56 -> 0 | R17: =$D17*QuarterBreakup!D$28*'One Helix'!$C$56 -> 0 | S17: =$D17*QuarterBreakup!E$28*'One Helix'!$C$56 -> 0 | T17: =Q17+R17+S17 -> 0
A18: Van Campaign | B18: To be done in Top 3 high potential districts for all operational states @ Rs 7000 /day (No. of states: 15) for 2 month | C18: =15*3*7000*60 -> 18900000 | D18: =C18/$C$11 -> 0.1344239 | E18: =($D18*QuarterBreakup!C$10*'One Helix'!$C$56)+(850500/2) -> 1842750 | F18: =($D18*QuarterBreakup!D$10*'One Helix'!$C$56) + (850500/2) -> 2315250 | G18: =$D18*QuarterBreakup!E$10*'One Helix'!$C$56 -> 1417500 | H18: =E18+F18+G18 -> 5575500 | I18: 0 | J18: 0 | K18: =$D18*QuarterBreakup!E$16*'One Helix'!$C$56 -> 992250 | L18: =I18+J18+K18 -> 992250 | M18: =$D18*QuarterBreakup!C$22*'One Helix'!$C$56+(992250/2) -> 2811375 | N18: =$D18*QuarterBreakup!D$22*'One Helix'!$C$56+(992250/2) -> 2480625 | O18: =$D18*QuarterBreakup!E$22*'One Helix'!$C$56 -> 2315250 | P18: =M18+N18+O18 -> 7607250 | Q18: =$D18*QuarterBreakup!C$28*'One Helix'!$C$56 -> 1890000 | R18: =$D18*QuarterBreakup!D$28*'One Helix'!$C$56 -> 1417500 | S18: =$D18*QuarterBreakup!E$28*'One Helix'!$C$56 -> 1417500 | T18: =Q18+R18+S18 -> 4725000
A19: Syndicate Launch events | B19: Syndicate Launch events @15 states -Distributor base locations @Rs 5 Lac/event | C19: =15*500000 -> 7500000 | D19: =C19/$C$11 -> 0.053342817 | E19: =$D19*QuarterBreakup!C$10*'One Helix'!$C$56 -> 562500 | F19: =$D19*QuarterBreakup!D$10*'One Helix'!$C$56 -> 750000 | G19: =$D19*QuarterBreakup!E$10*'One Helix'!$C$56 -> 562500 | H19: =E19+F19+G19 -> 1875000 | I19: =$D19*QuarterBreakup!C$16*'One Helix'!$C$56 -> 337500 | J19: =$D19*QuarterBreakup!D$16*'One Helix'!$C$56 -> 393750 | K19: =$D19*QuarterBreakup!E$16*'One Helix'!$C$56 -> 393750 | L19: =I19+J19+K19 -> 1125000 | M19: =$D19*QuarterBreakup!C$22*'One Helix'!$C$56 -> 918750 | N19: =$D19*QuarterBreakup!D$22*'One Helix'!$C$56 -> 787500 | O19: =$D19*QuarterBreakup!E$22*'One Helix'!$C$56 -> 918750 | P19: =M19+N19+O19 -> 2625000 | Q19: =$D19*QuarterBreakup!C$28*'One Helix'!$C$56 -> 750000 | R19: =$D19*QuarterBreakup!D$28*'One Helix'!$C$56 -> 562500 | S19: =$D19*QuarterBreakup!E$28*'One Helix'!$C$56 -> 562500 | T19: =Q19+R19+S19 -> 1875000
A20: Transit Branding | B20: To be done in 60 priority districts (V.High & High Potential) @1000 autos @Rs. 700/auto | C20: =60*1000*700 -> 42000000 | D20: =C20/$C$11 -> 0.29871977 | E20: =$D20*QuarterBreakup!C$10*'One Helix'!$C$56 -> 3150000 | F20: =$D20*QuarterBreakup!D$10*'One Helix'!$C$56 -> 4200000 | G20: =$D20*QuarterBreakup!E$10*'One Helix'!$C$56 -> 3150000 | H20: =E20+F20+G20 -> 10500000 | I20: =$D20*QuarterBreakup!C$16*'One Helix'!$C$56 -> 1890000 | J20: =$D20*QuarterBreakup!D$16*'One Helix'!$C$56 -> 2205000 | K20: =$D20*QuarterBreakup!E$16*'One Helix'!$C$56 -> 2205000 | L20: =I20+J20+K20 -> 6300000 | M20: =$D20*QuarterBreakup!C$22*'One Helix'!$C$56 -> 5145000 | N20: =$D20*QuarterBreakup!D$22*'One Helix'!$C$56 -> 4410000 | O20: =$D20*QuarterBreakup!E$22*'One Helix'!$C$56 -> 5145000 | P20: =M20+N20+O20 -> 14700000 | Q20: =$D20*QuarterBreakup!C$28*'One Helix'!$C$56 -> 4200000 | R20: =$D20*QuarterBreakup!D$28*'One Helix'!$C$56 -> 3150000 | S20: =$D20*QuarterBreakup!E$28*'One Helix'!$C$56 -> 3150000 | T20: =Q20+R20+S20 -> 10500000
A21: Tea Stall / Chai Point /Dhaba Branding | B21: To be done in all high priority districts - 25 tea stalls/district @ Rs 4000/stall | C21: =B10*25*4000 -> 15000000 | D21: =C21/$C$11 -> 0.10668563 | E21: =$D21*QuarterBreakup!C$10*'One Helix'!$C$56 -> 1125000 | F21: =$D21*QuarterBreakup!D$10*'One Helix'!$C$56 -> 1500000 | G21: =$D21*QuarterBreakup!E$10*'One Helix'!$C$56 -> 1125000 | H21: =E21+F21+G21 -> 3750000 | I21: =$D21*QuarterBreakup!C$16*'One Helix'!$C$56 -> 675000 | J21: =$D21*QuarterBreakup!D$16*'One Helix'!$C$56 -> 787500 | K21: =$D21*QuarterBreakup!E$16*'One Helix'!$C$56 -> 787500 | L21: =I21+J21+K21 -> 2250000 | M21: =$D21*QuarterBreakup!C$22*'One Helix'!$C$56 -> 1837500 | N21: =$D21*QuarterBreakup!D$22*'One Helix'!$C$56 -> 1575000 | O21: =$D21*QuarterBreakup!E$22*'One Helix'!$C$56 -> 1837500 | P21: =M21+N21+O21 -> 5250000 | Q21: =$D21*QuarterBreakup!C$28*'One Helix'!$C$56 -> 1500000 | R21: =$D21*QuarterBreakup!D$28*'One Helix'!$C$56 -> 1125000 | S21: =$D21*QuarterBreakup!E$28*'One Helix'!$C$56 -> 1125000 | T21: =Q21+R21+S21 -> 3750000
A22: BTL Activities | C22: =SUM(C23:C40) -> 1.0086462e+08 | E22: =SUM(E23:E40) -> 7279269.2 | F22: =SUM(F23:F40) -> 9705692.3 | G22: =SUM(G23:G40) -> 7279269.2 | H22: =SUM(H23:H40) -> 24264231 | I22: =SUM(I23:I40) -> 4367561.5 | J22: =SUM(J23:J40) -> 5095488.5 | K22: =SUM(K23:K40) -> 5095488.5 | L22: =SUM(L23:L40) -> 14558538 | ... T22: =SUM(T23:T40) -> 26168077
A23: NLBs | B23: To be given to 50% of active dealers (Cost is taken to be Rs.40/sqft. Avg size is taken to be 10*3=30 sqft) | C23: =(B8*0.5)*40*30 -> 830769.23 | D23: =C23/$C$22 -> 0.0082364784 | E23: =QuarterBreakup!C$10*'One Helix'!$C$57*'One Helix'!$D23 -> 62307.692 | F23: =QuarterBreakup!D$10*'One Helix'!$C$57*'One Helix'!$D23 -> 83076.923 | G23: =QuarterBreakup!E$10*'One Helix'!$C$57*'One Helix'!$D23 -> 62307.692 | H23: =QuarterBreakup!F$10*'One Helix'!$C$57*'One Helix'!$D23 -> 207692.31 | I23: =QuarterBreakup!C$16*'One Helix'!$C$57*'One Helix'!$D23 -> 37384.615 | J23: =QuarterBreakup!D$16*'One Helix'!$C$57*'One Helix'!$D23 -> 43615.385 | K23: =QuarterBreakup!E$16*'One Helix'!$C$57*'One Helix'!$D23 -> 43615.385 | L23: =I23+J23+K23 -> 124615.38 | M23: =QuarterBreakup!C$22*'One Helix'!$C$57*'One Helix'!$D23 -> 101769.23 | N23: =QuarterBreakup!D$22*'One Helix'!$C$57*'One Helix'!$D23 -> 87230.769 | O23: =QuarterBreakup!E$22*'One Helix'!$C$57*'One Helix'!$D23 -> 101769.23 | P23: =SUM(M23:O23) -> 290769.23 | Q23: =QuarterBreakup!C$28*'One Helix'!$C$57*'One Helix'!$D23 -> 83076.923 | R23: =QuarterBreakup!D$28*'One Helix'!$C$57*'One Helix'!$D23 -> 62307.692 | S23: =QuarterBreakup!E$28*'One Helix'!$C$57*'One Helix'!$D23 -> 62307.692 | T23: =Q23+R23+S23 -> 207692.31
A24: GSBs | B24: To be given to 25% of active dealers. Cost: (180 *size of flex + 65*length of iron angle), Avg size of flex taken to be 10*3. Avg iron angle length: 18 ft | C24: =(B8*0.25)*(180*30+65*18) -> 2274230.8 | D24: =C24/$C$22 -> 0.02254736 | E24: =QuarterBreakup!C$10*'One Helix'!$C$57*'One Helix'!$D24 -> 170567.31 | F24: =QuarterBreakup!D$10*'One Helix'!$C$57*'One Helix'!$D24 -> 227423.08 | G24: =QuarterBreakup!E$10*'One Helix'!$C$57*'One Helix'!$D24 -> 170567.31 | H24: =SUM(E24:G24) -> 568557.69 | I24: =QuarterBreakup!C$16*'One Helix'!$C$57*'One Helix'!$D24 -> 102340.38 | J24: =QuarterBreakup!D$16*'One Helix'!$C$57*'One Helix'!$D24 -> 119397.12 | K24: =QuarterBreakup!E$16*'One Helix'!$C$57*'One Helix'!$D24 -> 119397.12 | L24: =I24+J24+K24 -> 341134.62 | M24: =QuarterBreakup!C$22*'One Helix'!$C$57*'One Helix'!$D24 -> 278593.27 | N24: =QuarterBreakup!D$22*'One Helix'!$C$57*'One Helix'!$D24 -> 238794.23 | O24: =QuarterBreakup!E$22*'One Helix'!$C$57*'One Helix'!$D24 -> 278593.27 | P24: =SUM(M24:O24) -> 795980.77 | Q24: =QuarterBreakup!C$28*'One Helix'!$C$57*'One Helix'!$D24 -> 227423.08 | R24: =QuarterBreakup!D$28*'One Helix'!$C$57*'One Helix'!$D24 -> 170567.31 | S24: =QuarterBreakup!E$28*'One Helix'!$C$57*'One Helix'!$D24 -> 170567.31 | T24: =Q24+R24+S24 -> 568557.69
A25: Counter Wall Painting | B25: To be given to exclusive 20% active counters @Rs 10000/counter | C25: =(B8*0.2)*10000 -> 2769230.8 | D25: =C25/$C$22 -> 0.027454928 | E25: =QuarterBreakup!C$10*'One Helix'!$C$57*'One Helix'!$D25 -> 207692.31 | F25: =QuarterBreakup!D$10*'One Helix'!$C$57*'One Helix'!$D25 -> 276923.08 | G25: =QuarterBreakup!E$10*'One Helix'!$C$57*'One Helix'!$D25 -> 207692.31 | H25: =SUM(E25:G25) -> 692307.69 | I25: =QuarterBreakup!C$16*'One Helix'!$C$57*'One Helix'!$D25 -> 124615.38 | J25: =QuarterBreakup!D$16*'One Helix'!$C$57*'One Helix'!$D25 -> 145384.62 | K25: =QuarterBreakup!E$16*'One Helix'!$C$57*'One Helix'!$D25 -> 145384.62 | L25: =I25+J25+K25 -> 415384.62 | M25: =QuarterBreakup!C$22*'One Helix'!$C$57*'One Helix'!$D25 -> 339230.77 | N25: =QuarterBreakup!D$22*'One Helix'!$C$57*'One Helix'!$D25 -> 290769.23 | O25: =QuarterBreakup!E$22*'One Helix'!$C$57*'One Helix'!$D25 -> 339230.77 | P25: =SUM(M25:O25) -> 969230.77 | Q25: =QuarterBreakup!C$28*'One Helix'!$C$57*'One Helix'!$D25 -> 276923.08 | R25: =QuarterBreakup!D$28*'One Helix'!$C$57*'One Helix'!$D25 -> 207692.31 | S25: =QuarterBreakup!E$28*'One Helix'!$C$57*'One Helix'!$D25 -> 207692.31 | T25: =Q25+R25+S25 -> 692307.69
A26: Inshop Branding | B26: To be given to exclusive 10% active counters @Rs 40000/counter | C26: =(B8*0.1)*40000 -> 5538461.5 | D26: =C26/$C$22 -> 0.054909856 | E26: =QuarterBreakup!C$10*'One Helix'!$C$57*'One Helix'!$D26 -> 415384.62 | F26: =QuarterBreakup!D$10*'One Helix'!$C$57*'One Helix'!$D26 -> 553846.15 | G26: =QuarterBreakup!E$10*'One Helix'!$C$57*'One Helix'!$D26 -> 415384.62 | H26: =SUM(E26:G26) -> 1384615.4 | I26: =QuarterBreakup!C$16*'One Helix'!$C$57*'One Helix'!$D26 -> 249230.77 | J26: =QuarterBreakup!D$16*'One Helix'!$C$57*'One Helix'!$D26 -> 290769.23 | K26: =QuarterBreakup!E$16*'One Helix'!$C$57*'One Helix'!$D26 -> 290769.23 | L26: =I26+J26+K26 -> 830769.23 | M26: =QuarterBreakup!C$22*'One Helix'!$C$57*'One Helix'!$D26 -> 678461.54 | N26: =QuarterBreakup!D$22*'One Helix'!$C$57*'One Helix'!$D26 -> 581538.46 | O26: =QuarterBreakup!E$22*'One Helix'!$C$57*'One Helix'!$D26 -> 678461.54 | P26: =SUM(M26:O26) -> 1938461.5 | Q26: =QuarterBreakup!C$28*'One Helix'!$C$57*'One Helix'!$D26 -> 553846.15 | R26: =QuarterBreakup!D$28*'One Helix'!$C$57*'One Helix'!$D26 -> 415384.62 | S26: =QuarterBreakup!E$28*'One Helix'!$C$57*'One Helix'!$D26 -> 415384.62 | T26: =Q26+R26+S26 -> 1384615.4
A27: Architect/Engineer Meets | B27: Considering every distributor does 1 meets with 50 architects @Rs 3500/pax every quarter | C27: =B4*1*4*50*3500 -> 29400000 | D27: =C27/$C$22 -> 0.29147982 | E27: =QuarterBreakup!C$10*'One Helix'!$C$57*'One Helix'!$D27 -> 2205000 | F27: =QuarterBreakup!D$10*'One Helix'!$C$57*'One Helix'!$D27 -> 2940000 | G27: =QuarterBreakup!E$10*'One Helix'!$C$57*'One Helix'!$D27 -> 2205000 | H27: =SUM(E27:G27) -> 7350000 | I27: =QuarterBreakup!C$16*'One Helix'!$C$57*'One Helix'!$D27 -> 1323000 | J27: =QuarterBreakup!D$16*'One Helix'!$C$57*'One Helix'!$D27 -> 1543500 | K27: =QuarterBreakup!E$16*'One Helix'!$C$57*'One Helix'!$D27 -> 1543500 | L27: =I27+J27+K27 -> 4410000 | M27: =QuarterBreakup!C$22*'One Helix'!$C$57*'One Helix'!$D27 -> 3601500 | N27: =QuarterBreakup!D$22*'One Helix'!$C$57*'One Helix'!$D27 -> 3087000 | O27: =QuarterBreakup!E$22*'One Helix'!$C$57*'One Helix'!$D27 -> 3601500 | P27: =SUM(M27:O27) -> 10290000 | Q27: =QuarterBreakup!C$28*'One Helix'!$C$57*'One Helix'!$D27 -> 2940000 | R27: =QuarterBreakup!D$28*'One Helix'!$C$57*'One Helix'!$D27 -> 2205000 | S27: =QuarterBreakup!E$28*'One Helix'!$C$57*'One Helix'!$D27 -> 2205000 | T27: =Q27+R27+S27 -> 7350000
A28: Contractor Meets | B28: Considering every distributor does 2 meets with 50 contractors @Rs 1000/pax per quarter | C28: =B4*2*4*50*1000 -> 16800000 | D28: =C28/$C$22 -> 0.1665599 | E28: =QuarterBreakup!C$10*'One Helix'!$C$57*'One Helix'!$D28 -> 1260000 | F28: =QuarterBreakup!D$10*'One Helix'!$C$57*'One Helix'!$D28 -> 1680000 | G28: =QuarterBreakup!E$10*'One Helix'!$C$57*'One Helix'!$D28 -> 1260000 | H28: =SUM(E28:G28) -> 4200000 | I28: =QuarterBreakup!C$16*'One Helix'!$C$57*'One Helix'!$D28 -> 756000 | J28: =QuarterBreakup!D$16*'One Helix'!$C$57*'One Helix'!$D28 -> 882000 | K28: =QuarterBreakup!E$16*'One Helix'!$C$57*'One Helix'!$D28 -> 882000 | L28: =I28+J28+K28 -> 2520000 | M28: =QuarterBreakup!C$22*'One Helix'!$C$57*'One Helix'!$D28 -> 2058000 | N28: =QuarterBreakup!D$22*'One Helix'!$C$57*'One Helix'!$D28 -> 1764000 | O28: =QuarterBreakup!E$22*'One Helix'!$C$57*'One Helix'!$D28 -> 2058000 | P28: =SUM(M28:O28) -> 5880000 | Q28: =QuarterBreakup!C$28*'One Helix'!$C$57*'One Helix'!$D28 -> 1680000 | R28: =QuarterBreakup!D$28*'One Helix'!$C$57*'One Helix'!$D28 -> 1260000 | S28: =QuarterBreakup!E$28*'One Helix'!$C$57*'One Helix'!$D28 -> 1260000 | T28: =Q28+R28+S28 -> 4200000
A29: Mason Meets | B29: 1 Mason meet for every transacting dealer, of 30 pax/meet Cost @ Rs 300/pax/meet | C29: =B9*1*30*300 -> 8100000 | D29: =C29/$C$22 -> 0.080305665 | E29: =QuarterBreakup!C$10*'One Helix'!$C$57*'One Helix'!$D29 -> 607500 | F29: =QuarterBreakup!D$10*'One Helix'!$C$57*'One Helix'!$D29 -> 810000 | G29: =QuarterBreakup!E$10*'One Helix'!$C$57*'One Helix'!$D29 -> 607500 | H29: =SUM(E29:G29) -> 2025000 | I29: =QuarterBreakup!C$16*'One Helix'!$C$57*'One Helix'!$D29 -> 364500 | J29: =QuarterBreakup!D$16*'One Helix'!$C$57*'One Helix'!$D29 -> 425250 | K29: =QuarterBreakup!E$16*'One Helix'!$C$57*'One Helix'!$D29 -> 425250 | L29: =I29+J29+K29 -> 1215000 | M29: =QuarterBreakup!C$22*'One Helix'!$C$57*'One Helix'!$D29 -> 992250 | N29: =QuarterBreakup!D$22*'One Helix'!$C$57*'One Helix'!$D29 -> 850500 | O29: =QuarterBreakup!E$22*'One Helix'!$C$57*'One Helix'!$D29 -> 992250 | P29: =SUM(M29:O29) -> 2835000 | Q29: =QuarterBreakup!C$28*'One Helix'!$C$57*'One Helix'!$D29 -> 810000 | R29: =QuarterBreakup!D$28*'One Helix'!$C$57*'One Helix'!$D29 -> 607500 | S29: =QuarterBreakup!E$28*'One Helix'!$C$57*'One Helix'!$D29 -> 607500 | T29: =Q29+R29+S29 -> 2025000
A30: Dealer Certificates | B30: To be given to all active retailers @Rs 400 | C30: =B8*400 -> 553846.15 | D30: =C30/$C$22 -> 0.0054909856 | E30: =QuarterBreakup!C$10*'One Helix'!$C$57*'One Helix'!$D30 -> 41538.462 | F30: =QuarterBreakup!D$10*'One Helix'!$C$57*'One Helix'!$D30 -> 55384.615 | G30: =QuarterBreakup!E$10*'One Helix'!$C$57*'One Helix'!$D30 -> 41538.462 | H30: =SUM(E30:G30) -> 138461.54 | I30: =QuarterBreakup!C$16*'One Helix'!$C$57*'One Helix'!$D30 -> 24923.077 | J30: =QuarterBreakup!D$16*'One Helix'!$C$57*'One Helix'!$D30 -> 29076.923 | K30: =QuarterBreakup!E$16*'One Helix'!$C$57*'One Helix'!$D30 -> 29076.923 | L30: =I30+J30+K30 -> 83076.923 | M30: =QuarterBreakup!C$22*'One Helix'!$C$57*'One Helix'!$D30 -> 67846.154 | N30: =QuarterBreakup!D$22*'One Helix'!$C$57*'One Helix'!$D30 -> 58153.846 | O30: =QuarterBreakup!E$22*'One Helix'!$C$57*'One Helix'!$D30 -> 67846.154 | P30: =SUM(M30:O30) -> 193846.15 | Q30: =QuarterBreakup!C$28*'One Helix'!$C$57*'One Helix'!$D30 -> 55384.615 | R30: =QuarterBreakup!D$28*'One Helix'!$C$57*'One Helix'!$D30 -> 41538.462 | S30: =QuarterBreakup!E$28*'One Helix'!$C$57*'One Helix'!$D30 -> 41538.462 | T30: =Q30+R30+S30 -> 138461.54
