Workbook

Sheet Sheet1
A1: District | B1: State | C1: Zone | D1: Distributor | E1: Categorization of District | F1: stock yard presence | G1: No. of Dealers ( >100 MT) | H1: Stockist | L1: Haryana
A2: Gurugram | B2: HARYANA | C2: North | D2: NIKUNJ UDYOG | E2: Very High | G2: =COUNTIFS(Sheet2!D:D,Sheet1!A2) -> 9 | L2: west bengal
A3: Hisar | B3: HARYANA | C3: North | D3: PAL CEMENT AND STEEL PVT. LTD. | E3: Medium | F3: Yes | G3: =COUNTIFS(Sheet2!D:D,Sheet1!A3) -> 8 | L3: Bihar
A4: Panchkula | B4: HARYANA | C4: North | D4: RAMDOOT UDHYOG PRIVATE LIMITED | E4: Medium | G4: =COUNTIFS(Sheet2!D:D,Sheet1!A4) -> 3
A5: Sonipat | B5: HARYANA | C5: North | D5: JAI DURGA STEELS | E5: Medium | F5: Yes | G5: =COUNTIFS(Sheet2!D:D,Sheet1!A5) -> 6
A6: Jind | B6: HARYANA | C6: North | D6: PAL CEMENT AND STEEL PVT. LTD. | E6: Medium | G6: =COUNTIFS(Sheet2!D:D,Sheet1!A6) -> 3
A7: Kaithal | B7: HARYANA | C7: North | D7: RAMDOOT UDHYOG PRIVATE LIMITED | E7: Medium | G7: =COUNTIFS(Sheet2!D:D,Sheet1!A7) -> 3
A8: Karnal | B8: HARYANA | C8: North | D8: RAMDOOT UDHYOG PRIVATE LIMITED | E8: Medium | G8: =COUNTIFS(Sheet2!D:D,Sheet1!A8) -> 4
A9: Rewari | B9: HARYANA | C9: North | D9: NIKUNJ UDYOG | E9: Medium | G9: =COUNTIFS(Sheet2!D:D,Sheet1!A9) -> 2
A10: Jhajjar | B10: HARYANA | C10: North | D10: JAI DURGA STEELS | E10: Low | G10: =COUNTIFS(Sheet2!D:D,Sheet1!A10) -> 4
A11: Mahendragarh | B11: HARYANA | C11: North | D11: NIKUNJ UDYOG | E11: Low | G11: =COUNTIFS(Sheet2!D:D,Sheet1!A11) -> 0
A12: Jaipur | B12: RAJASTHAN | C12: North | D12: J P ALLOYS | E12: Very High | F12: Yes | G12: =COUNTIFS(Sheet2!D:D,Sheet1!A12) -> 8
A13: Jodhpur | B13: RAJASTHAN | C13: North | D13: M R ASSOCIATES | E13: Very High | F13: Yes | G13: =COUNTIFS(Sheet2!D:D,Sheet1!A13) -> 8
A14: Kota | B14: RAJASTHAN | C14: North | D14: J P ALLOYS | E14: High | G14: =COUNTIFS(Sheet2!D:D,Sheet1!A14) -> 0
A15: Ajmer | B15: RAJASTHAN | C15: North | D15: Swastik Tradevision Pvt. Ltd. | E15: High | G15: =COUNTIFS(Sheet2!D:D,Sheet1!A15) -> 2
A16: Alwar | B16: RAJASTHAN | C16: North | D16: Swastik Tradevision Pvt. Ltd. | E16: High | G16: =COUNTIFS(Sheet2!D:D,Sheet1!A16) -> 1
A17: Sikar | B17: RAJASTHAN | C17: North | D17: BD ISPAT AND ALLOYS | E17: High | G17: =COUNTIFS(Sheet2!D:D,Sheet1!A17) -> 0
A18: Pali | B18: RAJASTHAN | C18: North | D18: M R ASSOCIATES | E18: Medium | G18: =COUNTIFS(Sheet2!D:D,Sheet1!A18) -> 1
A19: Jhalawar | B19: RAJASTHAN | C19: North | D19: J P ALLOYS | E19: Medium | G19: =COUNTIFS(Sheet2!D:D,Sheet1!A19) -> 0
A20: Jhunjhunu | B20: RAJASTHAN | C20: North | D20: BD ISPAT AND ALLOYS | E20: Medium | G20: =COUNTIFS(Sheet2!D:D,Sheet1!A20) -> 0
A21: Hanumangarh | B21: RAJASTHAN | C21: North | D21: BD ISPAT AND ALLOYS | E21: Medium | G21: =COUNTIFS(Sheet2!D:D,Sheet1!A21) -> 0
A22: Nagaur | B22: RAJASTHAN | C22: North | D22: Swastik Tradevision Pvt. Ltd. | E22: Medium | G22: =COUNTIFS(Sheet2!D:D,Sheet1!A22) -> 2
A23: Churu | B23: RAJASTHAN | C23: North | D23: BD ISPAT AND ALLOYS | E23: Medium | G23: =COUNTIFS(Sheet2!D:D,Sheet1!A23) -> 0
A24: Tonk | B24: RAJASTHAN | C24: North | D24: J P ALLOYS | E24: Medium | G24: =COUNTIFS(Sheet2!D:D,Sheet1!A24) -> 0
A25: Jalore | B25: RAJASTHAN | C25: North | D25: M R ASSOCIATES | E25: Medium | G25: =COUNTIFS(Sheet2!D:D,Sheet1!A25) -> 0
... A37: Lucknow | B37: UTTAR PRADESH | C37: North | D37: SHREE LAKSHMAN ROLLING MILL (INDIA) LLP | E37: Very High | G37: =COUNTIFS(Sheet2!D:D,Sheet1!A37) -> 3
A38: Kanpur Nagar | B38: UTTAR PRADESH | C38: North | D38: SHREE LAKSHMAN ROLLING MILL (INDIA) LLP | E38: High | F38: Yes | G38: =COUNTIFS(Sheet2!D:D,Sheet1!A38) -> 1
A39: Varanasi | B39: UTTAR PRADESH | C39: North | D39: OPTRIX INFRA LLP 2 | E39: High | G39: =COUNTIFS(Sheet2!D:D,Sheet1!A39) -> 3
A40: Moradabad | B40: UTTAR PRADESH | C40: North | D40: OPTRIX INFRA LLP | E40: Medium | G40: =COUNTIFS(Sheet2!D:D,Sheet1!A40) -> 0
A41: Agra | B41: UTTAR PRADESH | C41: North | D41: Dinesh Steel Private Limited | E41: High | F41: Yes | G41: =COUNTIFS(Sheet2!D:D,Sheet1!A41) -> 4
A42: Kanpur Dehat | B42: UTTAR PRADESH | C42: North | D42: SHREE LAKSHMAN ROLLING MILL (INDIA) LLP | E42: High | G42: =COUNTIFS(Sheet2!D:D,Sheet1!A42) -> 0
A43: Unnao | B43: UTTAR PRADESH | C43: North | D43: SHREE LAKSHMAN ROLLING MILL (INDIA) LLP | E43: Medium | G43: =COUNTIFS(Sheet2!D:D,Sheet1!A43) -> 0
A44: Meerut | B44: UTTAR PRADESH | C44: North | D44: OPTRIX INFRA LLP | E44: Medium | G44: =COUNTIFS(Sheet2!D:D,Sheet1!A44) -> 0
A45: Barabanki | B45: UTTAR PRADESH | C45: North | D45: SHREE LAKSHMAN ROLLING MILL (INDIA) LLP | E45: Medium | G45: =COUNTIFS(Sheet2!D:D,Sheet1!A45) -> 0
A46: Gorakhpur | B46: UTTAR PRADESH | C46: North | D46: GOBINDGARH IRON LLP | E46: Medium | F46: Yes | G46: =COUNTIFS(Sheet2!D:D,Sheet1!A46) -> 2
A47: Muzaffarnagar | B47: UTTAR PRADESH | C47: North | D47: OPTRIX INFRA LLP | E47: Medium | G47: =COUNTIFS(Sheet2!D:D,Sheet1!A47) -> 1
A48: Bijnor | B48: UTTAR PRADESH | C48: North | D48: OPTRIX INFRA LLP | E48: Medium | G48: =COUNTIFS(Sheet2!D:D,Sheet1!A48) -> 0
A49: Mathura | B49: UTTAR PRADESH | C49: North | D49: Dinesh Steel Private Limited | E49: Medium | G49: =COUNTIFS(Sheet2!D:D,Sheet1!A49) -> 2
A50: Lakhimpur | B50: UTTAR PRADESH | C50: North | D50: SHREE LAKSHMAN ROLLING MILL (INDIA) LLP | E50: Medium | G50: =COUNTIFS(Sheet2!D:D,Sheet1!A50) -> 0
A51: Sultanpur | B51: UTTAR PRADESH | C51: North | D51: SHREE LAKSHMAN ROLLING MILL (INDIA) LLP | E51: Medium | G51: =COUNTIFS(Sheet2!D:D,Sheet1!A51) -> 0
...

Sheet Sheet2
A1: Account Sf ID | B1: Name of the Dealer | C1: State | D1: District | E1: Taluka | F1: Distributor Name | G1: Account Owner As per SF
A2: 0015g00001UBHkRAAX | B2: M/S SHRI NIRMAL KUMAR JAIN & CO. | C2: UTTAR PRADESH | D2: KANPUR NAGAR | E2: Fazalganj | F2: SHREE LAKSHMAN ROLLING MILL (INDIA) LLP | G2: Ashutosh Shukla
A3: 0015g00001V9fpAAAR | B3: ALLAHABAD IRON AND STEEL COMPANY | C3: UTTAR PRADESH | D3: PRAYAGRAJ | E3: Prayagraj | F3: GLOBAL IRONTRADING PVT. LTD. | G3: Divyansh Dhawal
A4: 0015g00001W4TWFAA3 | B4: JAI DURGA IRON & STEEL COMPANY | C4: UTTAR PRADESH | D4: MATHURA | E4: Mathura | F4: DINESH STEEL PRIVATE LIMITED | G4: Pankaj Garg
A5: 0015g00001YOMCMAA5 | B5: M/S AAR DEE DISTRIBUTORS | C5: UTTAR PRADESH | D5: AGRA | E5: Agra | F5: DINESH STEEL PRIVATE LIMITED | G5: Pankaj Garg
A6: 0015g00001Y3x1EAAR | B6: M/S MEENA STEELS | C6: UTTAR PRADESH | D6: AGRA | E6: Agra | F6: DINESH STEEL PRIVATE LIMITED | G6: Pankaj Garg
A7: 0015g00001caT4XAAU | B7: M/S TIRUPATI INFRA DEVLOPERS | C7: UTTAR PRADESH | D7: VARANASI | E7: Rajatalab | F7: GLOBAL IRONTRADING PVT. LTD. | G7: Divyansh Dhawal
A8: 0015g00001UBHbSAAX | B8: KVA Trading Company | C8: UTTAR PRADESH | D8: GAUTAM BUDDHA NAGAR | E8: Ghaziabad | F8: SHASHI STEELS CORPORATION | G8: Abhijeet Biswas
A9: 0015g00001UBHaiAAH | B9: SHARMA STEELS AND PIPES | C9: HARYANA | D9: REWARI | E9: Rewari | F9: NIKUNJ UDYOG | G9: Shiv Shankar Sharma
A10: 0015g00001UBHaFAAX | B10: DELHI STEEL & CEMENT | C10: HARYANA | D10: GURUGRAM | E10: Gurugram | F10: NIKUNJ UDYOG | G10: Shiv Shankar Sharma
A11: 0015g00001UBHjbAAH | B11: Yadav Iron Store | C11: HARYANA | D11: REWARI | E11: Rewari | F11: NIKUNJ UDYOG | G11: Shiv Shankar Sharma
A12: 001J100000RyDBkIAN | B12: BAHALGARH STEEL UDYOG | C12: HARYANA | D12: SONIPAT | E12: Sonipat | F12: JAI DURGA STEELS | G12: Sunny Bhutani
... A55: 0015g00001RKmdfAAD | B55: M/S KESHARI BHANDAR | C55: UTTAR PRADESH | D55: MIRZAPUR | E55: Gonda | F55: GLOBAL IRONTRADING PVT. LTD. | G55: Divyansh Dhawal
A56: 0015g00001gv91iAAA | B56: MEWAR STEEL | C56: RAJASTHAN | D56: CHITTORGARH | F56: J P ALLOYS | G56: Pushpendra Kumar
A57: 0015g00001f9BXpAAM | B57: SHAKTI STEELS | C57: RAJASTHAN | D57: JODHPUR | E57: Jodhpur | F57: M R Associates | G57: Neeraj Sharma
A58: 0015g00001fx5hlAAA | B58: GIRIRAJ STEELS | C58: RAJASTHAN | D58: JODHPUR | E58: Jodhpur | F58: M R Associates | G58: Neeraj Sharma
A59: 001J100000TuLNmIAN | B59: JMB & CO. | C59: RAJASTHAN | D59: JAISALMER | E59: Jaisalmer | F59: M R Associates | G59: Neeraj Sharma
A60: 0015g00001geGaJAAU | B60: SHREE SUMER SAGAR STEEL | C60: RAJASTHAN | D60: AJMER | E60: Ajmer | F60: Swastik Tradevision Pvt. Ltd. | G60: Ravi Kumar Kulmi
A61: 0015g00001f8c5UAAQ | B61: M/S LAXMI STEELS | C61: UTTAR PRADESH | D61: ALIGARH | E61: Aligarh | F61: DINESH STEEL PRIVATE LIMITED | G61: Pawan Kumar
A62: 001J1000002jX2GIAU | B62: M/S SANDEEP & COMPANY | C62: UTTAR PRADESH | D62: FIROZABAD | E62: Tundla | F62: DINESH STEEL PRIVATE LIMITED | G62: Pankaj Garg
A63: 0015g00001gv7wFAAQ | B63: BABA SHEOT NATH CEMENT STORE | C63: HARYANA | D63: ROHTAK | E63: Meham | F63: JAI DURGA STEELS | G63: Sunny Bhutani
A64: 001J100000EpBvjIAF | B64: BABA STEEL | C64: HARYANA | D64: HISAR | E64: Samalkha | F64: JAI DURGA STEELS | G64: Sunny Bhutani
A65: 0015g00001XK8bKAAT | B65: M/S DELHI STEEL & SANITARY HOUSE | C65: UTTAR PRADESH | D65: GHAZIABAD | E65: Ghaziabad | F65: OPTRIX INFRA LLP | G65: Aashish Goyal
A66: 0015g00001fUOLdAAO | B66: BHAGWATI CEMENT STORE | C66: HARYANA | D66: KARNAL | E66: Karnal | F66: RAMDOOT UDHYOG PRIVATE LIMITED | G66: Naseem Makkar
A67: 0015g00001X2P8zAAF | B67: SAINI CEMENT AND BUILDING MATERIAL | C67: HARYANA | D67: PANCHKULA | E67: Raipur Rani | F67: RAMDOOT UDHYOG PRIVATE LIMITED | G67: Sushant Abrol
A68: 001J100000CMm7xIAD | B68: SHREE BALA JI SANITARY STORE | C68: HARYANA | D68: KURUKSHETRA | E68: Pehowa | F68: RAMDOOT UDHYOG PRIVATE LIMITED | G68: Naseem Makkar
... A77: 0015g00001XKKMAAA5 | B77: CHHITAR MAL PURUSHOTTAM DAS | C77: UTTAR PRADESH | D77: MATHURA | E77: Mathura | F77: DINESH STEEL PRIVATE LIMITED | G77: Pankaj Garg
A78: 001J100000JrSC0IAN | B78: JINDAL STEEL & INFRA LINES | C78: RAJASTHAN | D78: JAIPUR | F78: J P ALLOYS | G78: Pushpendra Kumar
A79: 001J100000JM6xzIAD | B79: SHUBHAM TRADING CO | C79: HARYANA | D79: HISAR | E79: Hisar | F79: PAL CEMENT AND STEEL PVT. LTD. | G79: Dinesh Kumar
A80: 0015g00001XanN4AAJ | B80: M/S VAISHNAVI TRADING CORPORATION | C80: UTTAR PRADESH | D80: LUCKNOW | E80: Sarojini Nagar | F80: SHREE LAKSHMAN ROLLING MILL (INDIA) LLP | G80: Deepanshu
A81: 0015g00001UBHaJAAX | B81: SHREE SHYAM STEEL | C81: HARYANA | D81: GURUGRAM | E81: Gurugram | F81: NIKUNJ UDYOG | G81: Shiv Shankar Sharma
A82: 001J100000DqPBgIAN | B82: SHREE BALAJI ENTERPRISES | C82: UTTAR PRADESH | D82: SHAMLI | E82: Shamli | F82: OPTRIX INFRA LLP | G82: SHIV KUMAR
A83: 001J100000JrJwqIAF | B83: JP STEEL TUBES & PIPES PRIVATE LIMITED | C83: RAJASTHAN | D83: JAIPUR | F83: J P ALLOYS | G83: Mukesh Agarwal
A84: 001J1000005ZqvLIAS | B84: J P STEEL CO | C84: RAJASTHAN | D84: JAIPUR | E84: Jaipur | F84: J P ALLOYS | G84: Amit Kumar Sharma
A85: 001J100000BadzzIAB | B85: HINGLAJ IRON STORE | C85: RAJASTHAN | D85: BARMER | E85: Barmer | F85: M R Associates | G85: Neeraj Sharma
A86: 0015g00001f8tNYAAY | B86: KABRA IRON AGENCIES | C86: RAJASTHAN | D86: JODHPUR | E86: Jodhpur | F86: M R Associates | G86: Neeraj Sharma
A87: 0015g00001f8ua5AAA | B87: ROOP STEEL TRADING COMPANY | C87: RAJASTHAN | D87: JODHPUR | E87: Jodhpur | F87: M R Associates | G87: Neeraj Sharma
A88: 001J100000JsZI8IAN | B88: PRATEEK TRADERS | C88: HARYANA | D88: PANIPAT | E88: Panipat | F88: JAI DURGA STEELS | G88: Sunny Bhutani
A89: 001J1000007opyJIAQ | B89: CITY BUILDER | C89: HARYANA | D89: ROHTAK | E89: Rohtak | F89: JAI DURGA STEELS | G89: Sunny Bhutani
A90: 0015g00001VBCeyAAH | B90: SURAJ BHAN NIRANIA SALES COP. | C90: HARYANA | D90: BHIWANI | E90: Bhiwani | F90: PAL CEMENT AND STEEL PVT. LTD. | G90: Dinesh Kumar
...
