Workbook

Sheet Minutes of Meeting
B1: Sr. No. | C1: Point of discussion | D1: Brief description of activity/Actionables | E1: Responsibilities | F1: Timelines/ Remarks
B2: 1 | C2: Supply chain design | D2: Create a supply chain design (for 1 state - Uttar Pradesh) comprising of the following - 1. Create a brand-wise distribution / supply 2. Current distributor stocking points + additional stockyards (wherever required) 3. How do we incentivice stocking - current stocking vs ship to is (38 / 62); What will be our ratio [this should differ for Western UP + Eastern, Central UP] 4. Nodal agency approvals required in the state [identification of key nodal agency bodies] 5. Wholeseller -> smaller dealers [identification of wholesellers + associated smaller dealers] | E2: Kunal, Shariq, Satyam/Ajay/Mohit | F2: 46065
B3: =B2+1 -> 2 | C3: Nodal agency approach | D3: - Designing of Nodal Agency approval process - Budget requirements + approvals - Manpower requirements - senior resource is required to handle key project customers - Credit facilities (BG/LC) - Separate deck to be shared on the work that is done + plan for FY 27 | E3: Sumit, Bhrugesh, Ashu | F3: Feb 3rd week
B4: =B3+1 -> 3 | C4: Gaurav's Market visit plan | D4: Detailed visit plan for East | E4: Mohit | F4: March 1st/2nd week
B5: =B4+1 -> 4 | C5: Channel | D5: Rework numbers (at a brand level) for UP, HR, East, RJ + revised market share in these markets [at a premium price point, non-premium price point] - Idealogy: Replace Fe550 fully with Fe550D; price of One Helix to be fixed (~INR 2,000 lower) | E5: Kunal, Mohit, Ajay Swami | F5: Feb 4th week
B6: =B5+1 -> 5 | D6: Reassess low-priority states (J&K, HP, Assam, CG) - do we want to supply to these states? If yes, what brand and at what price position? | E6: Mohit, Sumit | F6: Feb 4th week
B7: =B6+1 -> 6 | D7: One Helix launch in 3 key markets + phase-wise plan for the other states | E7: Kunal, Mohit, Sumit | F7: Feb 4th week
B8: =B7+1 -> 7 | D8: Design the MoU for FY 27 [focus should be on incentivising higher for One Helix TMT] | E8: Sumit, Mohit, Kunal | F8: Feb 4th week
B9: =B8+1 -> 8 | D9: Retailer app. - - Additional functionalities required? [to be discussed with the product team] - sales, MTD, YTD, marketing collaterals, smart nudges - to look at the current messaging functionality available with the org. - How do we use the retailer app. to engage the dealers | E9: Mohit, Kunal, Puneet, Rajeshwar | F9: Feb 3rd week
B10: =B9+1 -> 9 | D10: Distributor MoU signing [+ meeting to be set up at a central location] | E10: Mohit, Kunal, Sumit | F10: TBD
B11: =B10+1 -> 10 | C11: Influencer Engagement | D11: Create a structured program for 'ACE' [Architects, Contractors, Engineers] - Structure + initiatives need to be defined | E11: Mohit, Jagdish, Tanvi | F11: Feb 4th week
B12: =B11+1 -> 11 | D12: Rework the approach for mason meets - train the DSRs/DGOs for this | E12: Jagdish, HR | F12: TBD
B13: =B12+1 -> 12 | C13: Marketing & Branding | D13: State-level marketing plans to be developed [start with UP, HR, RJ, East] - Plan for East [with a focus on brand-awareness] - District-wise plan needs to be created [as is status today vs plan for FY 27] - Co-branded assets for One Helix TMT + JSW One TMT / evaluate co-branding between One Helix P&T and One Helix TMT [what is the overlap] - Basic branding activites [GSB/NLB, Inshop, Counter branding, POP] to be executed without special approval [auto approved] | E13: Channel team | F13: Feb 4th week
B14: =B13+1 -> 13 | C14: Kathmandu trip - communication | D14: Conduct technical knowledge sessions - Dealer meet deck + LRF (Arijit) | E14: Arijit | F14: 46065
B15: =B14+1 -> 14 | D15: Review last year lifting vs current year plan - FY'26 Performance | E15: Kunal
B16: =B15+1 -> 15 | D16: Define clear trip objectives and KPIs (Internal) - Qualifiers for FY'26, Prospects for FY'27 | E16: Kunal
B17: =B16+1 -> 16 | D17: Puneet to lead product and influencer engagement session | E17: Puneet
B18: =B17+1 -> 17 | D18: Channel Finance discussion - Kunal | E18: Kunal
B19: =B18+1 -> 18 | D19: Show nodal agency approvals and project progress - Dealer meet deck | E19: Tanvi, Mohit
B20: =B19+1 -> 19 | D20: Present branding plan | E20: Tanvi, Mohit
B21: =B20+1 -> 20 | D21: Present DGO strategy | E21: Mohit
B22: =B21+1 -> 21 | D22: Launch of One Helix Brand | E22: Mohit
B23: =B22+1 -> 22 | C23: Manpower alignment | D23: Manpower requirements were aligned in principle; Finance to come back with an accurate manpower costing | E23: Karan, Shreyas | F23: TBD
B24: =B23+1 -> 23 | C24: Vendor Management system | D24: Align vendors across One Helix and JSW One TMT; conduct best-practice meeting | E24: Somen, Tanvi | F24: TBD
B25: =B24+1 -> 24 | C25: Pipes and Tube Business | D25: Terminologies (in terms of distributor/channel performance KPIs, metrics) to be synced between P&T and TMT | E25: Deepak, Somen, Kunal | F25: Feb 2nd week

Sheet Sheet4
A2: FY 25-26 | E2: 45748 | F2: 45778 | G2: 45809 | H2: 45839 | I2: 45870 | J2: 45901 | K2: 45931 | L2: 45962 | M2: 45992 | N2: 46023 | O2: 46054 | P2: 46082 | Q2: Total
A4: Volume (in '000) | D4: 1000 | E4: 18.775 | F4: 19.409 | G4: 15.623 | H4: 18.857 | I4: 15.51 | J4: 11.637 | K4: 11.419 | L4: 18.13 | M4: 23.571 | N4: 24.402 | O4: 30 | P4: 35 | Q4: =(SUM(E4:P4)) -> 242.333
A5: Sales (in Cr) | D5: =10^7 -> 10000000 | E5: 106.14158 | F5: 108.11101 | G5: 82.482233 | H5: 90.88609 | I5: 73.704581 | J5: 55.811387 | K5: 53.346405 | L5: 82.912999 | M5: 110.14637 | N5: 121.09498 | O5: =(53000*O4*1000)/10000000 -> 159 | P5: =(52000*P4*1000)/10000000 -> 182 | Q5: =SUM(E5:P5) -> 1225.6376
A7: Margin PMT | E7: 2886 | F7: 2991 | G7: 1453 | H7: -963 | I7: -981 | J7: 93 | K7: -18 | L7: 686 | M7: 258 | N7: 1778.95 | O7: 2000 | P7: 1800 | Q7: =SUMPRODUCT(E7:P7,E4:P4)/SUM(E4:P4) -> 1185.8382
A9: Project
A10: Qty (in '000) | D10: 1000 | E10: 3.846 | F10: 5.211 | G10: 2.99 | H10: 4.793 | I10: 6.2 | J10: 3.393 | K10: 3.447 | L10: 4.738 | M10: 6.243 | N10: 7.990435 | O10: 11 | P10: 12.833333 | Q10: 72.684768
A11: CM/MT | E11: =E56 -> 2398 | F11: =F56 -> 3089 | G11: =G56 -> 1895 | H11: =H56 -> -1553 | I11: =I56 -> -1804 | J11: =J56 -> -349 | K11: =K56 -> -642 | L11: =L56 -> -215 | M11: =M56 -> -233 | N11: 551.37558 | O11: =N11 -> 551.37558 | P11: =N11 -> 551.37558 | Q11: =SUMPRODUCT(E11:P11,E10:P10)/SUM(E10:P10) -> 330.65575
A13: Retail
A14: Qty (in '000) | E14: =E4-E10 -> 14.929 | F14: =F4-F10 -> 14.198 | G14: =G4-G10 -> 12.633 | H14: =H4-H10 -> 14.064 | I14: =I4-I10 -> 9.31 | J14: =J4-J10 -> 8.244 | K14: =K4-K10 -> 7.972 | L14: =L4-L10 -> 13.392 | ... P14: =P4-P10 -> 22.166667 | Q14: =SUM(E14:P14) -> 169.64823
A15: CM/MT | E15: 3012 | F15: 2955 | G15: 1344 | H15: -757 | I15: -415 | J15: 277 | K15: 252 | L15: 1005 | M15: 436 | N15: 2376.6294 | O15: 2376.6294 | P15: 2376.6294 | Q15: 1482.7063
A17: FY 26-27 | E17: 46113 | F17: =EOMONTH(E17,0)+1 -> 46143 | G17: =EOMONTH(F17,0)+1 -> 46174 | H17: =EOMONTH(G17,0)+1 -> 46204 | I17: =EOMONTH(H17,0)+1 -> 46235 | J17: =EOMONTH(I17,0)+1 -> 46266 | K17: =EOMONTH(J17,0)+1 -> 46296 | L17: =EOMONTH(K17,0)+1 -> 46327 | M17: =EOMONTH(L17,0)+1 -> 46357 | ... P17: =EOMONTH(O17,0)+1 -> 46447 | Q17: Total
A18: ='P&L-month wise (One TMT)'!A3 -> Volume (in '000 MT)
A19: Retail
A20: 550D | E20: 9.725 | F20: 13.28 | G20: 11.58 | H20: 9.725 | I20: 8.135 | J20: 9.075 | K20: 11.58 | L20: 14.145 | M20: 15.07 | N20: 18.615 | O20: 21.17 | P20: 24.595 | Q20: 166.695
A21: 550 | E21: 9.519 | F21: 12.885 | G21: 11.006 | H21: 9.351 | I21: 7.256 | J21: 7.731 | K21: 8.3015 | L21: 8.6225 | M21: 6.9035 | N21: 7.247 | O21: 6.976 | P21: 5.651 | Q21: 101.4495
A22: Sub-Total | E22: =SUM(E20:E21) -> 19.244 | F22: =SUM(F20:F21) -> 26.165 | G22: =SUM(G20:G21) -> 22.586 | H22: =SUM(H20:H21) -> 19.076 | I22: =SUM(I20:I21) -> 15.391 | J22: =SUM(J20:J21) -> 16.806 | K22: =SUM(K20:K21) -> 19.8815 | L22: =SUM(L20:L21) -> 22.7675 | ... Q22: =SUM(Q20:Q21) -> 268.1445
A24: Project
A25: 550D | E25: 11.025 | F25: 12.94 | G25: 12.675 | H25: 10.195 | I25: 9.915 | J25: 10.045 | K25: 11.225 | L25: 12.755 | M25: 15.285 | N25: 18.3 | O25: 21.7 | P25: 25.325 | Q25: 171.385
A26: 550 | E26: 4.475 | F26: 4.91 | G26: 5.225 | H26: 5.055 | I26: 5.185 | J26: 5.855 | K26: 7.25 | L26: 8.095 | M26: 9.015 | N26: 10.1 | O26: 11.55 | P26: 13.075 | Q26: 89.79
A27: Sub-Total | E27: =SUM(E25:E26) -> 15.5 | F27: =SUM(F25:F26) -> 17.85 | G27: =SUM(G25:G26) -> 17.9 | H27: =SUM(H25:H26) -> 15.25 | I27: =SUM(I25:I26) -> 15.1 | J27: =SUM(J25:J26) -> 15.9 | K27: =SUM(K25:K26) -> 18.475 | L27: =SUM(L25:L26) -> 20.85 | ... Q27: =SUM(Q25:Q26) -> 261.175
A29: JSW One Qty | E29: =SUM(E25:E26,E20:E21) -> 34.744 | F29: =SUM(F25:F26,F20:F21) -> 44.015 | G29: =SUM(G25:G26,G20:G21) -> 40.486 | H29: =SUM(H25:H26,H20:H21) -> 34.326 | I29: =SUM(I25:I26,I20:I21) -> 30.491 | J29: =SUM(J25:J26,J20:J21) -> 32.706 | K29: =SUM(K25:K26,K20:K21) -> 38.3565 | L29: =SUM(L25:L26,L20:L21) -> 43.6175 | ... Q29: =SUM(Q25:Q26,Q20:Q21) -> 529.3195
A31: One Helix 550 | E31: 3.606 | F31: 4.935 | G31: 4.464 | H31: 3.774 | I31: 3.709 | J31: 4.344 | K31: 7.1685 | L31: 10.3825 | M31: 13.1765 | N31: 17.538 | O31: 21.254 | P31: 27.054 | Q31: 121.4055
A33: Overall Qty | E33: =SUM(E29,E31) -> 38.35 | F33: =SUM(F29,F31) -> 48.95 | G33: =SUM(G29,G31) -> 44.95 | H33: =SUM(H29,H31) -> 38.1 | I33: =SUM(I29,I31) -> 34.2 | J33: =SUM(J29,J31) -> 37.05 | K33: =SUM(K29,K31) -> 45.525 | L33: =SUM(L29,L31) -> 54 | ... Q33: =SUM(Q29,Q31) -> 650.725
A37: Retail- Margin
A38: =A20 -> 550D | D38: 1000 | E38: =E39-$D$38 -> 500 | F38: =F39-$D$38 -> 500 | G38: =G39-$D$38 -> 500 | H38: 150 | I38: 150 | J38: 150 | K38: =K39-$D$38 -> 500 | L38: =L39-$D$38 -> 500 | M38: =M39-$D$38 -> 750 | N38: =N39-$D$38 -> 1000 | O38: =O39-$D$38 -> 1250 | P38: =P39-$D$38 -> 1500 | Q38: =SUMPRODUCT(E38:P38,E20:P20)/Q20 -> 764.6765
A39: =A21 -> 550 | E39: 1500 | F39: 1500 | G39: 1500 | H39: 1000 | I39: 1000 | J39: 1000 | K39: 1500 | L39: 1500 | M39: 1750 | N39: 2000 | O39: 2250 | P39: 2500 | Q39: =SUMPRODUCT(E39:P39,E21:P21)/Q21 -> 1540.0532
A40: Total | E40: =((E38*E20)+(E39*E21))/E22 -> 994.64768 | F40: =((F38*F20)+(F39*F21))/F22 -> 992.45175 | G40: =((G38*G20)+(G39*G21))/G22 -> 987.29301 | H40: =((H38*H20)+(H39*H21))/H22 -> 566.66754 | I40: =((I38*I20)+(I39*I21))/I22 -> 550.7277 | J40: =((J38*J20)+(J39*J21))/J22 -> 541.01214 | K40: =((K38*K20)+(K39*K21))/K22 -> 917.54898 | L40: =((L38*L20)+(L39*L21))/L22 -> 878.71967 | ... Q40: =((Q38*Q20)+(Q39*Q21))/Q22 -> 1058.0317
A42: Project-Margin
A43: =A25 -> 550D | D43: 500 | E43: 100 | F43: 100 | G43: 100 | H43: 100 | I43: 100 | J43: 100 | K43: 100 | L43: 150 | M43: 200 | N43: 250 | O43: 300 | P43: 400 | Q43: =SUMPRODUCT(E43:P43,E25:P25)/Q25 -> 198.30936
A44: =A26 -> 550 | E44: =E39-$D$43 -> 1000 | F44: =F39-$D$43 -> 1000 | G44: =G39-$D$43 -> 1000 | H44: =H39-$D$43 -> 500 | I44: =I39-$D$43 -> 500 | J44: =J39-$D$43 -> 500 | K44: =K39-$D$43 -> 1000 | L44: =L39-$D$43 -> 1000 | ... P44: =P39-$D$43 -> 2000 | Q44: =SUMPRODUCT(E44:P44,E26:P26)/Q26 -> 1233.8094
A45: Total | E45: =((E43*E25)+(E44*E26))/E27 -> 359.83871 | F45: =((F43*F25)+(F44*F26))/F27 -> 347.56303 | G45: =((G43*G25)+(G44*G26))/G27 -> 362.7095 | H45: =((H43*H25)+(H44*H26))/H27 -> 232.59016 | I45: =((I43*I25)+(I44*I26))/I27 -> 237.35099 | J45: =((J43*J25)+(J44*J26))/J27 -> 247.2956 | K45: =((K43*K25)+(K44*K26))/K27 -> 453.17997 | L45: =((L43*L25)+(L44*L26))/L27 -> 480.01199 | ... Q45: =((Q43*Q25)+(Q44*Q26))/Q27 -> 554.3065
A47: JSW One margin | E47: =((E40*E22)+(E45*E27))/SUM(E22,E27) -> 711.44658 | F47: =((F40*F22)+(F45*F27))/SUM(F22,F27) -> 730.92128 | G47: =((G40*G22)+(G45*G27))/SUM(G22,G27) -> 711.14706 | H47: =((H40*H22)+(H45*H27))/SUM(H22,H27) -> 418.2471 | I47: =((I40*I22)+(I45*I27))/SUM(I22,I27) -> 395.53475 | J47: =((J40*J22)+(J45*J27))/SUM(J22,J27) -> 398.22204 | K47: =((K40*K22)+(K45*K27))/SUM(K22,K27) -> 693.87848 | L47: =((L40*L22)+(L45*L27))/SUM(L22,L27) -> 688.12976 | ... Q47: =((Q40*Q22)+(Q45*Q27))/SUM(Q22,Q27) -> 809.48534
A49: One Helix | D49: 750 | E49: =E39-$D$49 -> 750 | F49: =F39-$D$49 -> 750 | G49: 650 | H49: =H39-$D$49 -> 250 | I49: =I39-$D$49 -> 250 | J49: =J39-$D$49 -> 250 | K49: 400 | L49: 500 | M49: 700 | N49: 900 | O49: 900 | P49: 1150 | Q49: =SUMPRODUCT(E49:P49,E31:P31)/Q31 -> 787.20651
A51: Overall margin | E51: =((E47*E29)+(E49*E31))/E33 -> 715.07171 | F51: =((F47*F29)+(F49*F31))/F33 -> 732.84474 | G51: =((G47*G29)+(G49*G31))/G33 -> 705.07453 | H51: =((H47*H29)+(H49*H31))/H33 -> 401.58136 | I51: =((I47*I29)+(I49*I31))/I33 -> 379.75146 | J51: =((J47*J29)+(J49*J31))/J33 -> 380.84345 | K51: =((K47*K29)+(K49*K31))/K33 -> 647.60351 | L51: =((L47*L29)+(L49*L31))/L33 -> 651.95833 | ... Q51: =((Q47*Q29)+(Q49*Q31))/Q33 -> 805.32879
B54: FY25-26 | C54: Projects | D54: Unit | E54: April'25 | F54: May'25 | G54: June'25 | H54: July'25 | I54: Aug'25 | J54: Sep'25 | K54: Oct'25 | L54: Nov’25 | M54: Dec'25 | N54: Jan'26 | O54: Feb'26 | P54: Mar'26 | Q54: Overall
C55: Sales quantity | D55: MT (in '000) | E55: =E10 -> 3.846 | F55: =F10 -> 5.211 | G55: =G10 -> 2.99 | H55: =H10 -> 4.793 | I55: =I10 -> 6.2 | J55: =J10 -> 3.393 | K55: =K10 -> 3.447 | L55: =L10 -> 4.738 | ... Q55: =Q10 -> 72.684768
C56: CM/MT | D56: INR | E56: 2398 | F56: 3089 | G56: 1895 | H56: -1553 | I56: -1804 | J56: -349 | K56: -642 | L56: -215 | M56: -233 | N56: =N11 -> 551.37558 | O56: =O11 -> 551.37558 | P56: =P11 -> 551.37558 | Q56: =Q11 -> 330.65575
C59: Retail | D59: Metric | E59: April'25 | F59: May'25 | G59: June'25 | H59: July'25 | I59: Aug'25 | J59: Sep'25 | K59: Oct'25 | L59: Nov’25 | M59: Dec'25 | N59: Jan'26 | O59: Feb'26 | P59: Mar'26 | Q59: Overall
C60: Sales quantity | D60: MT (in '000) | E60: =E14 -> 14.929 | F60: =F14 -> 14.198 | G60: =G14 -> 12.633 | H60: =H14 -> 14.064 | I60: =I14 -> 9.31 | J60: =J14 -> 8.244 | K60: =K14 -> 7.972 | L60: =L14 -> 13.392 | ... P60: =P14 -> 22.166667 | Q60: 169.64823
C61: CM/MT | D61: INR | E61: =E15 -> 3012 | F61: =F15 -> 2955 | G61: =G15 -> 1344 | H61: =H15 -> -757 | I61: =I15 -> -415 | J61: =J15 -> 277 | K61: =K15 -> 252 | L61: =L15 -> 1005 | ... Q61: =Q15 -> 1482.7063
...

Sheet Jan Actuals-P&L-Output
A1: Project/retail | B1: (All)
A2: Grade | B2: (All)
B4: CM Name 2
A5: Values | B5: Aditya | C5: AIC | D5: Amba Shakti | E5: Amba Shakti Udyog | F5: API | G5: German Steel | H5: Real Ispat | I5: SKA | J5: Grand Total | K5: 30th jan
A6: Quantity | B6: 1372.31 | C6: 781.06 | D6: 8521.71 | E6: 4848.6 | F6: 2110.075 | G6: 143.7 | H6: 1847.63 | I6: 4897.21 | J6: 24522.295
A7: Sales incl. freight | B7: 72910820 | C7: 40532696 | D7: 4.4995443e+08 | E7: 250196486 | F7: 1.0517513e+08 | G7: 7433269 | H7: 92475554 | I7: 2.4499577e+08 | J7: 1.2636742e+09 | K7: 51531.643
A8: Purchase price ex-works | B8: 63492030 | C8: 34059605 | D8: 3.9654529e+08 | E8: 2.2913632e+08 | F8: 85640427 | G8: 6441566 | H8: 83622115 | I8: 2.1117413e+08 | J8: 1.1101115e+09 | K8: 45269.477
A9: Price Difference-Purchase | B9: 882316.74 | C9: 795876.74 | D9: 13238614 | E9: 7297997 | F9: 1632902.1 | G9: 84052.86 | H9: 3144166.1 | I9: 6196892.3 | J9: 33272817 | K9: 1356.8395
A10: 3PL cost (actual/estimated as per JOTS team) | B10: 2155254.5 | C10: 1528126.2 | D10: 13323373 | E10: 8277810.9 | F10: 5345181.9 | G10: 215550 | H10: 4736534.9 | I10: 9324396.5 | J10: 44906228 | K10: 1831.2408 | L10: =K7-K8-K9-K10 -> 3074.0856
A11: Gross margin | B11: 6381217.8 | C11: 4149088.3 | D11: 26839073 | E11: 5484360.6 | F11: 6942914.6 | G11: 692100.14 | H11: 1065735.3 | I11: 17186193 | J11: 68740683 | K11: 2803.1913
A12: MOU | B12: 745248 | C12: 386316 | D12: 4480908 | E12: 1302762 | F12: 943980 | G12: 45702 | H12: 309900 | I12: 1704300 | J12: 9919116 | K12: 404.49379
A13: SFDC | B13: 62104 | C13: 32193 | D13: 373409 | E13: 108563.5 | F13: 78665 | G13: 3808.5 | H13: 25825 | I13: 142025 | J13: 826593 | K13: 33.707816
A14: Price difference-Sales | B14: 0 | C14: 0 | D14: 0 | E14: 0 | F14: 0 | G14: 0 | H14: 0 | I14: 0 | J14: 0 | K14: 0
A15: Service charges | B15: 748628.69 | C15: 426087.35 | D15: 4648801.4 | E15: 2645030 | F15: 1151097.6 | G15: 78391.867 | H15: 1007927.4 | I15: 2671547.9 | J15: 13377512 | K15: 545.52448
A16: Price support | K16: 0
A17: QD from CM | B17: 0 | C17: 0 | D17: 2982598.5 | E17: 1697010 | F17: 0 | G17: 0 | H17: 0 | I17: 1469163 | J17: 6148771.5 | K17: 250.74209
A18: Contribution margin | B18: 4825237.1 | C18: 3304492 | D18: 14353356 | E18: -269004.88 | F18: 4769172.1 | G18: 564197.77 | H18: -277917.1 | I18: 11199157 | J18: 38468690 | K18: =J18/J6 -> 1568.7231
A24: Project/retail | B24: Retail
A25: Grade | B25: (All)
B27: CM Name 2
A28: Values | B28: Aditya | C28: AIC | D28: Amba Shakti | E28: Amba Shakti Udyog | F28: API | G28: German Steel | H28: Real Ispat | I28: SKA | J28: Grand Total
A29: Quantity | B29: 1242.08 | C29: 643.86 | D29: 7468.18 | E29: 2171.27 | F29: 1573.3 | G29: 76.17 | H29: 516.5 | I29: 2840.5 | J29: 16531.86
A30: Sales incl. freight | B30: 65792146 | C30: 33246604 | D30: 3.9454903e+08 | E30: 1.1648246e+08 | F30: 79166330 | G30: 3917943 | H30: 26997568 | I30: 1.439419e+08 | J30: 8.6409399e+08 | K30: 52268.407
A31: Purchase price ex-works | B31: 57378603 | C31: 27922731 | D31: 3.4748121e+08 | E31: 103245970 | F31: 67626255 | G31: 3362652 | H31: 23130306 | I31: 1.2226357e+08 | J31: 7.5241129e+08 | K31: 45512.803
A32: Price Difference-Purchase | B32: 810704.31 | C32: 678707.94 | D32: 11677509 | E32: 3356546.1 | F32: 1193145.4 | G32: 65369.4 | H32: 976163.56 | I32: 3772619.3 | J32: 22530765 | K32: 1362.8693
A33: 3PL cost (actual/estimated as per JOTS team) | B33: 1959909.5 | C33: 1279530.8 | D33: 11671189 | E33: 3784411.8 | F33: 4288494.6 | G33: 114255 | H33: 1464286.1 | I33: 6305653 | J33: 30867730 | K33: 1867.1662
A34: Gross margin | B34: 5642929.7 | C34: 3365634 | D34: 23719121 | E34: 6095534.6 | F34: 6001054.7 | G34: 375666.6 | H34: 1420709.1 | I34: 11432510 | J34: 58053160 | K34: 3511.5928
A35: MOU | B35: 745248 | C35: 386316 | D35: 4480908 | E35: 1302762 | F35: 943980 | G35: 45702 | H35: 309900 | I35: 1704300 | J35: 9919116 | K35: 600
A36: SFDC | B36: 62104 | C36: 32193 | D36: 373409 | E36: 108563.5 | F36: 78665 | G36: 3808.5 | H36: 25825 | I36: 142025 | J36: 826593 | K36: 50
A37: Price difference-Sales | B37: 0 | C37: 0 | D37: 0 | E37: 0 | F37: 0 | G37: 0 | H37: 0 | I37: 0 | J37: 0 | K37: 0
A38: Service charges | B38: 677585.04 | C38: 351241.39 | D38: 4074075 | E38: 1184480.9 | F38: 858273.66 | G38: 41552.599 | H38: 281763.39 | I38: 1549562.3 | J38: 9018534.3 | K38: 545.52448
A39: Price support | K39: 0
A40: QD from CM | B40: 0 | C40: 0 | D40: 2613863 | E40: 759944.5 | F40: 0 | G40: 0 | H40: 0 | I40: 852150 | J40: 4225957.5 | K40: 255.62505
A41: Contribution margin | B41: 4157992.7 | C41: 2595883.6 | D41: 12176866 | E41: 2739783.7 | F41: 4120136.1 | G41: 284603.5 | H41: 803220.75 | I41: 7184473.1 | J41: 34062960 | K41: =J41/J29 -> 2060.4433
A45: Project/retail | B45: Retail
A46: Grade | B46: 550
B48: CM Name 2
A49: Values | B49: Aditya | C49: AIC | D49: Amba Shakti | E49: Amba Shakti Udyog | F49: API | G49: SKA | H49: Grand Total
A50: Quantity | B50: 1206.49 | C50: 643.86 | D50: 7468.18 | E50: 39.8 | F50: 1481.79 | G50: 2830.82 | H50: 13670.94
A51: Sales incl. freight | B51: 63866728 | C51: 33246604 | D51: 3.9454903e+08 | E51: 1942240 | F51: 74454155 | G51: 1.4345645e+08 | H51: 7.1151521e+08 | I51: 52045.815
...

Sheet P&L-month wise (One TMT)
A2: Particulars | B2: =Summary!B3 -> 46113 | C2: =Summary!C3 -> 46143 | D2: =Summary!D3 -> 46174 | E2: =Summary!E3 -> 46204 | F2: =Summary!F3 -> 46235 | G2: =Summary!G3 -> 46266 | H2: =Summary!H3 -> 46296 | I2: =Summary!I3 -> 46327 | ... N2: =Summary!N3 -> Total
A3: Volume (in '000 MT)
A4: =Summary!A17 -> JSW One TMT (Fe550D) | B4: =Summary!B17 -> 20.61 | C4: =Summary!C17 -> 26.105 | D4: =Summary!D17 -> 24.11 | E4: =Summary!E17 -> 19.78 | F4: =Summary!F17 -> 17.885 | G4: =Summary!G17 -> 18.975 | H4: =Summary!H17 -> 22.66 | ... M4: =Summary!M17 -> 49.48 | N4: =SUM(B4:M4) -> 335.365
A5: =Summary!A18 -> JSW One TMT (Fe550) | B5: =Summary!B18 -> 13.849 | C5: =Summary!C18 -> 17.401 | D5: =Summary!D18 -> 15.988 | E5: =Summary!E18 -> 14.169 | F5: =Summary!F18 -> 12.408 | G5: =Summary!G18 -> 13.4325 | H5: =Summary!H18 -> 15.339 | ... M5: =Summary!M18 -> 16.166 | N5: =SUM(B5:M5) -> 182.337
A6: Total | B6: =B4+B5 -> 34.459 | C6: =C4+C5 -> 43.506 | D6: =D4+D5 -> 40.098 | E6: =E4+E5 -> 33.949 | F6: =F4+F5 -> 30.293 | G6: =G4+G5 -> 32.4075 | H6: =H4+H5 -> 37.999 | I6: =I4+I5 -> 42.9565 | ... M6: =M4+M5 -> 65.646 | N6: =SUM(B6:M6) -> 517.702
A8: Retail | B8: =Summary!B24+Summary!B25 -> 18.959 | C8: =Summary!C24+Summary!C25 -> 25.656 | D8: =Summary!D24+Summary!D25 -> 22.198 | E8: =Summary!E24+Summary!E25 -> 18.699 | F8: =Summary!F24+Summary!F25 -> 15.193 | G8: =Summary!G24+Summary!G25 -> 16.5075 | H8: =Summary!H24+Summary!H25 -> 19.524 | I8: =Summary!I24+Summary!I25 -> 22.1065 | ... M8: =Summary!M24+Summary!M25 -> 27.246 | N8: =SUM(B8:M8) -> 256.527
A9: Projects-PB | B9: =B6-B8-B10 -> 11.9 | C9: =C6-C8-C10 -> 13.6 | D9: =D6-D8-D10 -> 13.2 | E9: =E6-E8-E10 -> 10.3 | F9: =F6-F8-F10 -> 9.4 | G9: =G6-G8-G10 -> 9 | H9: =H6-H8-H10 -> 10.7 | I9: =I6-I8-I10 -> 12.5 | ... M9: =M6-M8-M10 -> 27.7 | N9: =(SUM(B9:M9)) -> 175.5
A10: Projects-Distributor | B10: =(Distributor_projects!I3)/1000 -> 3.6 | C10: =(Distributor_projects!J3)/1000 -> 4.25 | D10: =(Distributor_projects!K3)/1000 -> 4.7 | E10: =(Distributor_projects!L3)/1000 -> 4.95 | F10: =(Distributor_projects!M3)/1000 -> 5.7 | G10: =(Distributor_projects!N3)/1000 -> 6.9 | H10: =(Distributor_projects!O3)/1000 -> 7.775 | I10: =(Distributor_projects!P3)/1000 -> 8.35 | ... M10: =(Distributor_projects!T3)/1000 -> 10.7 | N10: =(SUM(B10:M10)) -> 85.675
A11: Total | B11: =SUM(B8:B10) -> 34.459 | C11: =SUM(C8:C10) -> 43.506 | D11: =SUM(D8:D10) -> 40.098 | E11: =SUM(E8:E10) -> 33.949 | F11: =SUM(F8:F10) -> 30.293 | G11: =SUM(G8:G10) -> 32.4075 | H11: =SUM(H8:H10) -> 37.999 | I11: =SUM(I8:I10) -> 42.9565 | ... N11: =SUM(N8:N10) -> 517.702
A13: GM | B13: ='Wt average prices'!E46 -> 1692.6012 | C13: ='Wt average prices'!F46 -> 1752.2224 | D13: ='Wt average prices'!G46 -> 1179.3977 | E13: ='Wt average prices'!H46 -> 530.95335 | F13: ='Wt average prices'!I46 -> -356.79175 | G13: ='Wt average prices'!J46 -> 553.51293 | H13: ='Wt average prices'!K46 -> 2612.8332 | I13: ='Wt average prices'!L46 -> 2569.5425 | ... N13: ='Wt average prices'!Q46 -> 1309.0396
A14: Less: MOU | B14: ='MOu calculation'!B10 -> 330.11405 | C14: ='MOu calculation'!C10 -> 353.82706 | D14: ='MOu calculation'!D10 -> 332.15622 | E14: ='MOu calculation'!E10 -> 330.47807 | F14: ='MOu calculation'!F10 -> 300.921 | G14: ='MOu calculation'!G10 -> 305.6237 | H14: ='MOu calculation'!H10 -> 308.2818 | I14: ='MOu calculation'!I10 -> 308.77516 | ... N14: ='MOu calculation'!N10 -> 297.30656
A15: Less: Project Management Fees | B15: ='MOu calculation'!B14 -> 500 | C15: ='MOu calculation'!C14 -> 500 | D15: ='MOu calculation'!D14 -> 500 | E15: ='MOu calculation'!E14 -> 500 | F15: ='MOu calculation'!F14 -> 500 | G15: ='MOu calculation'!G14 -> 500 | H15: ='MOu calculation'!H14 -> 500 | I15: ='MOu calculation'!I14 -> 500 | ... N15: ='MOu calculation'!N14 -> 500
A16: Add: QD from CM | B16: =_xlfn.XLOOKUP(B2,'QD from CM'!$F$50:$R$50,'QD from CM'!$F$64:$R$64,"Not found",0) -> 171.91808 | C16: =_xlfn.XLOOKUP(C2,'QD from CM'!$F$50:$R$50,'QD from CM'!$F$64:$R$64,"Not found",0) -> 174.32165 | D16: =_xlfn.XLOOKUP(D2,'QD from CM'!$F$50:$R$50,'QD from CM'!$F$64:$R$64,"Not found",0) -> 177.21824 | E16: =_xlfn.XLOOKUP(E2,'QD from CM'!$F$50:$R$50,'QD from CM'!$F$64:$R$64,"Not found",0) -> 166.92397 | F16: =_xlfn.XLOOKUP(F2,'QD from CM'!$F$50:$R$50,'QD from CM'!$F$64:$R$64,"Not found",0) -> 159.26783 | G16: =_xlfn.XLOOKUP(G2,'QD from CM'!$F$50:$R$50,'QD from CM'!$F$64:$R$64,"Not found",0) -> 167.8372 | H16: =_xlfn.XLOOKUP(H2,'QD from CM'!$F$50:$R$50,'QD from CM'!$F$64:$R$64,"Not found",0) -> 175.18044 | I16: =_xlfn.XLOOKUP(I2,'QD from CM'!$F$50:$R$50,'QD from CM'!$F$64:$R$64,"Not found",0) -> 175.7855 | ... N16: =_xlfn.XLOOKUP(N2,'QD from CM'!$F$50:$R$50,'QD from CM'!$F$64:$R$64,"Not found",0) -> 179.72822
A17: CM1 | B17: =B13-B14-B15+B16 -> 1034.4052 | C17: =C13-C14-C15+C16 -> 1072.717 | D17: =D13-D14-D15+D16 -> 524.45968 | E17: =E13-E14-E15+E16 -> -132.60075 | F17: =F13-F14-F15+F16 -> -998.44492 | G17: =G13-G14-G15+G16 -> -84.273572 | H17: =H13-H14-H15+H16 -> 1979.7318 | I17: =I13-I14-I15+I16 -> 1936.5528 | ... N17: =N13-N14-N15+N16 -> 691.46123 | O17: =N17*N11*1000 -> 3.5797086e+08
A28: Marketing cost
A30: Manpower cost
A31: ESOP
A32: Others
A34: Admin cost
A35: Rent
A36: Travel
A37: Others
A39: Interest on Working Capital
A41: CM2

Sheet MOu calculation
A1: ='P&L-month wise (One TMT)'!A14 -> Less: MOU | B1: ='P&L-month wise (One TMT)'!B2 -> 46113 | C1: ='P&L-month wise (One TMT)'!C2 -> 46143 | D1: ='P&L-month wise (One TMT)'!D2 -> 46174 | E1: ='P&L-month wise (One TMT)'!E2 -> 46204 | F1: ='P&L-month wise (One TMT)'!F2 -> 46235 | G1: ='P&L-month wise (One TMT)'!G2 -> 46266 | H1: ='P&L-month wise (One TMT)'!H2 -> 46296 | I1: ='P&L-month wise (One TMT)'!I2 -> 46327 | ... N1: ='P&L-month wise (One TMT)'!N2 -> Total
A2: ='P&L-month wise (One TMT)'!A8 -> Retail | B2: ='P&L-month wise (One TMT)'!B8 -> 18.959 | C2: ='P&L-month wise (One TMT)'!C8 -> 25.656 | D2: ='P&L-month wise (One TMT)'!D8 -> 22.198 | E2: ='P&L-month wise (One TMT)'!E8 -> 18.699 | F2: ='P&L-month wise (One TMT)'!F8 -> 15.193 | G2: ='P&L-month wise (One TMT)'!G8 -> 16.5075 | H2: ='P&L-month wise (One TMT)'!H8 -> 19.524 | ... N2: ='P&L-month wise (One TMT)'!N8 -> 256.527
A3: ='P&L-month wise (One TMT)'!A9 -> Projects-PB | B3: ='P&L-month wise (One TMT)'!B9 -> 11.9 | C3: ='P&L-month wise (One TMT)'!C9 -> 13.6 | D3: ='P&L-month wise (One TMT)'!D9 -> 13.2 | E3: ='P&L-month wise (One TMT)'!E9 -> 10.3 | F3: ='P&L-month wise (One TMT)'!F9 -> 9.4 | G3: ='P&L-month wise (One TMT)'!G9 -> 9 | H3: ='P&L-month wise (One TMT)'!H9 -> 10.7 | ... N3: ='P&L-month wise (One TMT)'!N9 -> 175.5
A4: ='P&L-month wise (One TMT)'!A10 -> Projects-Distributor | B4: ='P&L-month wise (One TMT)'!B10 -> 3.6 | C4: ='P&L-month wise (One TMT)'!C10 -> 4.25 | D4: ='P&L-month wise (One TMT)'!D10 -> 4.7 | E4: ='P&L-month wise (One TMT)'!E10 -> 4.95 | F4: ='P&L-month wise (One TMT)'!F10 -> 5.7 | G4: ='P&L-month wise (One TMT)'!G10 -> 6.9 | H4: ='P&L-month wise (One TMT)'!H10 -> 7.775 | ... N4: ='P&L-month wise (One TMT)'!N10 -> 85.675
A5: ='P&L-month wise (One TMT)'!A11 -> Total | B5: ='P&L-month wise (One TMT)'!B11 -> 34.459 | C5: ='P&L-month wise (One TMT)'!C11 -> 43.506 | D5: ='P&L-month wise (One TMT)'!D11 -> 40.098 | E5: ='P&L-month wise (One TMT)'!E11 -> 33.949 | F5: ='P&L-month wise (One TMT)'!F11 -> 30.293 | G5: ='P&L-month wise (One TMT)'!G11 -> 32.4075 | H5: ='P&L-month wise (One TMT)'!H11 -> 37.999 | ... N5: ='P&L-month wise (One TMT)'!N11 -> 517.702
A7: MOU PMT | B7: 600 | C7: 600 | D7: 600 | E7: 600 | F7: 600 | G7: 600 | H7: 600 | I7: 600 | J7: 600 | K7: 600 | L7: 600 | M7: 600 | N7: 600
A8: Retail | B8: =B2 -> 18.959 | C8: =C2 -> 25.656 | D8: =D2 -> 22.198 | E8: =E2 -> 18.699 | F8: =F2 -> 15.193 | G8: =G2 -> 16.5075 | H8: =H2 -> 19.524 | I8: =I2 -> 22.1065 | ... N8: =N2 -> 256.527
A10: Average MOU PMT | B10: =(B7*B8)/B5 -> 330.11405 | C10: =(C7*C8)/C5 -> 353.82706 | D10: =(D7*D8)/D5 -> 332.15622 | E10: =(E7*E8)/E5 -> 330.47807 | F10: =(F7*F8)/F5 -> 300.921 | G10: =(G7*G8)/G5 -> 305.6237 | H10: =(H7*H8)/H5 -> 308.2818 | I10: =(I7*I8)/I5 -> 308.77516 | ... N10: =(N7*N8)/N5 -> 297.30656
A13: ='P&L-month wise (One TMT)'!A15 -> Less: Project Management Fees | B13: =B1 -> 46113 | C13: =C1 -> 46143 | D13: =D1 -> 46174 | E13: =E1 -> 46204 | F13: =F1 -> 46235 | G13: =G1 -> 46266 | H13: =H1 -> 46296 | I13: =I1 -> 46327 | ... N13: =N1 -> Total
A14: PMT | B14: 500 | C14: 500 | D14: 500 | E14: 500 | F14: 500 | G14: 500 | H14: 500 | I14: 500 | J14: 500 | K14: 500 | L14: 500 | M14: 500 | N14: 500

Sheet Steelmint prices for last 36m
A1: Grade | B1: CM | C1: BIS | D1: Loading | E1: Price
A2: 550 | B2: AIC IRON INDUSTRIES PRIVATE LIMITED | C2: 2700 | D2: 270 | E2: =SUM(C2:D2) -> 2970
A3: 550 | B3: Aditya Industries | C3: 400 | D3: 250 | E3: =SUM(C3:D3) -> 650
A4: 550 | B4: Ambashakti Industries Limited | C4: 1200 | D4: 200 | E4: =SUM(C4:D4) -> 1400
A5: 550 | B5: AMBASHAKTI UDYOG LIMITED- GWALIOR | C5: 1200 | D5: 200 | E5: =SUM(C5:D5) -> 1400
A6: 550 | B6: API Ispat And Powertech Private Limited | C6: 2150 | D6: 265 | E6: =SUM(C6:D6) -> 2415
A7: 550 | B7: GERMAN GREEN STEEL AND POWER LIMITED | C7: 0 | D7: 200 | E7: =SUM(C7:D7) -> 200
A8: 550 | B8: SKA Ispat Private Limited | C8: 1800 | D8: 275 | E8: =SUM(C8:D8) -> 2075
A9: 550 | B9: Real Ispat | C9: 0 | D9: 0 | E9: =SUM(C9:D9) -> 0
A10: 550 | B10: Rashmi Steel | C10: =C$6 -> 2150 | D10: =D$6 -> 265 | E10: =SUM(C10:D10) -> 2415
A11: 550 | B11: Telangana - New Plant | C11: =C$6 -> 2150 | D11: =D$6 -> 265 | E11: =SUM(C11:D11) -> 2415
A12: 550 | B12: Maharashtra - New Plant | C12: =C$6 -> 2150 | D12: =D$6 -> 265 | E12: =SUM(C12:D12) -> 2415
A14: 550D | B14: =B2 -> AIC IRON INDUSTRIES PRIVATE LIMITED | C14: 3500 | D14: 270 | E14: =SUM(C14:D14) -> 3770
A15: 550D | B15: =B3 -> Aditya Industries | C15: 1200 | D15: 250 | E15: =SUM(C15:D15) -> 1450
A16: 550D | B16: =B4 -> Ambashakti Industries Limited | C16: 2200 | D16: 200 | E16: =SUM(C16:D16) -> 2400
A17: 550D | B17: =B5 -> AMBASHAKTI UDYOG LIMITED- GWALIOR | C17: 3200 | D17: 200 | E17: =SUM(C17:D17) -> 3400
A18: 550D | B18: =B6 -> API Ispat And Powertech Private Limited | C18: 3400 | D18: 265 | E18: =SUM(C18:D18) -> 3665
A19: 550D | B19: =B7 -> GERMAN GREEN STEEL AND POWER LIMITED | C19: 1000 | D19: 200 | E19: =SUM(C19:D19) -> 1200
A20: 550D | B20: =B8 -> SKA Ispat Private Limited | C20: 2800 | D20: 275 | E20: =SUM(C20:D20) -> 3075
A21: 550D | B21: =B9 -> Real Ispat | C21: 4500 | D21: 0 | E21: =SUM(C21:D21) -> 4500
A22: 550D | B22: =B10 -> Rashmi Steel | C22: =C$18 -> 3400 | D22: =D$18 -> 265 | E22: =SUM(C22:D22) -> 3665
A23: 550D | B23: =B11 -> Telangana - New Plant | C23: =C$18 -> 3400 | D23: =D$18 -> 265 | E23: =SUM(C23:D23) -> 3665
A24: 550D | B24: =B12 -> Maharashtra - New Plant | C24: =C$18 -> 3400 | D24: =D$18 -> 265 | E24: =SUM(C24:D24) -> 3665
A27: Loading charges
A28: BIS charges
A29: Month | B29: Delhi/NCR | C29: Mumbai | D29: Ahmedabad | E29: Mandi Gobindgarh | F29: Raipur | G29: Hyderabad | H29: Jaipur | I29: Muzaffarnagar | J29: Rourkela | K29: Patna | L29: Durgapur | M29: Hyderabad | N29: Mumbai
A30: 44927 | B30: 55332 | C30: 57116 | D30: 55917 | E30: 54444 | F30: 51764 | G30: 53640 | H30: 55016 | I30: 53688 | J30: 51416 | K30: 52864 | L30: 51684 | M30: 53640 | N30: 57116
A31: 44958 | B31: 53392 | C31: 56917 | D31: 54363 | E31: 53383 | F31: 50621 | G31: 53538 | H31: 53571 | I31: 51567 | J31: 50325 | K31: 51746 | L31: 50171 | M31: 45418 | N31: 48700
A32: 44986 | B32: 52668 | C32: 55933 | D32: 53088 | E32: 53744 | F32: 50280 | G32: 53424 | H32: 52900 | I32: 51736 | J32: 50192 | K32: 52048 | L32: 50658 | M32: 44084.615 | N32: 47074.074
A33: 45017 | B33: 52452 | C33: 54880 | D33: 53652 | E33: 53312 | F33: 50264 | G33: 53428 | H33: 52924 | I33: 51208 | J33: 50320 | K33: 52164 | L33: 50872 | M33: 45320 | N33: 49228.571
A34: 45047 | B34: 51519 | C34: 53326 | D34: 51763 | E34: 52215 | F34: 47793 | G34: 50870 | H34: 51352 | I34: 50411 | J34: 48181 | K34: 49926 | L34: 48033 | M34: 53537.5 | N34: 56916.667
A35: 45078 | B35: 51015 | C35: 50796 | D35: 50946 | E35: 52158 | F35: 47215 | G35: 48577 | H35: 50804 | I35: 50069 | J35: 47065 | K35: 48546 | L35: 46988 | M35: 44772 | N35: 48240
A36: 45108 | B36: 48396 | C36: 46969 | D36: 47708 | E36: 49835 | F36: 43969 | G36: 46308 | H36: 47812 | I36: 47777 | J36: 44408 | K36: 45912 | L36: 44127 | M36: 44708.333 | N36: 47945.833
A37: 45139 | B37: 48576 | C37: 48860 | D37: 49020 | E37: 50444 | F37: 45616 | G37: 47732 | H37: 48820 | I37: 47876 | J37: 45984 | K37: 46916 | L37: 45404 | M37: 53424 | N37: 55933.333
A38: 45170 | B38: 50477 | C38: 51988 | D38: 51312 | E38: 51558 | F38: 47365 | G38: 51260 | H38: 50204 | I38: 49788 | J38: 48050 | K38: 48596 | L38: 47250 | M38: 46089.583 | N38: 49250
A39: 45200 | B39: 48190 | C39: 50800 | D39: 49613 | E39: 49638 | F39: 45904 | G39: 49656 | H39: 47854 | I39: 47296 | J39: 45870 | K39: 46758 | L39: 45391 | M39: 46425 | N39: 49358.333
A40: 45231 | B40: 46992 | C40: 49044 | D40: 48239 | E40: 48340 | F40: 44276 | G40: 47500 | H40: 46700 | I40: 46060 | J40: 44248 | K40: 45757 | L40: 44036 | M40: 53428 | N40: 54880
A41: 45261 | B41: 46604 | C41: 48748 | D41: 47900 | E41: 47860 | F41: 43520 | G41: 46740 | H41: 46080 | I41: 45844 | J41: 43548 | K41: 44800 | L41: 43388 | M41: 48511.538 | N41: 50542.308
... A66: 46023 | B66: 47364 | C66: 49229 | D66: 49471 | E66: 48045 | F66: 43773 | G66: 45320 | H66: 46086 | I66: 46600 | J66: 43350 | K66: 47068 | L66: 42839 | M66: 41861.538 | N66: 44965.385
A67: 46054 | B67: =AVERAGE(B31,B43,B55) -> 48629.333 | C67: =AVERAGE(C31,C43,C55) -> 51034.333 | D67: =AVERAGE(D31,D43,D55) -> 49680 | E67: =AVERAGE(E31,E43,E55) -> 49142.333 | F67: =AVERAGE(F31,F43,F55) -> 45303 | G67: =AVERAGE(G31,G43,G55) -> 47672.667 | H67: =AVERAGE(H31,H43,H55) -> 47973 | I67: =AVERAGE(I31,I43,I55) -> 47379 | ... L67: =AVERAGE(L31,L43,L55) -> 45317.333
...

Sheet Plant wise prices
A1: Base Prices
A2: Grade | B2: CM | C2: Loading+BIS | D2: City for Steelmint pricing | E2: 46113 | F2: 46143 | G2: 46174 | H2: 46204 | I2: 46235 | J2: 46266 | K2: 46296 | L2: 46327 | M2: 46357 | N2: 46388 | O2: 46419 | P2: 46447
A3: 550 | B3: AIC IRON INDUSTRIES PRIVATE LIMITED | C3: 2970 | D3: ='Steelmint prices for last 36m'!L29 -> Durgapur | E3: =INDEX('Steelmint prices for last 36m'!$A$29:$N$80,MATCH('Plant wise prices'!E$2,'Steelmint prices for last 36m'!$A$29:$A$80,0),MATCH('Plant wise prices'!$D3,'Steelmint prices for last 36m'!$A$29:$N$29,0)) -> 47844.333 | F3: =INDEX('Steelmint prices for last 36m'!$A$29:$N$80,MATCH('Plant wise prices'!F$2,'Steelmint prices for last 36m'!$A$29:$A$80,0),MATCH('Plant wise prices'!$D3,'Steelmint prices for last 36m'!$A$29:$N$29,0)) -> 46166.667 | G3: =INDEX('Steelmint prices for last 36m'!$A$29:$N$80,MATCH('Plant wise prices'!G$2,'Steelmint prices for last 36m'!$A$29:$A$80,0),MATCH('Plant wise prices'!$D3,'Steelmint prices for last 36m'!$A$29:$N$29,0)) -> 44392 | H3: =INDEX('Steelmint prices for last 36m'!$A$29:$N$80,MATCH('Plant wise prices'!H$2,'Steelmint prices for last 36m'!$A$29:$A$80,0),MATCH('Plant wise prices'!$D3,'Steelmint prices for last 36m'!$A$29:$N$29,0)) -> 42156 | I3: =INDEX('Steelmint prices for last 36m'!$A$29:$N$80,MATCH('Plant wise prices'!I$2,'Steelmint prices for last 36m'!$A$29:$A$80,0),MATCH('Plant wise prices'!$D3,'Steelmint prices for last 36m'!$A$29:$N$29,0)) -> 42114.333 | J3: =INDEX('Steelmint prices for last 36m'!$A$29:$N$80,MATCH('Plant wise prices'!J$2,'Steelmint prices for last 36m'!$A$29:$A$80,0),MATCH('Plant wise prices'!$D3,'Steelmint prices for last 36m'!$A$29:$N$29,0)) -> 42390 | K3: =INDEX('Steelmint prices for last 36m'!$A$29:$N$80,MATCH('Plant wise prices'!K$2,'Steelmint prices for last 36m'!$A$29:$A$80,0),MATCH('Plant wise prices'!$D3,'Steelmint prices for last 36m'!$A$29:$N$29,0)) -> 42379 | L3: =INDEX('Steelmint prices for last 36m'!$A$29:$N$80,MATCH('Plant wise prices'!L$2,'Steelmint prices for last 36m'!$A$29:$A$80,0),MATCH('Plant wise prices'!$D3,'Steelmint prices for last 36m'!$A$29:$N$29,0)) -> 41367.667 | ... P3: =INDEX('Steelmint prices for last 36m'!$A$29:$N$80,MATCH('Plant wise prices'!P$2,'Steelmint prices for last 36m'!$A$29:$A$80,0),MATCH('Plant wise prices'!$D3,'Steelmint prices for last 36m'!$A$29:$N$29,0)) -> 44539.778
A4: 550 | B4: Aditya Industries | C4: 650 | D4: ='Steelmint prices for last 36m'!E29 -> Mandi Gobindgarh | E4: =INDEX('Steelmint prices for last 36m'!$A$29:$N$80,MATCH('Plant wise prices'!E$2,'Steelmint prices for last 36m'!$A$29:$A$80,0),MATCH('Plant wise prices'!$D4,'Steelmint prices for last 36m'!$A$29:$N$29,0)) -> 50924.333 | F4: =INDEX('Steelmint prices for last 36m'!$A$29:$N$80,MATCH('Plant wise prices'!F$2,'Steelmint prices for last 36m'!$A$29:$A$80,0),MATCH('Plant wise prices'!$D4,'Steelmint prices for last 36m'!$A$29:$N$29,0)) -> 50534.667 | G4: =INDEX('Steelmint prices for last 36m'!$A$29:$N$80,MATCH('Plant wise prices'!G$2,'Steelmint prices for last 36m'!$A$29:$A$80,0),MATCH('Plant wise prices'!$D4,'Steelmint prices for last 36m'!$A$29:$N$29,0)) -> 49712.333 | H4: =INDEX('Steelmint prices for last 36m'!$A$29:$N$80,MATCH('Plant wise prices'!H$2,'Steelmint prices for last 36m'!$A$29:$A$80,0),MATCH('Plant wise prices'!$D4,'Steelmint prices for last 36m'!$A$29:$N$29,0)) -> 47798 | I4: =INDEX('Steelmint prices for last 36m'!$A$29:$N$80,MATCH('Plant wise prices'!I$2,'Steelmint prices for last 36m'!$A$29:$A$80,0),MATCH('Plant wise prices'!$D4,'Steelmint prices for last 36m'!$A$29:$N$29,0)) -> 47495.667 | J4: =INDEX('Steelmint prices for last 36m'!$A$29:$N$80,MATCH('Plant wise prices'!J$2,'Steelmint prices for last 36m'!$A$29:$A$80,0),MATCH('Plant wise prices'!$D4,'Steelmint prices for last 36m'!$A$29:$N$29,0)) -> 47359.667 | K4: =INDEX('Steelmint prices for last 36m'!$A$29:$N$80,MATCH('Plant wise prices'!K$2,'Steelmint prices for last 36m'!$A$29:$A$80,0),MATCH('Plant wise prices'!$D4,'Steelmint prices for last 36m'!$A$29:$N$29,0)) -> 47096.333 | L4: =INDEX('Steelmint prices for last 36m'!$A$29:$N$80,MATCH('Plant wise prices'!L$2,'Steelmint prices for last 36m'!$A$29:$A$80,0),MATCH('Plant wise prices'!$D4,'Steelmint prices for last 36m'!$A$29:$N$29,0)) -> 46326 | ... P4: =INDEX('Steelmint prices for last 36m'!$A$29:$N$80,MATCH('Plant wise prices'!P$2,'Steelmint prices for last 36m'!$A$29:$A$80,0),MATCH('Plant wise prices'!$D4,'Steelmint prices for last 36m'!$A$29:$N$29,0)) -> 48095.556
A5: 550 | B5: Ambashakti Industries Limited | C5: 1400 | D5: ='Steelmint prices for last 36m'!B29 -> Delhi/NCR | E5: =INDEX('Steelmint prices for last 36m'!$A$29:$N$80,MATCH('Plant wise prices'!E$2,'Steelmint prices for last 36m'!$A$29:$A$80,0),MATCH('Plant wise prices'!$D5,'Steelmint prices for last 36m'!$A$29:$N$29,0)) -> 50440.333 | F5: =INDEX('Steelmint prices for last 36m'!$A$29:$N$80,MATCH('Plant wise prices'!F$2,'Steelmint prices for last 36m'!$A$29:$A$80,0),MATCH('Plant wise prices'!$D5,'Steelmint prices for last 36m'!$A$29:$N$29,0)) -> 49797.667 | G5: =INDEX('Steelmint prices for last 36m'!$A$29:$N$80,MATCH('Plant wise prices'!G$2,'Steelmint prices for last 36m'!$A$29:$A$80,0),MATCH('Plant wise prices'!$D5,'Steelmint prices for last 36m'!$A$29:$N$29,0)) -> 48637 | H5: =INDEX('Steelmint prices for last 36m'!$A$29:$N$80,MATCH('Plant wise prices'!H$2,'Steelmint prices for last 36m'!$A$29:$A$80,0),MATCH('Plant wise prices'!$D5,'Steelmint prices for last 36m'!$A$29:$N$29,0)) -> 46497.333 | I5: =INDEX('Steelmint prices for last 36m'!$A$29:$N$80,MATCH('Plant wise prices'!I$2,'Steelmint prices for last 36m'!$A$29:$A$80,0),MATCH('Plant wise prices'!$D5,'Steelmint prices for last 36m'!$A$29:$N$29,0)) -> 45973 | J5: =INDEX('Steelmint prices for last 36m'!$A$29:$N$80,MATCH('Plant wise prices'!J$2,'Steelmint prices for last 36m'!$A$29:$A$80,0),MATCH('Plant wise prices'!$D5,'Steelmint prices for last 36m'!$A$29:$N$29,0)) -> 45928.667 | K5: =INDEX('Steelmint prices for last 36m'!$A$29:$N$80,MATCH('Plant wise prices'!K$2,'Steelmint prices for last 36m'!$A$29:$A$80,0),MATCH('Plant wise prices'!$D5,'Steelmint prices for last 36m'!$A$29:$N$29,0)) -> 45753 | L5: =INDEX('Steelmint prices for last 36m'!$A$29:$N$80,MATCH('Plant wise prices'!L$2,'Steelmint prices for last 36m'!$A$29:$A$80,0),MATCH('Plant wise prices'!$D5,'Steelmint prices for last 36m'!$A$29:$N$29,0)) -> 44874 | ... P5: =INDEX('Steelmint prices for last 36m'!$A$29:$N$80,MATCH('Plant wise prices'!P$2,'Steelmint prices for last 36m'!$A$29:$A$80,0),MATCH('Plant wise prices'!$D5,'Steelmint prices for last 36m'!$A$29:$N$29,0)) -> 47492.889
A6: 550 | B6: AMBASHAKTI UDYOG LIMITED- GWALIOR | C6: 1400 | E6: =E5-800 -> 49640.333 | F6: =F5-800 -> 48997.667 | G6: =G5-800 -> 47837 | H6: =H5-800 -> 45697.333 | I6: =I5-800 -> 45173 | J6: =J5-800 -> 45128.667 | K6: =K5-800 -> 44953 | L6: =L5-800 -> 44074 | ... P6: =P5-800 -> 46692.889
A7: 550 | B7: API Ispat And Powertech Private Limited | C7: 2415 | D7: ='Steelmint prices for last 36m'!F29 -> Raipur | E7: =INDEX('Steelmint prices for last 36m'!$A$29:$N$80,MATCH('Plant wise prices'!E$2,'Steelmint prices for last 36m'!$A$29:$A$80,0),MATCH('Plant wise prices'!$D7,'Steelmint prices for last 36m'!$A$29:$N$29,0)) -> 47358.333 | F7: =INDEX('Steelmint prices for last 36m'!$A$29:$N$80,MATCH('Plant wise prices'!F$2,'Steelmint prices for last 36m'!$A$29:$A$80,0),MATCH('Plant wise prices'!$D7,'Steelmint prices for last 36m'!$A$29:$N$29,0)) -> 46368 | G7: =INDEX('Steelmint prices for last 36m'!$A$29:$N$80,MATCH('Plant wise prices'!G$2,'Steelmint prices for last 36m'!$A$29:$A$80,0),MATCH('Plant wise prices'!$D7,'Steelmint prices for last 36m'!$A$29:$N$29,0)) -> 44909 | H7: =INDEX('Steelmint prices for last 36m'!$A$29:$N$80,MATCH('Plant wise prices'!H$2,'Steelmint prices for last 36m'!$A$29:$A$80,0),MATCH('Plant wise prices'!$D7,'Steelmint prices for last 36m'!$A$29:$N$29,0)) -> 42005.667 | I7: =INDEX('Steelmint prices for last 36m'!$A$29:$N$80,MATCH('Plant wise prices'!I$2,'Steelmint prices for last 36m'!$A$29:$A$80,0),MATCH('Plant wise prices'!$D7,'Steelmint prices for last 36m'!$A$29:$N$29,0)) -> 42310 | J7: =INDEX('Steelmint prices for last 36m'!$A$29:$N$80,MATCH('Plant wise prices'!J$2,'Steelmint prices for last 36m'!$A$29:$A$80,0),MATCH('Plant wise prices'!$D7,'Steelmint prices for last 36m'!$A$29:$N$29,0)) -> 42985.667 | K7: =INDEX('Steelmint prices for last 36m'!$A$29:$N$80,MATCH('Plant wise prices'!K$2,'Steelmint prices for last 36m'!$A$29:$A$80,0),MATCH('Plant wise prices'!$D7,'Steelmint prices for last 36m'!$A$29:$N$29,0)) -> 42769.333 | L7: =INDEX('Steelmint prices for last 36m'!$A$29:$N$80,MATCH('Plant wise prices'!L$2,'Steelmint prices for last 36m'!$A$29:$A$80,0),MATCH('Plant wise prices'!$D7,'Steelmint prices for last 36m'!$A$29:$N$29,0)) -> 41708 | ... P7: =INDEX('Steelmint prices for last 36m'!$A$29:$N$80,MATCH('Plant wise prices'!P$2,'Steelmint prices for last 36m'!$A$29:$A$80,0),MATCH('Plant wise prices'!$D7,'Steelmint prices for last 36m'!$A$29:$N$29,0)) -> 44542.222
A8: 550 | B8: GERMAN GREEN STEEL AND POWER LIMITED | C8: 200 | D8: ='Steelmint prices for last 36m'!D29 -> Ahmedabad | E8: =INDEX('Steelmint prices for last 36m'!$A$29:$N$80,MATCH('Plant wise prices'!E$2,'Steelmint prices for last 36m'!$A$29:$A$80,0),MATCH('Plant wise prices'!$D8,'Steelmint prices for last 36m'!$A$29:$N$29,0)) -> 50322.333 | F8: =INDEX('Steelmint prices for last 36m'!$A$29:$N$80,MATCH('Plant wise prices'!F$2,'Steelmint prices for last 36m'!$A$29:$A$80,0),MATCH('Plant wise prices'!$D8,'Steelmint prices for last 36m'!$A$29:$N$29,0)) -> 49913.667 | G8: =INDEX('Steelmint prices for last 36m'!$A$29:$N$80,MATCH('Plant wise prices'!G$2,'Steelmint prices for last 36m'!$A$29:$A$80,0),MATCH('Plant wise prices'!$D8,'Steelmint prices for last 36m'!$A$29:$N$29,0)) -> 48520.667 | H8: =INDEX('Steelmint prices for last 36m'!$A$29:$N$80,MATCH('Plant wise prices'!H$2,'Steelmint prices for last 36m'!$A$29:$A$80,0),MATCH('Plant wise prices'!$D8,'Steelmint prices for last 36m'!$A$29:$N$29,0)) -> 45967 | I8: =INDEX('Steelmint prices for last 36m'!$A$29:$N$80,MATCH('Plant wise prices'!I$2,'Steelmint prices for last 36m'!$A$29:$A$80,0),MATCH('Plant wise prices'!$D8,'Steelmint prices for last 36m'!$A$29:$N$29,0)) -> 46257.333 | J8: =INDEX('Steelmint prices for last 36m'!$A$29:$N$80,MATCH('Plant wise prices'!J$2,'Steelmint prices for last 36m'!$A$29:$A$80,0),MATCH('Plant wise prices'!$D8,'Steelmint prices for last 36m'!$A$29:$N$29,0)) -> 46615.333 | K8: =INDEX('Steelmint prices for last 36m'!$A$29:$N$80,MATCH('Plant wise prices'!K$2,'Steelmint prices for last 36m'!$A$29:$A$80,0),MATCH('Plant wise prices'!$D8,'Steelmint prices for last 36m'!$A$29:$N$29,0)) -> 46281.333 | L8: =INDEX('Steelmint prices for last 36m'!$A$29:$N$80,MATCH('Plant wise prices'!L$2,'Steelmint prices for last 36m'!$A$29:$A$80,0),MATCH('Plant wise prices'!$D8,'Steelmint prices for last 36m'!$A$29:$N$29,0)) -> 45582.667 | ... P8: =INDEX('Steelmint prices for last 36m'!$A$29:$N$80,MATCH('Plant wise prices'!P$2,'Steelmint prices for last 36m'!$A$29:$A$80,0),MATCH('Plant wise prices'!$D8,'Steelmint prices for last 36m'!$A$29:$N$29,0)) -> 48395.111
A9: 550 | B9: SKA Ispat Private Limited | C9: 2075 | D9: ='Steelmint prices for last 36m'!F29 -> Raipur | E9: =INDEX('Steelmint prices for last 36m'!$A$29:$N$80,MATCH('Plant wise prices'!E$2,'Steelmint prices for last 36m'!$A$29:$A$80,0),MATCH('Plant wise prices'!$D9,'Steelmint prices for last 36m'!$A$29:$N$29,0)) -> 47358.333 | F9: =INDEX('Steelmint prices for last 36m'!$A$29:$N$80,MATCH('Plant wise prices'!F$2,'Steelmint prices for last 36m'!$A$29:$A$80,0),MATCH('Plant wise prices'!$D9,'Steelmint prices for last 36m'!$A$29:$N$29,0)) -> 46368 | G9: =INDEX('Steelmint prices for last 36m'!$A$29:$N$80,MATCH('Plant wise prices'!G$2,'Steelmint prices for last 36m'!$A$29:$A$80,0),MATCH('Plant wise prices'!$D9,'Steelmint prices for last 36m'!$A$29:$N$29,0)) -> 44909 | H9: =INDEX('Steelmint prices for last 36m'!$A$29:$N$80,MATCH('Plant wise prices'!H$2,'Steelmint prices for last 36m'!$A$29:$A$80,0),MATCH('Plant wise prices'!$D9,'Steelmint prices for last 36m'!$A$29:$N$29,0)) -> 42005.667 | I9: =INDEX('Steelmint prices for last 36m'!$A$29:$N$80,MATCH('Plant wise prices'!I$2,'Steelmint prices for last 36m'!$A$29:$A$80,0),MATCH('Plant wise prices'!$D9,'Steelmint prices for last 36m'!$A$29:$N$29,0)) -> 42310 | J9: =INDEX('Steelmint prices for last 36m'!$A$29:$N$80,MATCH('Plant wise prices'!J$2,'Steelmint prices for last 36m'!$A$29:$A$80,0),MATCH('Plant wise prices'!$D9,'Steelmint prices for last 36m'!$A$29:$N$29,0)) -> 42985.667 | K9: =INDEX('Steelmint prices for last 36m'!$A$29:$N$80,MATCH('Plant wise prices'!K$2,'Steelmint prices for last 36m'!$A$29:$A$80,0),MATCH('Plant wise prices'!$D9,'Steelmint prices for last 36m'!$A$29:$N$29,0)) -> 42769.333 | L9: =INDEX('Steelmint prices for last 36m'!$A$29:$N$80,MATCH('Plant wise prices'!L$2,'Steelmint prices for last 36m'!$A$29:$A$80,0),MATCH('Plant wise prices'!$D9,'Steelmint prices for last 36m'!$A$29:$N$29,0)) -> 41708 | ... P9: =INDEX('Steelmint prices for last 36m'!$A$29:$N$80,MATCH('Plant wise prices'!P$2,'Steelmint prices for last 36m'!$A$29:$A$80,0),MATCH('Plant wise prices'!$D9,'Steelmint prices for last 36m'!$A$29:$N$29,0)) -> 44542.222
A10: 550 | B10: Real Ispat | C10: 0 | D10: ='Steelmint prices for last 36m'!F29 -> Raipur | E10: =INDEX('Steelmint prices for last 36m'!$A$29:$N$80,MATCH('Plant wise prices'!E$2,'Steelmint prices for last 36m'!$A$29:$A$80,0),MATCH('Plant wise prices'!$D10,'Steelmint prices for last 36m'!$A$29:$N$29,0)) -> 47358.333 | F10: =INDEX('Steelmint prices for last 36m'!$A$29:$N$80,MATCH('Plant wise prices'!F$2,'Steelmint prices for last 36m'!$A$29:$A$80,0),MATCH('Plant wise prices'!$D10,'Steelmint prices for last 36m'!$A$29:$N$29,0)) -> 46368 | G10: =INDEX('Steelmint prices for last 36m'!$A$29:$N$80,MATCH('Plant wise prices'!G$2,'Steelmint prices for last 36m'!$A$29:$A$80,0),MATCH('Plant wise prices'!$D10,'Steelmint prices for last 36m'!$A$29:$N$29,0)) -> 44909 | H10: =INDEX('Steelmint prices for last 36m'!$A$29:$N$80,MATCH('Plant wise prices'!H$2,'Steelmint prices for last 36m'!$A$29:$A$80,0),MATCH('Plant wise prices'!$D10,'Steelmint prices for last 36m'!$A$29:$N$29,0)) -> 42005.667 | I10: =INDEX('Steelmint prices for last 36m'!$A$29:$N$80,MATCH('Plant wise prices'!I$2,'Steelmint prices for last 36m'!$A$29:$A$80,0),MATCH('Plant wise prices'!$D10,'Steelmint prices for last 36m'!$A$29:$N$29,0)) -> 42310 | J10: =INDEX('Steelmint prices for last 36m'!$A$29:$N$80,MATCH('Plant wise prices'!J$2,'Steelmint prices for last 36m'!$A$29:$A$80,0),MATCH('Plant wise prices'!$D10,'Steelmint prices for last 36m'!$A$29:$N$29,0)) -> 42985.667 | K10: =INDEX('Steelmint prices for last 36m'!$A$29:$N$80,MATCH('Plant wise prices'!K$2,'Steelmint prices for last 36m'!$A$29:$A$80,0),MATCH('Plant wise prices'!$D10,'Steelmint prices for last 36m'!$A$29:$N$29,0)) -> 42769.333 | L10: =INDEX('Steelmint prices for last 36m'!$A$29:$N$80,MATCH('Plant wise prices'!L$2,'Steelmint prices for last 36m'!$A$29:$A$80,0),MATCH('Plant wise prices'!$D10,'Steelmint prices for last 36m'!$A$29:$N$29,0)) -> 41708 | ... P10: =INDEX('Steelmint prices for last 36m'!$A$29:$N$80,MATCH('Plant wise prices'!P$2,'Steelmint prices for last 36m'!$A$29:$A$80,0),MATCH('Plant wise prices'!$D10,'Steelmint prices for last 36m'!$A$29:$N$29,0)) -> 44542.222
A11: 550 | B11: Rashmi Steel | C11: 2415 | D11: ='Steelmint prices for last 36m'!L29 -> Durgapur | E11: =INDEX('Steelmint prices for last 36m'!$A$29:$N$80,MATCH('Plant wise prices'!E$2,'Steelmint prices for last 36m'!$A$29:$A$80,0),MATCH('Plant wise prices'!$D11,'Steelmint prices for last 36m'!$A$29:$N$29,0)) -> 47844.333 | F11: =INDEX('Steelmint prices for last 36m'!$A$29:$N$80,MATCH('Plant wise prices'!F$2,'Steelmint prices for last 36m'!$A$29:$A$80,0),MATCH('Plant wise prices'!$D11,'Steelmint prices for last 36m'!$A$29:$N$29,0)) -> 46166.667 | G11: =INDEX('Steelmint prices for last 36m'!$A$29:$N$80,MATCH('Plant wise prices'!G$2,'Steelmint prices for last 36m'!$A$29:$A$80,0),MATCH('Plant wise prices'!$D11,'Steelmint prices for last 36m'!$A$29:$N$29,0)) -> 44392 | H11: =INDEX('Steelmint prices for last 36m'!$A$29:$N$80,MATCH('Plant wise prices'!H$2,'Steelmint prices for last 36m'!$A$29:$A$80,0),MATCH('Plant wise prices'!$D11,'Steelmint prices for last 36m'!$A$29:$N$29,0)) -> 42156 | I11: =INDEX('Steelmint prices for last 36m'!$A$29:$N$80,MATCH('Plant wise prices'!I$2,'Steelmint prices for last 36m'!$A$29:$A$80,0),MATCH('Plant wise prices'!$D11,'Steelmint prices for last 36m'!$A$29:$N$29,0)) -> 42114.333 | J11: =INDEX('Steelmint prices for last 36m'!$A$29:$N$80,MATCH('Plant wise prices'!J$2,'Steelmint prices for last 36m'!$A$29:$A$80,0),MATCH('Plant wise prices'!$D11,'Steelmint prices for last 36m'!$A$29:$N$29,0)) -> 42390 | K11: =INDEX('Steelmint prices for last 36m'!$A$29:$N$80,MATCH('Plant wise prices'!K$2,'Steelmint prices for last 36m'!$A$29:$A$80,0),MATCH('Plant wise prices'!$D11,'Steelmint prices for last 36m'!$A$29:$N$29,0)) -> 42379 | L11: =INDEX('Steelmint prices for last 36m'!$A$29:$N$80,MATCH('Plant wise prices'!L$2,'Steelmint prices for last 36m'!$A$29:$A$80,0),MATCH('Plant wise prices'!$D11,'Steelmint prices for last 36m'!$A$29:$N$29,0)) -> 41367.667 | ... P11: =INDEX('Steelmint prices for last 36m'!$A$29:$N$80,MATCH('Plant wise prices'!P$2,'Steelmint prices for last 36m'!$A$29:$A$80,0),MATCH('Plant wise prices'!$D11,'Steelmint prices for last 36m'!$A$29:$N$29,0)) -> 44539.778
A12: 550 | B12: Telangana - New Plant | C12: 2415 | D12: Hyderabad | E12: =INDEX('Steelmint prices for last 36m'!$A$29:$N$80,MATCH('Plant wise prices'!E$2,'Steelmint prices for last 36m'!$A$29:$A$80,0),MATCH('Plant wise prices'!$D12,'Steelmint prices for last 36m'!$A$29:$N$29,0)) -> 49673.667 | F12: =INDEX('Steelmint prices for last 36m'!$A$29:$N$80,MATCH('Plant wise prices'!F$2,'Steelmint prices for last 36m'!$A$29:$A$80,0),MATCH('Plant wise prices'!$D12,'Steelmint prices for last 36m'!$A$29:$N$29,0)) -> 48756 | G12: =INDEX('Steelmint prices for last 36m'!$A$29:$N$80,MATCH('Plant wise prices'!G$2,'Steelmint prices for last 36m'!$A$29:$A$80,0),MATCH('Plant wise prices'!$D12,'Steelmint prices for last 36m'!$A$29:$N$29,0)) -> 46797.667 | H12: =INDEX('Steelmint prices for last 36m'!$A$29:$N$80,MATCH('Plant wise prices'!H$2,'Steelmint prices for last 36m'!$A$29:$A$80,0),MATCH('Plant wise prices'!$D12,'Steelmint prices for last 36m'!$A$29:$N$29,0)) -> 45036 | I12: =INDEX('Steelmint prices for last 36m'!$A$29:$N$80,MATCH('Plant wise prices'!I$2,'Steelmint prices for last 36m'!$A$29:$A$80,0),MATCH('Plant wise prices'!$D12,'Steelmint prices for last 36m'!$A$29:$N$29,0)) -> 44642.333 | J12: =INDEX('Steelmint prices for last 36m'!$A$29:$N$80,MATCH('Plant wise prices'!J$2,'Steelmint prices for last 36m'!$A$29:$A$80,0),MATCH('Plant wise prices'!$D12,'Steelmint prices for last 36m'!$A$29:$N$29,0)) -> 45460.667 | K12: =INDEX('Steelmint prices for last 36m'!$A$29:$N$80,MATCH('Plant wise prices'!K$2,'Steelmint prices for last 36m'!$A$29:$A$80,0),MATCH('Plant wise prices'!$D12,'Steelmint prices for last 36m'!$A$29:$N$29,0)) -> 45104 | L12: =INDEX('Steelmint prices for last 36m'!$A$29:$N$80,MATCH('Plant wise prices'!L$2,'Steelmint prices for last 36m'!$A$29:$A$80,0),MATCH('Plant wise prices'!$D12,'Steelmint prices for last 36m'!$A$29:$N$29,0)) -> 44154 | ... P12: =INDEX('Steelmint prices for last 36m'!$A$29:$N$80,MATCH('Plant wise prices'!P$2,'Steelmint prices for last 36m'!$A$29:$A$80,0),MATCH('Plant wise prices'!$D12,'Steelmint prices for last 36m'!$A$29:$N$29,0)) -> 47053.778
A13: 550 | B13: Maharashtra - New Plant | C13: 2415 | D13: Mumbai | E13: =INDEX('Steelmint prices for last 36m'!$A$29:$N$80,MATCH('Plant wise prices'!E$2,'Steelmint prices for last 36m'!$A$29:$A$80,0),MATCH('Plant wise prices'!$D13,'Steelmint prices for last 36m'!$A$29:$N$29,0)) -> 51608.667 | F13: =INDEX('Steelmint prices for last 36m'!$A$29:$N$80,MATCH('Plant wise prices'!F$2,'Steelmint prices for last 36m'!$A$29:$A$80,0),MATCH('Plant wise prices'!$D13,'Steelmint prices for last 36m'!$A$29:$N$29,0)) -> 51348 | G13: =INDEX('Steelmint prices for last 36m'!$A$29:$N$80,MATCH('Plant wise prices'!G$2,'Steelmint prices for last 36m'!$A$29:$A$80,0),MATCH('Plant wise prices'!$D13,'Steelmint prices for last 36m'!$A$29:$N$29,0)) -> 48694.667 | H13: =INDEX('Steelmint prices for last 36m'!$A$29:$N$80,MATCH('Plant wise prices'!H$2,'Steelmint prices for last 36m'!$A$29:$A$80,0),MATCH('Plant wise prices'!$D13,'Steelmint prices for last 36m'!$A$29:$N$29,0)) -> 45745.333 | I13: =INDEX('Steelmint prices for last 36m'!$A$29:$N$80,MATCH('Plant wise prices'!I$2,'Steelmint prices for last 36m'!$A$29:$A$80,0),MATCH('Plant wise prices'!$D13,'Steelmint prices for last 36m'!$A$29:$N$29,0)) -> 46515.333 | J13: =INDEX('Steelmint prices for last 36m'!$A$29:$N$80,MATCH('Plant wise prices'!J$2,'Steelmint prices for last 36m'!$A$29:$A$80,0),MATCH('Plant wise prices'!$D13,'Steelmint prices for last 36m'!$A$29:$N$29,0)) -> 47287.333 | K13: =INDEX('Steelmint prices for last 36m'!$A$29:$N$80,MATCH('Plant wise prices'!K$2,'Steelmint prices for last 36m'!$A$29:$A$80,0),MATCH('Plant wise prices'!$D13,'Steelmint prices for last 36m'!$A$29:$N$29,0)) -> 47096.333 | L13: =INDEX('Steelmint prices for last 36m'!$A$29:$N$80,MATCH('Plant wise prices'!L$2,'Steelmint prices for last 36m'!$A$29:$A$80,0),MATCH('Plant wise prices'!$D13,'Steelmint prices for last 36m'!$A$29:$N$29,0)) -> 46410.333 | ... P13: =INDEX('Steelmint prices for last 36m'!$A$29:$N$80,MATCH('Plant wise prices'!P$2,'Steelmint prices for last 36m'!$A$29:$A$80,0),MATCH('Plant wise prices'!$D13,'Steelmint prices for last 36m'!$A$29:$N$29,0)) -> 50040.556
A15: 550D | B15: =B3 -> AIC IRON INDUSTRIES PRIVATE LIMITED | C15: 3770 | D15: =D3 -> Durgapur | E15: =INDEX('Steelmint prices for last 36m'!$A$29:$N$80,MATCH('Plant wise prices'!E$2,'Steelmint prices for last 36m'!$A$29:$A$80,0),MATCH('Plant wise prices'!$D15,'Steelmint prices for last 36m'!$A$29:$N$29,0)) -> 47844.333 | F15: =INDEX('Steelmint prices for last 36m'!$A$29:$N$80,MATCH('Plant wise prices'!F$2,'Steelmint prices for last 36m'!$A$29:$A$80,0),MATCH('Plant wise prices'!$D15,'Steelmint prices for last 36m'!$A$29:$N$29,0)) -> 46166.667 | G15: =INDEX('Steelmint prices for last 36m'!$A$29:$N$80,MATCH('Plant wise prices'!G$2,'Steelmint prices for last 36m'!$A$29:$A$80,0),MATCH('Plant wise prices'!$D15,'Steelmint prices for last 36m'!$A$29:$N$29,0)) -> 44392 | H15: =INDEX('Steelmint prices for last 36m'!$A$29:$N$80,MATCH('Plant wise prices'!H$2,'Steelmint prices for last 36m'!$A$29:$A$80,0),MATCH('Plant wise prices'!$D15,'Steelmint prices for last 36m'!$A$29:$N$29,0)) -> 42156 | I15: =INDEX('Steelmint prices for last 36m'!$A$29:$N$80,MATCH('Plant wise prices'!I$2,'Steelmint prices for last 36m'!$A$29:$A$80,0),MATCH('Plant wise prices'!$D15,'Steelmint prices for last 36m'!$A$29:$N$29,0)) -> 42114.333 | J15: =INDEX('Steelmint prices for last 36m'!$A$29:$N$80,MATCH('Plant wise prices'!J$2,'Steelmint prices for last 36m'!$A$29:$A$80,0),MATCH('Plant wise prices'!$D15,'Steelmint prices for last 36m'!$A$29:$N$29,0)) -> 42390 | K15: =INDEX('Steelmint prices for last 36m'!$A$29:$N$80,MATCH('Plant wise prices'!K$2,'Steelmint prices for last 36m'!$A$29:$A$80,0),MATCH('Plant wise prices'!$D15,'Steelmint prices for last 36m'!$A$29:$N$29,0)) -> 42379 | L15: =INDEX('Steelmint prices for last 36m'!$A$29:$N$80,MATCH('Plant wise prices'!L$2,'Steelmint prices for last 36m'!$A$29:$A$80,0),MATCH('Plant wise prices'!$D15,'Steelmint prices for last 36m'!$A$29:$N$29,0)) -> 41367.667 | ... P15: =INDEX('Steelmint prices for last 36m'!$A$29:$N$80,MATCH('Plant wise prices'!P$2,'Steelmint prices for last 36m'!$A$29:$A$80,0),MATCH('Plant wise prices'!$D15,'Steelmint prices for last 36m'!$A$29:$N$29,0)) -> 44539.778
A16: 550D | B16: =B4 -> Aditya Industries | C16: 1450 | D16: =D4 -> Mandi Gobindgarh | E16: =INDEX('Steelmint prices for last 36m'!$A$29:$N$80,MATCH('Plant wise prices'!E$2,'Steelmint prices for last 36m'!$A$29:$A$80,0),MATCH('Plant wise prices'!$D16,'Steelmint prices for last 36m'!$A$29:$N$29,0)) -> 50924.333 | F16: =INDEX('Steelmint prices for last 36m'!$A$29:$N$80,MATCH('Plant wise prices'!F$2,'Steelmint prices for last 36m'!$A$29:$A$80,0),MATCH('Plant wise prices'!$D16,'Steelmint prices for last 36m'!$A$29:$N$29,0)) -> 50534.667 | G16: =INDEX('Steelmint prices for last 36m'!$A$29:$N$80,MATCH('Plant wise prices'!G$2,'Steelmint prices for last 36m'!$A$29:$A$80,0),MATCH('Plant wise prices'!$D16,'Steelmint prices for last 36m'!$A$29:$N$29,0)) -> 49712.333 | H16: =INDEX('Steelmint prices for last 36m'!$A$29:$N$80,MATCH('Plant wise prices'!H$2,'Steelmint prices for last 36m'!$A$29:$A$80,0),MATCH('Plant wise prices'!$D16,'Steelmint prices for last 36m'!$A$29:$N$29,0)) -> 47798 | I16: =INDEX('Steelmint prices for last 36m'!$A$29:$N$80,MATCH('Plant wise prices'!I$2,'Steelmint prices for last 36m'!$A$29:$A$80,0),MATCH('Plant wise prices'!$D16,'Steelmint prices for last 36m'!$A$29:$N$29,0)) -> 47495.667 | J16: =INDEX('Steelmint prices for last 36m'!$A$29:$N$80,MATCH('Plant wise prices'!J$2,'Steelmint prices for last 36m'!$A$29:$A$80,0),MATCH('Plant wise prices'!$D16,'Steelmint prices for last 36m'!$A$29:$N$29,0)) -> 47359.667 | K16: =INDEX('Steelmint prices for last 36m'!$A$29:$N$80,MATCH('Plant wise prices'!K$2,'Steelmint prices for last 36m'!$A$29:$A$80,0),MATCH('Plant wise prices'!$D16,'Steelmint prices for last 36m'!$A$29:$N$29,0)) -> 47096.333 | L16: =INDEX('Steelmint prices for last 36m'!$A$29:$N$80,MATCH('Plant wise prices'!L$2,'Steelmint prices for last 36m'!$A$29:$A$80,0),MATCH('Plant wise prices'!$D16,'Steelmint prices for last 36m'!$A$29:$N$29,0)) -> 46326 | ... P16: =INDEX('Steelmint prices for last 36m'!$A$29:$N$80,MATCH('Plant wise prices'!P$2,'Steelmint prices for last 36m'!$A$29:$A$80,0),MATCH('Plant wise prices'!$D16,'Steelmint prices for last 36m'!$A$29:$N$29,0)) -> 48095.556
