Workbook

Sheet Executive Summary
A1: JSW STEEL TMT - MARKETING BUDGET FY 2026-27
A2: Executive Summary - Management Review
A4: KEY PERFORMANCE INDICATORS
B5: Total Budget | D5: Helix Budget | F5: JSW ONE Budget | H5: Total Volume
B6: ='Budget Control'!C6 | D6: ='Budget Control'!C16 | F6: ='Budget Control'!C17 | H6: ='Budget Control'!C37+'Budget Control'!C43
B8: Blended Cost/MT | D8: Contingency | F8: Helix A/S Ratio | H8: JSW ONE A/S Ratio
B9: =IF(('Budget Control'!C37+'Budget Control'!C43)>0,('Budget Control'!C16+'Budget Control'!C17)/('Budget Control'!C37+'Budget Control'!C43),0) | D9: ='Budget Control'!C20 | F9: ='Obj1 - Helix Launch'!E56 | H9: ='Obj2 - JSW ONE Growth'!F60
A11: STRATEGIC OBJECTIVES OVERVIEW
B12: Objective | C12: Brand | D12: Geography | E12: Budget (Rs.) | F12: Volume (MT) | G12: Cost/MT | H12: ATL/BTL | J12: Key Focus
B13: Obj1: National Launch | C13: One Helix TMT | D13: Pan-India (250 dist) | E13: ='Budget Control'!C16 | F13: ='Budget Control'!C37 | G13: ='Obj1 - Helix Launch'!E54 | H13: 40:60 | J13: Brand awareness + dealer activation
B14: Obj2A: East Growth | C14: JSW ONE TMT | D14: Bihar, WB, JH, OD | E14: ='Budget Control'!C18 | F14: ='Budget Control'!C43*'Budget Control'!C48 | G14: =IF(F14>0,E14/F14,0) | H14: BTL heavy | J14: Market penetration + retailer network
B15: Obj2B: UP+HR 2x Growth | C15: JSW ONE TMT | D15: UP & Haryana | E15: ='Budget Control'!C19 | F15: ='Budget Control'!C43*'Budget Control'!C49 | G15: =IF(F15>0,E15/F15,0) | H15: BTL heavy | J15: Aggressive volume push + conversion
B16: Contingency Reserve | E16: ='Budget Control'!C20
B17: TOTAL | E17: ='Budget Control'!C6 | F17: ='Budget Control'!C37+'Budget Control'!C43
A19: BUDGET ALLOCATION BREAKDOWN
B20: Category | C20: Obj1: Helix | D20: Obj2A: East | E20: Obj2B: UP+HR | F20: Total Obj2 | G20: Grand Total | H20: % of Budget
B21: Allocated Budget | C21: ='Budget Control'!C16 | D21: ='Budget Control'!C18 | E21: ='Budget Control'!C19 | F21: =D21+E21 | G21: =C21+F21 | H21: =IF('Budget Control'!C6<>0,G21/'Budget Control'!C6,0)
B22: ATL Spend | C22: ='Obj1 - Helix Launch'!E25 | D22: ='Obj2 - JSW ONE Growth'!D27 | E22: ='Obj2 - JSW ONE Growth'!F27 | F22: =D22+E22 | G22: =C22+F22 | H22: =IF('Budget Control'!C6<>0,G22/'Budget Control'!C6,0)
B23: BTL Spend | C23: ='Obj1 - Helix Launch'!E42 | D23: ='Obj2 - JSW ONE Growth'!D44 | E23: ='Obj2 - JSW ONE Growth'!F44 | F23: =D23+E23 | G23: =C23+F23 | H23: =IF('Budget Control'!C6<>0,G23/'Budget Control'!C6,0)
B24: Total Spend | C24: ='Obj1 - Helix Launch'!E43 | D24: ='Obj2 - JSW ONE Growth'!D45 | E24: ='Obj2 - JSW ONE Growth'!F45 | F24: =D24+E24 | G24: =C24+F24 | H24: =IF('Budget Control'!C6<>0,G24/'Budget Control'!C6,0)
A27: QUARTERLY SPEND PLAN
B28: Quarter | C28: Obj1: Helix | D28: Obj2: JSW ONE | E28: Total | F28: % of Annual
B29: Q1 (Apr-Jun) | C29: ='Obj1 - Helix Launch'!F43 | D29: ='Obj2 - JSW ONE Growth'!H45 | E29: =C29+D29 | F29: =IF(E33<>0,E29/E33,0)
B30: Q2 (Jul-Sep) | C30: ='Obj1 - Helix Launch'!G43 | D30: ='Obj2 - JSW ONE Growth'!I45 | E30: =C30+D30 | F30: =IF(E33<>0,E30/E33,0)
B31: Q3 (Oct-Dec) | C31: ='Obj1 - Helix Launch'!H43 | D31: ='Obj2 - JSW ONE Growth'!J45 | E31: =C31+D31 | F31: =IF(E33<>0,E31/E33,0)
B32: Q4 (Jan-Mar) | C32: ='Obj1 - Helix Launch'!I43 | D32: ='Obj2 - JSW ONE Growth'!K45 | E32: =C32+D32 | F32: =IF(E33<>0,E32/E33,0)
B33: ANNUAL TOTAL | C33: =SUM(C29:C32) | D33: =SUM(D29:D32) | E33: =SUM(E29:E32) | F33: 1

Sheet Budget Control
A1: BUDGET CONTROL & REVIEW
A2: Yellow cells are editable. All changes cascade to objective tabs and executive summary.
A4: SECTION 1: BUDGET PARAMETERS
A5: # | B5: Parameter | C5: Value | D5: Unit | J5: Notes
A6: 1 | B6: Total Marketing Budget | C6: 50000000 | D6: Rs. | J6: Rs. 5 Crores for FY27
A7: 2 | B7: Objective 1 - Helix Share % | C7: 0.6 | D7: % | J7: 60% for national launch
A8: 3 | B8: Objective 2 - JSW ONE Share % | C8: =1-C7 | D8: % | J8: Auto = 1 - Helix%
A9: 4 | B9: Sub-2A East Share (of Obj2) | C9: 0.6 | D9: % | J9: 60% of JSW ONE budget
A10: 5 | B10: Sub-2B UP+HR Share (of Obj2) | C10: =1-C9 | D10: % | J10: Auto = 1 - East%
A11: 6 | B11: Contingency Reserve % | C11: 0.05 | D11: % | J11: 5% held back
A12: 7 | B12: ATL Share % (Helix) | C12: 0.4 | D12: % | J12: 40% ATL, 60% BTL
A13: 8 | B13: BTL Share % (Helix) | C13: =1-C12 | D13: % | J13: Auto = 1 - ATL%
A15: DERIVED BUDGET AMOUNTS
B16: Helix Budget (after contingency) | C16: =C6*C7*(1-C11)
B17: JSW ONE Total Budget (after contingency) | C17: =C6*C8*(1-C11)
B18: Sub-2A East Budget | C18: =C17*C9
B19: Sub-2B UP+HR Budget | C19: =C17*C10
B20: Contingency Reserve | C20: =C6*C11
B21: Total Allocated (Verification) | C21: =C16+C17+C20
A23: VERIFICATION CHECKS
B24: Obj1 + Obj2 = 100%? | C24: =IF(ABS(C7+C8-1)<0.001,"YES","NO")
B25: Sub-2A + Sub-2B = Obj2? | C25: =IF(ABS(C18+C19-C17)<1,"YES","NO")
B26: Total = Budget? | C26: =IF(ABS(C21-C6)<1,"YES","NO")
A28: QUARTERLY ALLOCATION
B29: Q1 (Apr-Jun) % | C29: 0.25 | J29: Launch push + early summer
B30: Q2 (Jul-Sep) % | C30: 0.15 | J30: Monsoon slowdown
B31: Q3 (Oct-Dec) % | C31: 0.35 | J31: Peak construction season
B32: Q4 (Jan-Mar) % | C32: 0.25 | J32: Year-end push
B33: Quarterly Sum = 100%? | C33: =IF(ABS(C29+C30+C31+C32-1)<0.001,"YES","NO")
A35: VOLUME & NETWORK ASSUMPTIONS
B36: Helix - Distributors | C36: 42 | D36: nos
B37: Helix - Annual Volume Target | C37: 121000 | D37: MT
B38: Helix - Active Retailers | C38: 2015 | D38: nos
B39: Helix - Transacting Retailers | C39: 1310 | D39: nos
B40: Helix - Priority Districts | C40: 250 | D40: nos
B41: Helix - Selling Price/MT | C41: 48868 | D41: Rs/MT
B42: JSW ONE - Distributors | C42: 56 | D42: nos
B43: JSW ONE - Annual Volume Target | C43: 268000 | D43: MT
B44: JSW ONE - Active Retailers | C44: 1590 | D44: nos
B45: JSW ONE - Transacting Retailers | C45: 1033 | D45: nos
...

Sheet Obj1 - Helix Launch
A1: OBJECTIVE 1: ONE HELIX TMT - NATIONAL LAUNCH
A3: BRAND OVERVIEW
B4: Brand | C4: One Helix TMT (FE550 Grade Premium Steel)
B5: Geography | C5: Pan-India, 250 Priority Districts
B6: Network | C6: ='Budget Control'!C36 & " Distributors, " & 'Budget Control'!C38 & " Active Retailers"
B7: Budget Allocation | C7: ="Rs. " & TEXT('Budget Control'!C16,"##,##,##0") & " (" & TEXT('Budget Control'!C7,"0%") & " of total)"
B8: ATL : BTL Split | C8: ="ATL " & TEXT('Budget Control'!C12,"0%") & " : BTL " & TEXT('Budget Control'!C13,"0%")
B9: Volume Target | C9: =TEXT('Budget Control'!C37,"##,##0") & " MT (Annual)"
B10: Selling Price | C10: ="Rs. " & TEXT('Budget Control'!C41,"##,##0") & " per MT"
A12: ACTIVITY PLAN WITH BUDGET
A13: # | B13: Activity | C13: Quantity | D13: Unit Cost (Rs.) | E13: Annual Cost (Rs.) | F13: Q1 | G13: Q2 | H13: Q3 | I13: Q4 | J13: Basis
A14: ATL ACTIVITIES
A15: 1 | B15: Impact Wall Painting | C15: =250*20000 | D15: ='Budget Control'!C62 | E15: =C15*D15 | F15: =E15*'Budget Control'!C29 | G15: =E15*'Budget Control'!C30 | H15: =E15*'Budget Control'!C31 | I15: =E15*'Budget Control'!C32 | J15: sqft across 250 districts
A16: 2 | B16: FM Radio Campaign | C16: =ROUND(250*0.05,0)*4 | D16: ='Budget Control'!C63 | E16: =C16*D16 | F16: =E16*'Budget Control'!C29 | G16: =E16*'Budget Control'!C30 | H16: =E16*'Budget Control'!C31 | I16: =E16*'Budget Control'!C32 | J16: 5% districts x 4 qtrs
A17: 3 | B17: Hoardings (Flex/Billboard) | C17: =250*5 | D17: ='Budget Control'!C64 | E17: =C17*D17 | F17: =E17*'Budget Control'!C29 | G17: =E17*'Budget Control'!C30 | H17: =E17*'Budget Control'!C31 | I17: =E17*'Budget Control'!C32 | J17: 5 per district
A18: 4 | B18: Digital Marketing Campaign | C18: 4 | D18: ='Budget Control'!C65 | E18: =C18*D18 | F18: =E18*'Budget Control'!C29 | G18: =E18*'Budget Control'!C30 | H18: =E18*'Budget Control'!C31 | I18: =E18*'Budget Control'!C32 | J18: 4 campaigns/year
A19: 5 | B19: Local Events / Trade Fairs | C19: 8 | D19: ='Budget Control'!C66 | E19: =C19*D19 | F19: =E19*'Budget Control'!C29 | G19: =E19*'Budget Control'!C30 | H19: =E19*'Budget Control'!C31 | I19: =E19*'Budget Control'!C32 | J19: 8 zonal events
A20: 6 | B20: Van Campaign (Mobile) | C20: =10*60 | D20: ='Budget Control'!C67 | E20: =C20*D20 | F20: =E20*'Budget Control'!C29 | G20: =E20*'Budget Control'!C30 | H20: =E20*'Budget Control'!C31 | I20: =E20*'Budget Control'!C32 | J20: 10 vans x 60 days
A21: 7 | B21: Syndicate Launch Events | C21: 15 | D21: ='Budget Control'!C68 | E21: =C21*D21 | F21: =E21*'Budget Control'!C29 | G21: =E21*'Budget Control'!C30 | H21: =E21*'Budget Control'!C31 | I21: =E21*'Budget Control'!C32 | J21: 15 state launches
A22: 8 | B22: Transit Auto Branding | C22: 500 | D22: ='Budget Control'!C69 | E22: =C22*D22 | F22: =E22*'Budget Control'!C29 | G22: =E22*'Budget Control'!C30 | H22: =E22*'Budget Control'!C31 | I22: =E22*'Budget Control'!C32 | J22: 500 autos branded
A23: 9 | B23: Tea Stall Branding | C23: =ROUND(250*0.1,0)*25 | D23: ='Budget Control'!C70 | E23: =C23*D23 | F23: =E23*'Budget Control'!C29 | G23: =E23*'Budget Control'!C30 | H23: =E23*'Budget Control'!C31 | I23: =E23*'Budget Control'!C32 | J23: 10% dist x 25 stalls
A24: 10 | B24: Paper Advertisement | C24: 12 | D24: ='Budget Control'!C71 | E24: =C24*D24 | F24: =E24*'Budget Control'!C29 | G24: =E24*'Budget Control'!C30 | H24: =E24*'Budget Control'!C31 | I24: =E24*'Budget Control'!C32 | J24: 12 insertions/year
B25: ATL SUBTOTAL | E25: =SUM(E15:E24) | F25: =SUM(F15:F24) | G25: =SUM(G15:G24) | H25: =SUM(H15:H24) | I25: =SUM(I15:I24)
A26: BTL ACTIVITIES
A27: 11 | B27: NLB (Name/Lit Board) | C27: =ROUND(2015*0.5,0) | D27: ='Budget Control'!C73 | E27: =C27*D27 | F27: =E27*'Budget Control'!C29 | G27: =E27*'Budget Control'!C30 | H27: =E27*'Budget Control'!C31 | I27: =E27*'Budget Control'!C32 | J27: 50% active retailers
A28: 12 | B28: GSB (Glow Sign Board) | C28: =ROUND(2015*0.25,0) | D28: ='Budget Control'!C74 | E28: =C28*D28 | F28: =E28*'Budget Control'!C29 | G28: =E28*'Budget Control'!C30 | H28: =E28*'Budget Control'!C31 | I28: =E28*'Budget Control'!C32 | J28: 25% active retailers
A29: 13 | B29: Counter Wall Painting | C29: =ROUND(2015*0.2,0) | D29: ='Budget Control'!C75 | E29: =C29*D29 | F29: =E29*'Budget Control'!C29 | G29: =E29*'Budget Control'!C30 | H29: =E29*'Budget Control'!C31 | I29: =E29*'Budget Control'!C32 | J29: 20% active retailers
A30: 14 | B30: Inshop Branding | C30: =ROUND(2015*0.1,0) | D30: ='Budget Control'!C76 | E30: =C30*D30 | F30: =E30*'Budget Control'!C29 | G30: =E30*'Budget Control'!C30 | H30: =E30*'Budget Control'!C31 | I30: =E30*'Budget Control'!C32 | J30: 10% active retailers
A31: 15 | B31: Architect/Engineer Meet | C31: =ROUND(250*0.5,0)*4 | D31: ='Budget Control'!C77 | E31: =C31*D31 | F31: =E31*'Budget Control'!C29 | G31: =E31*'Budget Control'!C30 | H31: =E31*'Budget Control'!C31 | I31: =E31*'Budget Control'!C32 | J31: 50% dist x 4 qtrs meets
A32: 16 | B32: Contractor Meet | C32: =250*4 | D32: ='Budget Control'!C78 | E32: =C32*D32 | F32: =E32*'Budget Control'!C29 | G32: =E32*'Budget Control'!C30 | H32: =E32*'Budget Control'!C31 | I32: =E32*'Budget Control'!C32 | J32: all dist x 4 qtrs meets
A33: 17 | B33: Mason Meet | C33: =250*4 | D33: ='Budget Control'!C79 | E33: =C33*D33 | F33: =E33*'Budget Control'!C29 | G33: =E33*'Budget Control'!C30 | H33: =E33*'Budget Control'!C31 | I33: =E33*'Budget Control'!C32 | J33: all dist x 4 qtrs meets
A34: 18 | B34: Dealer Certificates | C34: 2015 | D34: ='Budget Control'!C80 | E34: =C34*D34 | F34: =E34*'Budget Control'!C29 | G34: =E34*'Budget Control'!C30 | H34: =E34*'Budget Control'!C31 | I34: =E34*'Budget Control'!C32 | J34: all active retailers
A35: 19 | B35: Construction Site Gate Board | C35: =ROUND(250*0.3,0) | D35: ='Budget Control'!C81 | E35: =C35*D35 | F35: =E35*'Budget Control'!C29 | G35: =E35*'Budget Control'!C30 | H35: =E35*'Budget Control'!C31 | I35: =E35*'Budget Control'!C32 | J35: 30% districts
A36: 20 | B36: POP Materials Kit | C36: 42 | D36: ='Budget Control'!C82 | E36: =C36*D36 | F36: =E36*'Budget Control'!C29 | G36: =E36*'Budget Control'!C30 | H36: =E36*'Budget Control'!C31 | I36: =E36*'Budget Control'!C32 | J36: all distributors
A37: 21 | B37: Architect Gift/Engagement | C37: =ROUND(250*0.5,0)*50 | D37: ='Budget Control'!C83 | E37: =C37*D37 | F37: =E37*'Budget Control'!C29 | G37: =E37*'Budget Control'!C30 | H37: =E37*'Budget Control'!C31 | I37: =E37*'Budget Control'!C32 | J37: 50% dist x 50 architects
A38: 22 | B38: Distributor Meet (Grand) | C38: 42 | D38: ='Budget Control'!C84 | E38: =C38*D38 | F38: =E38*'Budget Control'!C29 | G38: =E38*'Budget Control'!C30 | H38: =E38*'Budget Control'!C31 | I38: =E38*'Budget Control'!C32 | J38: all distributors
A39: 23 | B39: Retailer Loyalty Program | C39: =ROUND(1310*0.3,0)*4 | D39: ='Budget Control'!C85 | E39: =C39*D39 | F39: =E39*'Budget Control'!C29 | G39: =E39*'Budget Control'!C30 | H39: =E39*'Budget Control'!C31 | I39: =E39*'Budget Control'!C32 | J39: 30% transacting x 4 qtrs
A40: 24 | B40: Mason Training Camp | C40: =ROUND(250*0.2,0) | D40: ='Budget Control'!C86 | E40: =C40*D40 | F40: =E40*'Budget Control'!C29 | G40: =E40*'Budget Control'!C30 | H40: =E40*'Budget Control'!C31 | I40: =E40*'Budget Control'!C32 | J40: 20% districts
A41: 25 | B41: Competitive Conversion Scheme | C41: =ROUND(2015*0.05,0) | D41: ='Budget Control'!C87 | E41: =C41*D41 | F41: =E41*'Budget Control'!C29 | G41: =E41*'Budget Control'!C30 | H41: =E41*'Budget Control'!C31 | I41: =E41*'Budget Control'!C32 | J41: 5% retailers
B42: BTL SUBTOTAL | E42: =SUM(E27:E41) | F42: =SUM(F27:F41) | G42: =SUM(G27:G41) | H42: =SUM(H27:H41) | I42: =SUM(I27:I41)
...

Sheet Obj2 - JSW ONE Growth
A1: OBJECTIVE 2: JSW ONE TMT - GROWTH STRATEGY
A3: BRAND OVERVIEW
B4: Brand | C4: JSW ONE TMT
B5: Total Obj2 Budget | C5: ="Rs. " & TEXT('Budget Control'!C17,"##,##,##0") & " (" & TEXT('Budget Control'!C8,"0%") & " of total)"
B6: Network | C6: ='Budget Control'!C42 & " Distributors, " & 'Budget Control'!C44 & " Active Retailers"
B7: Total Volume Target | C7: =TEXT('Budget Control'!C43,"##,##0") & " MT (Annual)"
B8: Selling Price | C8: ="Rs. " & TEXT('Budget Control'!C47,"##,##0") & " per MT"
A10: SUB-OBJECTIVES
B11: Sub-2A: EAST INDIA GROWTH | C11: ="Bihar, WB, Jharkhand, Odisha | Budget: Rs. " & TEXT('Budget Control'!C18,"##,##,##0") & " | 120 Districts"
B12: Sub-2B: UP & HARYANA 2x GROWTH | C12: ="UP & Haryana | Budget: Rs. " & TEXT('Budget Control'!C19,"##,##,##0") & " | 74 Districts | 2x Target"
A14: ACTIVITY PLAN - SUB-2A (EAST) vs SUB-2B (UP+HR)
A15: # | B15: Activity | C15: Sub-2A Qty | D15: Sub-2A Cost | E15: Sub-2B Qty | F15: Sub-2B Cost | G15: Total Cost | H15: Q1 | I15: Q2 | J15: Q3 | K15: Q4 | L15: Basis
A16: ATL ACTIVITIES
A17: 1 | B17: Impact Wall Painting | C17: =120*20000 | D17: =C17*'Budget Control'!C62 | E17: =74*20000 | F17: =E17*'Budget Control'!C62 | G17: =D17+F17 | H17: =G17*'Budget Control'!C29 | I17: =G17*'Budget Control'!C30 | J17: =G17*'Budget Control'!C31 | K17: =G17*'Budget Control'!C32 | L17: sqft across 120 East districts
A18: 2 | B18: FM Radio Campaign | C18: =ROUND(120*0.05,0)*4 | D18: =C18*'Budget Control'!C63 | E18: =ROUND(74*0.05,0)*4 | F18: =E18*'Budget Control'!C63 | G18: =D18+F18 | H18: =G18*'Budget Control'!C29 | I18: =G18*'Budget Control'!C30 | J18: =G18*'Budget Control'!C31 | K18: =G18*'Budget Control'!C32 | L18: 5% dist x 4 qtrs
A19: 3 | B19: Hoardings (Flex/Billboard) | C19: =120*3 | D19: =C19*'Budget Control'!C64 | E19: =74*3 | F19: =E19*'Budget Control'!C64 | G19: =D19+F19 | H19: =G19*'Budget Control'!C29 | I19: =G19*'Budget Control'!C30 | J19: =G19*'Budget Control'!C31 | K19: =G19*'Budget Control'!C32 | L19: 3 per district
A20: 4 | B20: Digital Marketing Campaign | C20: 4 | D20: =C20*'Budget Control'!C65 | E20: 4 | F20: =E20*'Budget Control'!C65 | G20: =D20+F20 | H20: =G20*'Budget Control'!C29 | I20: =G20*'Budget Control'!C30 | J20: =G20*'Budget Control'!C31 | K20: =G20*'Budget Control'!C32 | L20: 4 campaigns/year
A21: 5 | B21: Local Events / Trade Fairs | C21: 4 | D21: =C21*'Budget Control'!C66 | E21: 4 | F21: =E21*'Budget Control'!C66 | G21: =D21+F21 | H21: =G21*'Budget Control'!C29 | I21: =G21*'Budget Control'!C30 | J21: =G21*'Budget Control'!C31 | K21: =G21*'Budget Control'!C32 | L21: 4 zonal events
A22: 6 | B22: Van Campaign (Mobile) | C22: =4*60 | D22: =C22*'Budget Control'!C67 | E22: =2*60 | F22: =E22*'Budget Control'!C67 | G22: =D22+F22 | H22: =G22*'Budget Control'!C29 | I22: =G22*'Budget Control'!C30 | J22: =G22*'Budget Control'!C31 | K22: =G22*'Budget Control'!C32 | L22: 4 vans x 60 days (4 states)
A23: 7 | B23: Syndicate Launch Events | C23: 4 | D23: =C23*'Budget Control'!C68 | E23: 2 | F23: =E23*'Budget Control'!C68 | G23: =D23+F23 | H23: =G23*'Budget Control'!C29 | I23: =G23*'Budget Control'!C30 | J23: =G23*'Budget Control'!C31 | K23: =G23*'Budget Control'!C32 | L23: 4 state launches
A24: 8 | B24: Transit Auto Branding | C24: 300 | D24: =C24*'Budget Control'!C69 | E24: 200 | F24: =E24*'Budget Control'!C69 | G24: =D24+F24 | H24: =G24*'Budget Control'!C29 | I24: =G24*'Budget Control'!C30 | J24: =G24*'Budget Control'!C31 | K24: =G24*'Budget Control'!C32 | L24: 300 autos
A25: 9 | B25: Tea Stall Branding | C25: =ROUND(120*0.1,0)*25 | D25: =C25*'Budget Control'!C70 | E25: =ROUND(74*0.1,0)*25 | F25: =E25*'Budget Control'!C70 | G25: =D25+F25 | H25: =G25*'Budget Control'!C29 | I25: =G25*'Budget Control'!C30 | J25: =G25*'Budget Control'!C31 | K25: =G25*'Budget Control'!C32 | L25: 10% dist x 25 stalls
A26: 10 | B26: Paper Advertisement | C26: 8 | D26: =C26*'Budget Control'!C71 | E26: 6 | F26: =E26*'Budget Control'!C71 | G26: =D26+F26 | H26: =G26*'Budget Control'!C29 | I26: =G26*'Budget Control'!C30 | J26: =G26*'Budget Control'!C31 | K26: =G26*'Budget Control'!C32 | L26: 8 insertions/year
B27: ATL SUBTOTAL | D27: =SUM(D17:D26) | F27: =SUM(F17:F26) | G27: =SUM(G17:G26) | H27: =SUM(H17:H26) | I27: =SUM(I17:I26) | J27: =SUM(J17:J26) | K27: =SUM(K17:K26)
A28: BTL ACTIVITIES
A29: 11 | B29: NLB (Name/Lit Board) | C29: =ROUND(954*0.5,0) | D29: =C29*'Budget Control'!C73 | E29: =ROUND(636*0.5,0) | F29: =E29*'Budget Control'!C73 | G29: =D29+F29 | H29: =G29*'Budget Control'!C29 | I29: =G29*'Budget Control'!C30 | J29: =G29*'Budget Control'!C31 | K29: =G29*'Budget Control'!C32 | L29: 50% of 954 East retailers
A30: 12 | B30: GSB (Glow Sign Board) | C30: =ROUND(954*0.25,0) | D30: =C30*'Budget Control'!C74 | E30: =ROUND(636*0.25,0) | F30: =E30*'Budget Control'!C74 | G30: =D30+F30 | H30: =G30*'Budget Control'!C29 | I30: =G30*'Budget Control'!C30 | J30: =G30*'Budget Control'!C31 | K30: =G30*'Budget Control'!C32 | L30: 25%
A31: 13 | B31: Counter Wall Painting | C31: =ROUND(954*0.2,0) | D31: =C31*'Budget Control'!C75 | E31: =ROUND(636*0.2,0) | F31: =E31*'Budget Control'!C75 | G31: =D31+F31 | H31: =G31*'Budget Control'!C29 | I31: =G31*'Budget Control'!C30 | J31: =G31*'Budget Control'!C31 | K31: =G31*'Budget Control'!C32 | L31: 20%
A32: 14 | B32: Inshop Branding | C32: =ROUND(954*0.1,0) | D32: =C32*'Budget Control'!C76 | E32: =ROUND(636*0.1,0) | F32: =E32*'Budget Control'!C76 | G32: =D32+F32 | H32: =G32*'Budget Control'!C29 | I32: =G32*'Budget Control'!C30 | J32: =G32*'Budget Control'!C31 | K32: =G32*'Budget Control'!C32 | L32: 10%
A33: 15 | B33: Architect/Engineer Meet | C33: =ROUND(120*0.5,0)*4 | D33: =C33*'Budget Control'!C77 | E33: =ROUND(74*0.5,0)*4 | F33: =E33*'Budget Control'!C77 | G33: =D33+F33 | H33: =G33*'Budget Control'!C29 | I33: =G33*'Budget Control'!C30 | J33: =G33*'Budget Control'!C31 | K33: =G33*'Budget Control'!C32 | L33: 50% dist x 4 qtrs
A34: 16 | B34: Contractor Meet | C34: =120*4 | D34: =C34*'Budget Control'!C78 | E34: =74*4 | F34: =E34*'Budget Control'!C78 | G34: =D34+F34 | H34: =G34*'Budget Control'!C29 | I34: =G34*'Budget Control'!C30 | J34: =G34*'Budget Control'!C31 | K34: =G34*'Budget Control'!C32 | L34: all dist x 4 qtrs
A35: 17 | B35: Mason Meet | C35: =120*4 | D35: =C35*'Budget Control'!C79 | E35: =74*4 | F35: =E35*'Budget Control'!C79 | G35: =D35+F35 | H35: =G35*'Budget Control'!C29 | I35: =G35*'Budget Control'!C30 | J35: =G35*'Budget Control'!C31 | K35: =G35*'Budget Control'!C32 | L35: all dist x 4 qtrs
A36: 18 | B36: Dealer Certificates | C36: 954 | D36: =C36*'Budget Control'!C80 | E36: 636 | F36: =E36*'Budget Control'!C80 | G36: =D36+F36 | H36: =G36*'Budget Control'!C29 | I36: =G36*'Budget Control'!C30 | J36: =G36*'Budget Control'!C31 | K36: =G36*'Budget Control'!C32 | L36: all East retailers
A37: 19 | B37: Construction Site Gate Board | C37: =ROUND(120*0.3,0) | D37: =C37*'Budget Control'!C81 | E37: =ROUND(74*0.3,0) | F37: =E37*'Budget Control'!C81 | G37: =D37+F37 | H37: =G37*'Budget Control'!C29 | I37: =G37*'Budget Control'!C30 | J37: =G37*'Budget Control'!C31 | K37: =G37*'Budget Control'!C32 | L37: 30% districts
A38: 20 | B38: POP Materials Kit | C38: 34 | D38: =C38*'Budget Control'!C82 | E38: 22 | F38: =E38*'Budget Control'!C82 | G38: =D38+F38 | H38: =G38*'Budget Control'!C29 | I38: =G38*'Budget Control'!C30 | J38: =G38*'Budget Control'!C31 | K38: =G38*'Budget Control'!C32 | L38: 60% of 56 distributors
A39: 21 | B39: Architect Gift/Engagement | C39: =ROUND(120*0.5,0)*50 | D39: =C39*'Budget Control'!C83 | E39: =ROUND(74*0.5,0)*50 | F39: =E39*'Budget Control'!C83 | G39: =D39+F39 | H39: =G39*'Budget Control'!C29 | I39: =G39*'Budget Control'!C30 | J39: =G39*'Budget Control'!C31 | K39: =G39*'Budget Control'!C32 | L39: 50% dist x 50 arch
A40: 22 | B40: Distributor Meet (Grand) | C40: 34 | D40: =C40*'Budget Control'!C84 | E40: 22 | F40: =E40*'Budget Control'!C84 | G40: =D40+F40 | H40: =G40*'Budget Control'!C29 | I40: =G40*'Budget Control'!C30 | J40: =G40*'Budget Control'!C31 | K40: =G40*'Budget Control'!C32 | L40: 34 East distributors
A41: 23 | B41: Retailer Loyalty Program | C41: =ROUND(620*0.3,0)*4 | D41: =C41*'Budget Control'!C85 | E41: =ROUND(413*0.3,0)*4 | F41: =E41*'Budget Control'!C85 | G41: =D41+F41 | H41: =G41*'Budget Control'!C29 | I41: =G41*'Budget Control'!C30 | J41: =G41*'Budget Control'!C31 | K41: =G41*'Budget Control'!C32 | L41: 30% transacting x 4 qtrs
A42: 24 | B42: Mason Training Camp | C42: =ROUND(120*0.2,0) | D42: =C42*'Budget Control'!C86 | E42: =ROUND(74*0.2,0) | F42: =E42*'Budget Control'!C86 | G42: =D42+F42 | H42: =G42*'Budget Control'!C29 | I42: =G42*'Budget Control'!C30 | J42: =G42*'Budget Control'!C31 | K42: =G42*'Budget Control'!C32 | L42: 20% districts
A43: 25 | B43: Competitive Conversion Scheme | C43: =ROUND(954*0.05,0) | D43: =C43*'Budget Control'!C87 | E43: =ROUND(636*0.05,0) | F43: =E43*'Budget Control'!C87 | G43: =D43+F43 | H43: =G43*'Budget Control'!C29 | I43: =G43*'Budget Control'!C30 | J43: =G43*'Budget Control'!C31 | K43: =G43*'Budget Control'!C32 | L43: 5% retailers
...
